Workbook

Sheet 交易案例
A1: A
A2: 江宁区天印大道以西、科建路以南地块信息表 | F2: 地面地价 | G2: 容积率 | H2: 楼面地价
A4: 地块编号： | B4: NO.2018G26 | C4: 地块位置： | D4: 东至天印大道，南至科宁路，西至莱茵达路，北至科建路。
A5: 容积率： | B5: 2.56 | C5: 用地性质： | D5: R2二类居住用地 Rc基层社区中心用地 Rax幼托用地
A6: 规划面积： | B6: 167896.78平方米 | C6: 实际出让面积： | D6: 153260.90平方米
A7: 公告发布时间： | B7: 43250 | C7: 挂牌起始价： | D7: 550000万元 | F7: =556000/153260.9*10000 -> 36278.007 | G7: 2.56 | H7: =F7/G7 -> 14171.1
A8: 成交时间： | B8: 43280 | C8: 成交总额： | D8: 556000万元
A9: 竞得人： | B9: 南京万融置业有限公司 | C9: 公告编号： | D9: 2018年宁出第05号
A13: B
A14: 江宁区东山街道天佑路以东、天环路以南地块信息表
A16: 地块编号： | B16: NO.2017G72 | C16: 地块位置： | D16: 东至现状，南至规划道路，西至现状，北至现状。
A17: 容积率： | B17: ≤2.19 | C17: 用地性质： | D17: R21住宅用地Rc基层社区中心
A18: 规划面积： | B18: 34623.03平方米 | C18: 实际出让面积： | D18: 34623.03平方米
A19: 公告发布时间： | B19: 43063 | C19: 挂牌起始价： | D19: 85000万元 | F19: =106000/34623.03*10000 -> 30615.46 | G19: 2.19 | H19: =F19/G19 -> 13979.66
A20: 成交时间： | B20: 43096 | C20: 成交总额： | D20: 106000万元
A21: 竞得人： | B21: 马鞍山深业地产有限公司 | C21: 公告编号： | D21: （2017年宁网挂第10号）
A25: C
A26: 江宁区东山街道润麒路以东、天云路以南地块信息表
A28: 地块编号： | B28: NO.2017G71 | C28: 地块位置： | D28: 东至现状，南至万安西路，西至现状，北至现状
A29: 容积率： | B29: ≤2.5 | C29: 用地性质： | D29: R21住宅用地
A30: 规划面积： | B30: 86628.01平方米 | C30: 实际出让面积： | D30: 86628.01平方米
A31: 公告发布时间： | B31: 43063 | C31: 挂牌起始价： | D31: 260000万元 | F31: =303000/86628.01*10000 -> 34977.14 | G31: 2.5 | H31: =F31/G31 -> 13990.86
A32: 成交时间： | B32: 43096 | C32: 成交总额： | D32: 303000万元
A33: 竞得人： | B33: 北京方兴亦城置业有限公司 | C33: 公告编号： | D33: （2017年宁网挂第10号）
A38: 江宁区汤泉路以西、若水路以南地块信息表
A40: 地块编号： | B40: NO.2017G66 | C40: 地块位置： | D40: 东至汤泉路，南至现状，西至规划道路，北至若水路。
A41: 容积率： | B41: ≤2.0 | C41: 用地性质： | D41: R2二类居住用地
A42: 规划面积： | B42: 14710.51平方米 | C42: 实际出让面积： | D42: 14710.51平方米
A43: 公告发布时间： | B43: 43060 | C43: 挂牌起始价： | D43: 24000万元 | F43: =31000/14710.51*10000 -> 21073.369 | G43: 2 | H43: =F43/G43 -> 10536.68
A44: 成交时间： | B44: 43091 | C44: 成交总额： | D44: 31000万元
A45: 竞得人： | B45: 重庆旭昌房地产开发有限公司 | C45: 公告编号： | D45: （2017年宁网挂第09号）
A51: 江宁区泉都大街以北、若水路以东地块信息表
A53: 地块编号： | B53: NO.2017G65 | C53: 地块位置： | D53: 东至上善路，南至泉都大街，西至若水路，北至纬九路。
A54: 容积率： | B54: ≤1.5 | C54: 用地性质： | D54: R2二类居住用地
A55: 规划面积： | B55: 79316.75平方米 | C55: 实际出让面积： | D55: 67681.40平方米
A56: 公告发布时间： | B56: 43060 | C56: 挂牌起始价： | D56: 84000万元 | F56: =108000/67681.4*10000 -> 15957.117 | G56: 1.5 | H56: =F56/G56 -> 10638.08
A57: 成交时间： | B57: 43091 | C57: 成交总额： | D57: 108000万元
A58: 竞得人： | B58: 滁州碧桂园房地产开发有限公司 | C58: 公告编号： | D58: （2017年宁网挂第09号）
A64: 江宁区秣陵街道云台山河以西、秣周路以南地块信息表
A66: 地块编号： | B66: NO.2017G64 | C66: 地块位置： | D66: 东至新宁溧路，南至学林东路，西至栖隐路，北至秣周路。
...

Sheet 市场法计算表
A1: 房地产市场法评估（住宅）评估计算表 | L1: 索引号：C4-6-1/Z3
A2: 修正因素 | C2: 委估对象 | D2: 案例A | E2: 案例B | F2: 案例C | G2: 委估对象 | H2: 案例A | I2: 案例B | J2: 案例C | K2: 案例A | L2: 案例B | M2: 案例C
A3: 地 址 | C3: 委估宗地 | D3: 宗地A | E3: 宗地B | F3: 宗地C | G3: =C3 -> 委估宗地 | H3: =D3 -> 宗地A | I3: =E3 -> 宗地B | J3: =F3 -> 宗地C | K3: =H3 -> 宗地A | L3: =I3 -> 宗地B | M3: =J3 -> 宗地C
A4: 交易价格（不含税） | C4: 待估 | D4: =D37 -> 27586 | E4: =E37 -> 25974 | F4: =F37 -> 27340 | G4: 待估 | H4: =D4 -> 27586 | I4: =E4 -> 25974 | J4: =F4 -> 27340 | K4: =H4 -> 27586 | L4: =I4 -> 25974 | M4: =F4 -> 27340
A5: 市场状况 | C5: 41682 | D5: 2013-05-27 | E5: 2013-04-13 | F5: 2014-02-01 | G5: 100 | H5: 113.81 | I5: 115.48 | J5: 100 | K5: =CONCATENATE($H5,"/",G5) -> 113.81/100 | L5: =CONCATENATE($I5,"/",G5) -> 115.48/100 | M5: =CONCATENATE($J5,"/",G5) -> 100/100
A6: 交易情况 | C6: 正常 | D6: 正常 | E6: 正常 | F6: 正常 | G6: 100 | H6: 100 | I6: 100 | J6: 100 | K6: =CONCATENATE($G6,"/",H6) -> 100/100 | L6: =CONCATENATE($G6,"/",I6) -> 100/100 | M6: =CONCATENATE($G6,"/",J6) -> 100/100
A7: 区位状况 | B7: 商业配套设施 | C7: 位于新街口商圈内，周边有金鹰国际，大洋百货、东方商城等大型商城，区域繁华程度高 | D7: 位于新街口商圈内，周边有金鹰国际，大洋百货、东方商城等大型商城，区域繁华程度高 | E7: 位于新街口商圈内，周边有金鹰国际，大洋百货、东方商城等大型商城，区域繁华程度高 | F7: 位于新街口商圈内，周边有金鹰国际，大洋百货、东方商城等大型商城，区域繁华程度高 | G7: 100 | H7: 100 | I7: 100 | J7: 100 | K7: =CONCATENATE($G7,"/",H7) -> 100/100 | L7: =CONCATENATE($G7,"/",I7) -> 100/100 | M7: =CONCATENATE($G7,"/",J7) -> 100/100
B8: 规划设计 | C8: 小区布局、建筑密度、绿化条件较优 | D8: 小区布局、建筑密度、绿化条件较优 | E8: 小区布局、建筑密度、绿化条件较优 | F8: 小区布局、建筑密度、绿化条件较优 | G8: 100 | H8: 100 | I8: 100 | J8: 100 | K8: =CONCATENATE($G8,"/",H8) -> 100/100 | L8: =CONCATENATE($G8,"/",I8) -> 100/100 | M8: =CONCATENATE($G8,"/",J8) -> 100/100
B9: 交通条件 | C9: 距秣陵路公交站约100米，有41路、43路、306路等公交线路通过，交通便捷度优 | D9: 距秣陵路公交站约100米，有41路、43路、306路等公交线路通过，交通便捷度优 | E9: 距秣陵路公交站约100米，有41路、43路、306路等公交线路通过，交通便捷度优 | F9: 距秣陵路公交站约100米，有41路、43路、306路等公交线路通过，交通便捷度优 | G9: 100 | H9: 100 | I9: 100 | J9: 100 | K9: =CONCATENATE($G9,"/",H9) -> 100/100 | L9: =CONCATENATE($G9,"/",I9) -> 100/100 | M9: =CONCATENATE($G9,"/",J9) -> 100/100
B10: 教育医疗设施 | C10: 属于xx学区，教育条件较优，距离XX医院约xx公里，教育医疗设施较优 | D10: 属于xx学区，教育条件较优，距离XX医院约xx公里，教育医疗设施较优 | E10: 属于xx学区，教育条件较优，距离XX医院约xx公里，教育医疗设施较优 | F10: 属于xx学区，教育条件较优，距离XX医院约xx公里，教育医疗设施较优 | G10: 100 | H10: 100 | I10: 100 | J10: 100 | K10: =CONCATENATE($G10,"/",H10) -> 100/100 | L10: =CONCATENATE($G10,"/",I10) -> 100/100 | M10: =CONCATENATE($G10,"/",J10) -> 100/100
B11: 周围环境 | C11: 自然环境一般 | D11: 自然环境一般 | E11: 自然环境一般 | F11: 自然环境一般 | G11: 100 | H11: 100 | I11: 100 | J11: 100 | K11: =CONCATENATE($G11,"/",H11) -> 100/100 | L11: =CONCATENATE($G11,"/",I11) -> 100/100 | M11: =CONCATENATE($G11,"/",J11) -> 100/100
B12: 所处楼栋 | C12: 位于王府小区1幢，较优 | D12: 位于王府小区1幢，较优 | E12: 位于王府小区1幢，较优 | F12: 位于王府小区1幢，较优 | G12: 100 | H12: 100 | I12: 100 | J12: 100 | K12: =CONCATENATE($G12,"/",H12) -> 100/100 | L12: =CONCATENATE($G12,"/",I12) -> 100/100 | M12: =CONCATENATE($G12,"/",J12) -> 100/100
B13: 楼层 | C13: 12/15 | D13: 14/15 | E13: 2/15 | F13: 6/15 | G13: 100 | H13: 100 | I13: 100 | J13: 100 | K13: =CONCATENATE($G13,"/",H13) -> 100/100 | L13: =CONCATENATE($G13,"/",I13) -> 100/100 | M13: =CONCATENATE($G13,"/",J13) -> 100/100
B14: 朝向 | C14: 两室朝南 | D14: 两室朝南 | E14: 两室朝南 | F14: 两室朝南 | G14: 100 | H14: 100 | I14: 100 | J14: 100 | K14: =CONCATENATE($G14,"/",H14) -> 100/100 | L14: =CONCATENATE($G14,"/",I14) -> 100/100 | M14: =CONCATENATE($G14,"/",J14) -> 100/100
A15: 权益状况 | B15: 规划条件 | C15: 无限制 | D15: 无限制 | E15: 无限制 | F15: 无限制 | G15: 100 | H15: 100 | I15: 100 | J15: 100 | K15: =CONCATENATE($G15,"/",H15) -> 100/100 | L15: =CONCATENATE($G15,"/",I15) -> 100/100 | M15: =CONCATENATE($G15,"/",J15) -> 100/100
B16: 土地使用期限 | C16: 剩余59.5年 | D16: 剩余59.5年 | E16: 剩余59.5年 | F16: 剩余59.5年 | G16: =ROUND((1-1/(1+7%)^59.5)/(1-1/(1+7%)^70),4) -> 0.9908 | H16: =ROUND((1-1/(1+7%)^59.5)/(1-1/(1+7%)^70),4) -> 0.9908 | I16: =ROUND((1-1/(1+7%)^59.5)/(1-1/(1+7%)^70),4) -> 0.9908 | J16: =ROUND((1-1/(1+7%)^59.5)/(1-1/(1+7%)^70),4) -> 0.9908 | K16: =CONCATENATE($G16,"/",H16) -> 0.9908/0.9908 | L16: =CONCATENATE($G16,"/",I16) -> 0.9908/0.9908 | M16: =CONCATENATE($G16,"/",J16) -> 0.9908/0.9908
B17: 租赁情况 | C17: 无租约 | D17: 无租约 | E17: 无租约 | F17: 无租约 | G17: 100 | H17: 100 | I17: 100 | J17: 100 | K17: =CONCATENATE($G17,"/",H17) -> 100/100 | L17: =CONCATENATE($G17,"/",I17) -> 100/100 | M17: =CONCATENATE($G17,"/",J17) -> 100/100
A18: 实物状况 | B18: 建筑面积 | C18: 142.53平方米，面积一般 | D18: 145平方米，面积一般 | E18: 143平方米，面积一般 | F18: 116平方米，面积较适中 | G18: 100 | H18: 100 | I18: 100 | J18: 100 | K18: =CONCATENATE($G18,"/",H18) -> 100/100 | L18: =CONCATENATE($G18,"/",I18) -> 100/100 | M18: =CONCATENATE($G18,"/",J18) -> 100/100
B19: 建筑结构 | C19: 建筑标准较高，钢混结构，完好 | D19: 建筑标准较高，钢混结构，完好 | E19: 建筑标准较高，钢混结构，完好 | F19: 建筑标准较高，钢混结构，完好 | G19: 100 | H19: 100 | I19: 100 | J19: 100 | K19: =CONCATENATE($G19,"/",H19) -> 100/100 | L19: =CONCATENATE($G19,"/",I19) -> 100/100 | M19: =CONCATENATE($G19,"/",J19) -> 100/100
B20: 建造年代 | C20: 2005年建成，成新较优 | D20: 2005年建成，成新较优 | E20: 2005年建成，成新较优 | F20: 2005年建成，成新较优 | G20: 100 | H20: 100 | I20: 100 | J20: 100 | K20: =CONCATENATE($G20,"/",H20) -> 100/100 | L20: =CONCATENATE($G20,"/",I20) -> 100/100 | M20: =CONCATENATE($G20,"/",J20) -> 100/100
B21: 层高 | C21: 2.9米 | D21: 2.9米 | E21: 2.9米 | F21: 2.9米 | G21: 100 | H21: 100 | I21: 100 | J21: 100 | K21: =CONCATENATE($G21,"/",H21) -> 100/100 | L21: =CONCATENATE($G21,"/",I21) -> 100/100 | M21: =CONCATENATE($G21,"/",J21) -> 100/100
B22: 空间布局 | C22: 空间布局较优 | D22: 空间布局较优 | E22: 空间布局较优 | F22: 空间布局较优 | G22: 100 | H22: 100 | I22: 100 | J22: 100 | K22: =CONCATENATE($G22,"/",H22) -> 100/100 | L22: =CONCATENATE($G22,"/",I22) -> 100/100 | M22: =CONCATENATE($G22,"/",J22) -> 100/100
B23: 停车便利度 | C23: 停车便利度较优 | D23: 停车便利度较优 | E23: 停车便利度较优 | F23: 停车便利度较优 | G23: 100 | H23: 100 | I23: 100 | J23: 100 | K23: =CONCATENATE($G23,"/",H23) -> 100/100 | L23: =CONCATENATE($G23,"/",I23) -> 100/100 | M23: =CONCATENATE($G23,"/",J23) -> 100/100
B24: 物业管理 | C24: 管理及服务优 | D24: 管理及服务优 | E24: 管理及服务优 | F24: 管理及服务优 | G24: 100 | H24: 100 | I24: 100 | J24: 100 | K24: =CONCATENATE($G24,"/",H24) -> 100/100 | L24: =CONCATENATE($G24,"/",I24) -> 100/100 | M24: =CONCATENATE($G24,"/",J24) -> 100/100
B25: 装饰装修 | C25: 中档装修 | D25: 中档装修 | E25: 中档装修 | F25: 简单装修 | G25: 100 | H25: 100 | I25: 100 | J25: 94 | K25: =CONCATENATE($G25,"/",H25) -> 100/100 | L25: =CONCATENATE($G25,"/",I25) -> 100/100 | M25: =CONCATENATE($G25,"/",J25) -> 100/94
B26: 设备设施 | C26: 水、电、气等设施齐全 | D26: 水、电、气等设施齐全 | E26: 水、电、气等设施齐全 | F26: 水、电、气等设施齐全 | G26: 100 | H26: 100 | I26: 100 | J26: 100 | K26: =CONCATENATE($G26,"/",H26) -> 100/100 | L26: =CONCATENATE($G26,"/",I26) -> 100/100 | M26: =CONCATENATE($G26,"/",J26) -> 100/100
A27: 修正后单价（不含税） | H27: =ROUND(PRODUCT($G6:$G26)/PRODUCT(H6:H26)*H4*$H5/$G5,0) -> 31396 | I27: =ROUND(PRODUCT($G6:$G26)/PRODUCT(I6:I26)*I4*$I5/$G5,0) -> 29995 | J27: =ROUND(PRODUCT($G6:$G26)/PRODUCT(J6:J26)*J4*$J5/$G5,0) -> 29085 | K27: =H27 -> 31396 | L27: =I27 -> 29995 | M27: =J27 -> 29085
A28: 修正后平均单价（不含税） | K28: =ROUND(AVERAGE(K27:M27),0) -> 30159
A29: 建筑面积 | K29: 142.53
A30: 不含税评估总价 | K30: =ROUND(K28*K29,-2) -> 4298600
A31: 评估人员： | C31: 日期： | E31: 复核人： | F31: 日期：
C33: 案例 | D33: A | E33: B | F33: C
C34: 房屋位置 | D34: 宗地A | E34: 宗地B | F34: 宗地C
C35: 建筑面积（m2） | D35: 145 | E35: 143 | F35: 116
C36: 含税总价（元） | D36: 4200000 | E36: 3900000 | F36: 3330000
C37: 折合不含税单价（元/m2） | D37: =ROUND(D36/D35/1.05,0) -> 27586 | E37: =ROUND(E36/E35/1.05,0) -> 25974 | F37: =ROUND(F36/F35/1.05,0) -> 27340 | G37: 注：老项目采用5%，新项目应采用11%，2019年4月1日起采用9%
C38: 成交日期 | D38: 2013-05-27 | E38: 2013-04-13 | F38: 2014-02-01
C39: 建筑结构 | D39: 钢混 | E39: 钢混 | F39: 钢混
C40: 楼层(地上） | D40: 14/15 | E40: 2/15 | F40: 6/15
C41: 装修状况 | D41: 中档装修 | E41: 中档装修 | F41: 简单装修
...

Sheet 市场比较法
A1: 比较因素条件说明表
A2: 项目名称 | C2: 待估宗地 | D2: 案例A | E2: 案例B | F2: 案例C
A3: 项目位置 | C3: 宏运大道2298号 | D3: 江宁区天印大道以西、科建路以南地块 | E3: 江宁区东山街道天佑路以东、天环路以南地块 | F3: 江宁区东山街道润麒路以东、天云路以南地块
A4: 成交土地楼面单价（元/㎡） | C4: 待估 | D4: 14171.1 | E4: 13979.66 | F4: 13990.86
A5: 交易日期 | C5: 43298 | D5: 43280 | E5: 43096 | F5: 43096
A6: 交易方式 | D6: 挂牌出让 | E6: 挂牌出让 | F6: 挂牌出让
A7: 交易情况 | C7: 正常 | D7: 正常 | E7: 正常 | F7: 正常
A8: 区域因素 | B8: 区域内商服繁华程度 | C8: 区域内商业设施较少，繁华程度较低 | D8: 区域内商业设施较少，繁华程度较低 | E8: 区域内商业设施较少，繁华程度较低 | F8: 区域内商业设施较少，繁华程度较低
B9: 区域内公用设施便利度 | C9: 区域内有东山小学、岔路学校，公用设施便利度较好 | D9: 区域内有南京市竹山中学，公用设施便利度较好 | E9: 区域内有上坊中学，公用设施便利度较好 | F9: 区域内有东山外国语学校，公用设施便利度较好
B10: 区域内公共交通便利度 | C10: 区域内有地铁1号南沿线及公交车，公共交通便利度好 | D10: 区域内有地铁1号南沿线及公交车，公共交通便利度好 | E10: 区域内无地铁线路，只有公交车，公共交通便利度一般 | F10: 区域内无地铁线路，只有公交车，公共交通便利度一般
B11: 区域内道路级别状况 | C11: 区域内以主干道为主，道路级别优 | D11: 区域内以主干道为主，道路级别优 | E11: 区域内以主干道为主，道路级别优 | F11: 区域内以主干道为主，道路级别优
B12: 区域内文体设施状况 | C12: 区域内有江宁文化馆，江宁博物馆，文体设施状况优 | D12: 区域内有江宁文化馆，江宁博物馆，文体设施状况优 | E12: 区域内无文体设施，文体设施状况劣 | F12: 区域内无文体设施，文体设施状况劣
B13: 区域环境质量状况 | C13: 区域内环境质量较好 | D13: 区域内环境质量较好 | E13: 区域内环境质量较好 | F13: 区域内环境质量较好
B14: 区域内土地利用状况 | C14: 区域内以住宅用地为主 | D14: 区域内住宅用地和工业用地并重 | E14: 区域内以住宅用地为主 | F14: 区域内住宅用地和工业用地并重
A15: 个别因素 | B15: 规划容积率 | C15: 0.9 | D15: 2.56 | E15: 2.19 | F15: 2.5
B16: 宗地自然条件 | C16: 宗地自然条件好 | D16: 宗地自然条件好 | E16: 宗地自然条件好 | F16: 宗地自然条件好
B17: 宗地临路条件 | C17: 宗地临宏运大道，临路状况好 | D17: 宗地临天印大道、科建路，临路状况好 | E17: 宗地临天佑路、天环路，临路状况好 | F17: 宗地临润麒路、天云路，临路状况好
B18: 宗地距公共交通站点的距离 | C18: 距地铁1号南沿线双龙大道站2KM，评价等级优 | D18: 距地铁1号南沿线天印大道站1.5KM，评价等级优 | E18: 距东山公交总站2KM，评价等级一般 | F18: 距东山公交总站4.8KM，评价等级劣
B19: 宗地面积 | C19: 15994m2，评估等级优 | D19: 153260.9m2，评估等级劣 | E19: 34623.03m2，评估等级较优 | F19: 86628.01m2，评估等级一般
B20: 宗地形状 | C20: 宗地形状不规则 | D20: 宗地形状不规则 | E20: 宗地形状不规则 | F20: 宗地形状不规则
B21: 规划土地用途 | C21: 住宅用地 | D21: 住宅用地 | E21: 住宅用地 | F21: 住宅用地
T24: 99.3 | U24: 100
U25: 100 | V25: =10000/T24 -> 100.7
A26: 比较因素条件指数表
A27: 项目名称 | C27: 待估宗地 | D27: 案例A | E27: 案例B | F27: 案例C
A28: 项目位置 | C28: 宏运大道2298号 | D28: 江宁区天印大道以西、科建路以南地块 | E28: 江宁区东山街道天佑路以东、天环路以南地块 | F28: 江宁区东山街道润麒路以东、天云路以南地块
A29: 成交土地单价（元/㎡） | C29: =C4 -> 待估 | D29: =D4 -> 14171.1 | E29: =E4 -> 13979.66 | F29: =F4 -> 13990.86
A30: 交易日期 | C30: 100 | D30: 100 | E30: 100 | F30: 100
A31: 交易方式 | C31: 100 | D31: 100 | E31: 100 | F31: 100
A32: 交易情况 | C32: 100 | D32: 100 | E32: 100 | F32: 100
A33: 区域因素 | B33: 区域内商服繁华程度 | C33: 100 | D33: 100 | E33: 100 | F33: 100
B34: 区域内公用设施便利度 | C34: 100 | D34: 100 | E34: 100 | F34: 100
B35: 区域内公共交通便利度 | C35: 100 | D35: 100 | E35: 98 | F35: 98
B36: 区域内道路级别状况 | C36: 100 | D36: 100 | E36: 100 | F36: 100
B37: 区域内文体设施便利度 | C37: 100 | D37: 100 | E37: 96 | F37: 96
B38: 区域环境质量状况 | C38: 100 | D38: 100 | E38: 100 | F38: 100
B39: 区域内土地利用状况 | C39: 100 | D39: 99 | E39: 100 | F39: 99 | I39: 评估基准日 | J39: 宗地到期日期 | K39: 剩余使用年限 | L39: 总计使用年限 | M39: 土地还原率
A40: 个别因素 | B40: 规划容积率 | C40: 100 | D40: 100 | E40: 100 | F40: 100
B41: 宗地自然条件 | C41: 100 | D41: 100 | E41: 100 | F41: 100
B42: 宗地临路条件 | C42: 100 | D42: 100 | E42: 100 | F42: 100
...

Sheet Sheet3
A1: 序号： | B1: 宗地1 | D1: 评估基准日 | E1: 39082
A2: 市场比较法（住宅用地）
A3: 影响因素 | C3: 待估宗地 | D3: 实例A | E3: 实例B | F3: 实例C
A4: 交易时间 | C4: 2006.12 | D4: 2007.1.5 | E4: 2007.1.18 | F4: 2007.1.18
A5: 交易情况 | C5: 正常 | D5: 正常 | E5: 正常 | F5: 正常
A6: 交易方式 | C6: －－ | D6: 出让 | E6: 出让 | F6: 出让
A7: 交易价格（元/m2） | C7: 待评估 | D7: =[1]土地市场法案例!F19 -> 2413 | E7: =[1]土地市场法案例!F30 -> 2619 | F7: =[1]土地市场法案例!F42 -> 2927
A8: 区域因素 | B8: 商服繁华度 | C8: 位于仙林边缘区，区域繁华程度一般 | D8: 位于仙林边缘区，区域繁华程度一般 | E8: 位于仙林边缘区，区域繁华程度一般 | F8: 位于仙林边缘区，区域繁华程度一般
B9: 交通便捷度 | C9: 有310路、177路、138路、324路等公交线路通过，距离规划中的二号线学则路站较远，交通便捷度较优 | D9: 有 178路、321路、322路、325路、326路等公交线路通过，紧靠规划中的二号线南大仙林校区站，交通便捷度较优 | E9: 有310路、177路、138路、324路等公交线路通过，距离规划中的二号线学则路站较远，交通便捷度较优 | F9: 有8路、24路、30路、53路、54路、64路、74路等公交线路通过，交通便捷度较优
B10: 外部配套设施 | C10: 区域内有大学城十所知名高校；有银行、餐厅、超市、美容等公共设施较齐全，完备度一般 | D10: 区域内有大学城十所知名高校；有银行、餐厅、超市、美容等公共设施较齐全，完备度一般 | E10: 区域内有大学城十所知名高校；有银行、餐厅、超市、美容等公共设施较齐全，完备度一般 | F10: 区域内有学校晓庄幼儿园 ；有银行、餐厅、超市、美容等公共设施较齐全，完备度较高
B11: 自然环境 | C11: 自然环境较好 | D11: 自然环境较好 | E11: 自然环境较好 | F11: 自然环境较好
A12: 个别因素 | B12: 宗地位置 | C12: 仙林大学城文澜路北，学海路东，宗地位置较好 | D12: 仙林大学城九乡河以东，仙林大道以南，宗地位置较好 | E12: 仙林大学城312国道南、学院路西 ，宗地位置较好 | F12: 和燕路329号，东至和燕路 ，宗地位置较好
B13: 邻接道路等级及通达度 | C13: 临文澜路、学海路，临路状况好 | D13: 临仙林大道，临路状况好 | E13: 临312国道、学院路，临路状况好 | F13: 临和燕路，临路状况好
B14: 宗地面积 | C14: 117660.7m2，面积中等，对土地利用无影响 | D14: 465725.4m2，面积大，对土地利用有利 | E14: 231276.9m2，面积大，对土地利用有利 | F14: 131712.4m2，面积大，对土地利用有利
B15: 宗地形状 | C15: 较规则 | D15: 较规则 | E15: 较规则 | F15: 较规则
B16: 容积率 | C16: 1.6 | D16: 1.01 | E16: 1.2 | F16: 1.7
A17: 修正指数
A18: 影响因素 | C18: 待估宗地 | D18: 实例A | E18: 实例B | F18: 实例C
A19: 交易时间 | C19: 100 | D19: 100 | E19: 100 | F19: 100
A20: 交易情况 | C20: 100 | D20: 100 | E20: 100 | F20: 100
A21: 交易方式 | C21: 100 | D21: 100 | E21: 100 | F21: 100
A22: 交易价格（元/m2） | C22: 待评估 | D22: =D7 -> 2413 | E22: =E7 -> 2619 | F22: =F7 -> 2927
A23: 区域因素 | B23: 商服繁华度 | C23: 100 | D23: 100 | E23: 100 | F23: 100
B24: 交通便捷度 | C24: 100 | D24: 100 | E24: 100 | F24: 100
B25: 外部配套设施 | C25: 100 | D25: 100 | E25: 100 | F25: 100
B26: 自然环境 | C26: 100 | D26: 100 | E26: 100 | F26: 100 | J26: 容积率修正系数表
A27: 个别因素 | B27: 宗地位置 | C27: 100 | D27: 100 | E27: 100 | F27: 100 | J27: 五、六级地 | K27: 容积率区段 | L27: <0.7 | M27: 0.7-1.0 | N27: 1.0-1.4 | O27: 1.4-1.8 | P27: >1.8
B28: 邻接道路等级及通达度 | C28: 100 | D28: 100 | E28: 100 | F28: 100 | K28: 修正系数 | L28: 0.85 | M28: 0.91 | N28: 1 | O28: 1.09 | P28: 1.15
B29: 宗地面积 | C29: 100 | D29: 98 | E29: 99 | F29: 100
B30: 宗地形状 | C30: 100 | D30: 100 | E30: 100 | F30: 100
B31: 容积率 | C31: 109 | D31: 100 | E31: 100 | F31: 109
A32: 比准地价 | D32: =D22*(C31/D31)*(C29/D29) -> 2683.85 | E32: =E22*(D31/E31)*(D29/E29) -> 2592.55 | F32: =F22*(E31/F31)*(E29/F29) -> 2658.47
A33: 平均地价 | C33: =ROUND((D32+E32+F32)/3,0) -> 2645
A34: 容积率 | C34: 1.6
A35: 平均楼面地价 | C35: =ROUND(C33/C34,0) -> 1653

Sheet 出让公告
E1: 出让公告信息
V5: G26
V6: 代建面积 | W6: =19400+1800+300+600+600+200+600+60+1500+1500+100+150+80+30+250 -> 27170
V7: 单价 | W7: 2000
W8: =W6*W7 -> 54340000
V9: 土地总价 | W9: 5560000000
W10: =W8/W9 -> 0.01
X24: =3000+1400+800+1050+2600+120+250+1800+3000+2500+140+160+60+600+400 -> 17880
W26: G72
W27: 代建面积 | X27: 5730
W28: 单价 | X28: 2000
X29: =X27*X28 -> 11460000
W30: 土地总价 | X30: 1060000000
X31: =X29/X30 -> 0.01
C68: 2018G26

Sheet 市场法计表
A1: 比较因素条件说明表
A2: 项目名称 | C2: 待估宗地 | D2: 案例A | E2: 案例B | F2: 案例C
A3: 成交地块编号 | D3: NO.2018G26 | E3: NO.2017G72 | F3: NO.2017G71
A4: 项目位置 | C4: 宏运大道2298号 | D4: 江宁区天印大道以西、科建路以南地块 | E4: 江宁区东山街道天佑路以东、天环路以南地块 | F4: 江宁区东山街道润麒路以东、天云路以南地块
A5: 成交总价 | D5: 556000万元 | E5: 106000万元 | F5: 303000万元
A6: 成交土地单价（元/㎡） | C6: 待估 | D6: 36278.01 | E6: 30615.46 | F6: 34977.14
A7: 交易日期 | C7: 43298 | D7: 43280 | E7: 43096 | F7: 43096
A8: 交易情况 | C8: 正常 | D8: 正常 | E8: 正常 | F8: 正常
A9: 交易方式 | D9: 挂牌出让 | E9: 挂牌出让 | F9: 挂牌出让
A10: 土地用途 | C10: 住宅用地 | D10: 住宅用地 | E10: 住宅用地 | F10: 住宅用地
A11: 土地剩余使用年期 | C11: 54.6年 | D11: 70年 | E11: 70年 | F11: 70年
A12: 区域因素 | B12: 商服繁华程度 | C12: 区域内有天印商场商业设施，繁华程度较好 | D12: 区域内有天印商场商业设施，繁华程度较好 | E12: 区域内无大型商业设施，繁华程度较劣 | F12: 区域内无大型商业设施，繁华程度较劣
B13: 公用设施便利度 | C13: 区域内有东山小学、岔路学校，公用设施便利度一般 | D13: 区域内有南京市竹山中学，公用设施便利度一般 | E13: 区域内有上坊中学，公用设施便利度一般 | F13: 区域内有东山外国语学校，公用设施便利度较好
B14: 公共交通便利度 | C14: 区域内有地铁1号南延线及公交车，公共交通便利度好 | D14: 区域内有地铁1号南延线及公交车，公共交通便利度好 | E14: 区域内无地铁线路，只有公交车，公共交通便利度一般 | F14: 区域内无地铁线路，只有公交车，公共交通便利度一般
B15: 道路级别状况 | C15: 区域内以主干道为主，道路级别优 | D15: 区域内以主干道为主，道路级别优 | E15: 区域内以主干道为主，道路级别优 | F15: 区域内以主干道为主，道路级别优
B16: 文体设施状况 | C16: 区域内有江宁文化馆，江宁博物馆，文体设施状况较优 | D16: 区域内有江宁文化馆，江宁博物馆，文体设施状况较优 | E16: 区域内无大型文体设施，文体设施状况较劣 | F16: 区域内无大型文体设施，文体设施状况较劣
B17: 环境质量状况 | C17: 区域内环境质量较好 | D17: 区域内环境质量较好 | E17: 区域内环境质量较好 | F17: 区域内环境质量较好
B18: 土地利用状况 | C18: 区域内以住宅用地为主 | D18: 区域内住宅用地和工业用地并重 | E18: 区域内以住宅用地为主 | F18: 区域内住宅用地和工业用地并重
A19: 个别因素 | B19: 规划容积率 | C19: 0.9 | D19: 2.56 | E19: 2.19 | F19: 2.5
B20: 宗地自然条件 | C20: 宗地自然条件好 | D20: 宗地自然条件好 | E20: 宗地自然条件好 | F20: 宗地自然条件好
B21: 宗地临路条件 | C21: 宗地临主干道宏运大道，临路状况好 | D21: 宗地临主干道天印大道、科建路，临路状况好 | E21: 宗地临主干道天佑路、天环路，临路状况好 | F21: 宗地临主干道润麒路、天云路，临路状况好
B22: 宗地距公共交通站点的距离 | C22: 距地铁1号南延线双龙大道站2KM，评价等级优 | D22: 距地铁1号南延线天印大道站1.5KM，评价等级优 | E22: 距东山公交总站2KM，评价等级一般 | F22: 距东山公交总站4.8KM，评价等级劣
B23: 宗地面积 | C23: 15994m2，面积适宜 | D23: 153260.9m2，面积过大 | E23: 34623.03m2，面积适宜 | F23: 86628.01m2，面积较大
B24: 宗地形状 | C24: 宗地形状较不规则 | D24: 宗地形状较规则 | E24: 宗地形状较规则 | F24: 宗地形状较规则
B25: 拟开发物业类型 | C25: 低密度叠加别墅 | D25: 高层 | E25: 小高层 | F25: 高层
B26: 有无代建设施 | C26: 无代建设施 | D26: 有代建公用设施 | E26: 有代建公用设施 | F26: 无代建设施
P28: 99.3 | Q28: 100
Q29: 100 | R29: =10000/P28 -> 100.7
A30: 比较因素条件指数表
A31: 项目名称 | C31: 待估宗地 | D31: 案例A | E31: 案例B | F31: 案例C
A32: 项目位置 | C32: 宏运大道2298号 | D32: 江宁区天印大道以西、科建路以南地块 | E32: 江宁区东山街道天佑路以东、天环路以南地块 | F32: 江宁区东山街道润麒路以东、天云路以南地块
A33: 成交单价（元/㎡） | C33: =C6 -> 待估 | D33: =D6 -> 36278.01 | E33: =E6 -> 30615.46 | F33: =F6 -> 34977.14
A34: 交易日期 | C34: 100 | D34: 100 | E34: 100 | F34: 100
A35: 交易情况 | C35: 100 | D35: 100 | E35: 100 | F35: 100
A36: 交易方式 | C36: 100 | D36: 100 | E36: 100 | F36: 100
A37: 土地用途 | C37: 100 | D37: 100 | E37: 100 | F37: 100
A38: 区域因素 | B38: 商服繁华程度 | C38: 100 | D38: 100 | E38: 96 | F38: 96
B39: 公用设施便利度 | C39: 100 | D39: 100 | E39: 100 | F39: 102
B40: 公共交通便利度 | C40: 100 | D40: 100 | E40: 96 | F40: 96
B41: 道路级别状况 | C41: 100 | D41: 100 | E41: 100 | F41: 100
...

Sheet 容积率修正系数
A1: 表2-41 住宅用地容积率修正系数表
A2: 容积率 | B2: 修正系数 | C2: 容积率 | D2: 修正系数 | E2: 容积率 | F2: 修正系数 | G2: 容积率 | H2: 修正系数
A3: ≤0.6 | B3: 0.491 | C3: 2 | D3: 1.201 | E3: 3.4 | F3: 1.89 | G3: 4.8 | H3: 2.558
A4: 0.7 | B4: 0.542 | C4: 2.1 | D4: 1.251 | E4: 3.5 | F4: 1.938 | G4: 4.9 | H4: 2.604
A5: 0.8 | B5: 0.594 | C5: 2.2 | D5: 1.301 | E5: 3.6 | F5: 1.987 | G5: 5 | H5: 2.652
A6: 0.9 | B6: 0.645 | C6: 2.3 | D6: 1.35 | E6: 3.7 | F6: 2.034 | G6: 5.1 | H6: 2.698
A7: 1 | B7: 0.696 | C7: 2.4 | D7: 1.401 | E7: 3.8 | F7: 2.083 | G7: 5.2 | H7: 2.745 | J7: 容积率 | K7: 修正系数
A8: 1.1 | B8: 0.747 | C8: 2.5 | D8: 1.45 | E8: 3.9 | F8: 2.131 | G8: 5.3 | H8: 2.791 | J8: 2.19 | K8: =ROUND((D5-D4)/10*9+D4,3) -> 1.296
A9: 1.2 | B9: 0.798 | C9: 2.6 | D9: 1.499 | E9: 4 | F9: 2.179 | G9: 5.4 | H9: 2.838 | J9: 2.56 | K9: =ROUND((D9-D8)/10*6+D8,3) -> 1.479
A10: 1.3 | B10: 0.848 | C10: 2.7 | D10: 1.548 | E10: 4.1 | F10: 2.226 | G10: 5.5 | H10: 2.884
A11: 1.4 | B11: 0.9 | C11: 2.8 | D11: 1.597 | E11: 4.2 | F11: 2.275 | G11: 5.6 | H11: 2.93
A12: 1.5 | B12: 0.95 | C12: 2.9 | D12: 1.647 | E12: 4.3 | F12: 2.322 | G12: 5.7 | H12: 2.975
A13: 1.6 | B13: 1 | C13: 3 | D13: 1.695 | E13: 4.4 | F13: 2.369 | G13: 5.8 | H13: 3.022
A14: 1.7 | B14: 1.05 | C14: 3.1 | D14: 1.744 | E14: 4.5 | F14: 2.416 | G14: 5.9 | H14: 3.068
A15: 1.8 | B15: 1.101 | C15: 3.2 | D15: 1.793 | E15: 4.6 | F15: 2.464 | G15: ≥6.0 | H15: 3.113
A16: 1.9 | B16: 1.151 | C16: 3.3 | D16: 1.842 | E16: 4.7 | F16: 2.511

Sheet 位置图
