Workbook
Name a: #REF!
Name a: #REF!
Name Document_array: {"Book1","公路收费权测算表.xls"}
Name Document_array: {"Book1","公路收费权测算表.xls"}
Name E5897844: #REF!
Name E5897844: #REF!
Name FANWEI1: [1]索引表!$C$4:$C$101
Name Payment_Number: ROW()-Header_Row
Name Payment_Number: ROW()-Header_Row
Name Print_Area_MI: #REF!
Name Print_Area_MI: #REF!
Name print_area1: #REF!
Name print_area1: #REF!
Name UFPrn20030702160950: #REF!
Name UFPrn20030702160950: #REF!
Name Work_Program_By_Area_List: #REF!
Name Work_Program_By_Area_List: #REF!
Name ww: #REF!
Name ww: #REF!
Name wwwwwwwwwwwww: ROW()-Header_Row
Name wwwwwwwwwwwww: ROW()-Header_Row
Name 安置补助费: #REF!
Name 安置补助费: #REF!
Name 大多数: [2]XL4Poppy!$A$15
Name 工作表: #REF!
Name 工作表: #REF!
Name 固定资产: [3]XL4Poppy!$A$15
Name 年初短期投资: #REF!
Name 年初短期投资: #REF!
Name 年初货币资金: #REF!
Name 年初货币资金: #REF!
Name 年初应收票据: #REF!
Name 年初应收票据: #REF!
Name 土地18: {"Book1","公路收费权测算表.xls"}
Name 土地18: {"Book1","公路收费权测算表.xls"}
Name 无形资产土地使用权账面价值: [4]土地评估明细表!#REF!
Name 无形资产土地使用权账面价值: [4]土地评估明细表!#REF!
Name 序号: #REF!
Name 序号: #REF!
Name 资料查证及特殊约定事项说明: #REF!
Name 资料查证及特殊约定事项说明: #REF!
Name 전: #REF!
Name 전: #REF!
Name 주택사업본부: #REF!
Name 주택사업본부: #REF!
Name 철구사업본부: #REF!
Name 철구사업본부: #REF!

Sheet 评估案例
A1: 评估案例
A2: http://www.landjs.com/web/cjgs_list.aspx?xmlx=&xzq=3212&LAND_USE=&REMISE_TYPE=&LAND_POSITION=&PARCEL_NO=&minqdrq=&maxqdrq=&mj=
A3: 定位 | B3: 行政区 | C3: 地块编号 | D3: 宗地位置 | E3: 土地用途 | F3: 成交时间 | G3: 面积(m2) | H3: 金额(万元) | I3: 单价 | J3: 容积率 | K3: 容积率修正系数（商业） | L3: 容积率修正系数（住宅） | N3: 评估单价 | R3: 商业案例A
B4: 泰州市本级 | C4: 泰地示告[2017]5-1号 | D4: 海陵区税务东街27号14室 | E4: 商业 | F4: 43103 | G4: 15.5 | H4: 20.2708 | I4: =H4*10000/G4 -> 13077.94 | J4: =44.29/G4 -> 2.86 | K4: 1.505 | N4: =H4*10000/G4 -> 13077.94 | Q4: 地块编号 | R4: [2016]2-2号
B5: 泰州市本级 | C5: 泰地储告〔2017〕7-4号 | D5: 海陵区梅兰西路北侧、青年南路西侧 | E5: 住宅 | F5: 43076 | G5: 47586 | H5: 65500 | I5: =H5*10000/G5 -> 13764.55 | J5: 1.60≤容积率≤1.80 | L5: 1.169 | N5: =H5*10000/G5 -> 13764.55 | Q5: 公告编号 | R5: 泰地储告[2016]2号
B6: 泰州市本级 | C6: 泰地储告〔2017〕7-3号 | D6: 泰州经济开发区青年南路西侧、苏源花园南侧 | E6: 住宅 | F6: 43076 | G6: 122257 | H6: 170100 | I6: =H6*10000/G6 -> 13913.31 | J6: 1.60≤容积率≤1.80 | L6: 1.169 | N6: =H6*10000/G6 -> 13913.31 | Q6: 土地位置 | R6: 海陵区鼓楼南路东侧、老通扬运河北侧25米
B7: 泰州市本级 | C7: 泰地储告〔2017〕7-2号 | D7: 泰州经济开发区凤凰西路北侧、天虹路西侧 | E7: 住宅 | F7: 43076 | G7: 42150 | H7: 34800 | I7: =H7*10000/G7 -> 8256.23 | J7: 1.0010≤容积率≤1.20 | L7: 0.831 | N7: =H7*10000/G7 -> 8256.23 | Q7: 公示开始时间 | R7: 42405 | S7: 公示截止时间 | T7: 42414
B8: 泰州市本级 | C8: 泰地储告〔2017〕7-1号 | D8: 海陵区东风北路东侧、森园路北侧 | E8: 住宅 | F8: 43076 | G8: 112726 | H8: 120100 | I8: =H8*10000/G8 -> 10654.15 | J8: 1.74≤容积率≤1.93 | L8: 1.225 | N8: =H8*10000/G8 -> 10654.15 | Q8: 所属行政区 | R8: 泰州市本级 | S8: 出让面积（平方米） | T8: 710
B9: 泰州市本级 | C9: 泰地储告〔2017〕5-2号 | D9: 泰州医药高新区会展路西侧、会展1号支路... | E9: 商业 | F9: 42943 | G9: 17217 | H9: 4800 | I9: =H9*10000/G9 -> 2787.94 | J9: 5.66≤容积率≤5.86 | K9: 1.514 | N9: =H9*10000/G9 -> 2787.94 | Q9: 建筑面积（平方米） | S9: 规划用途 | T9: 商业
B10: 泰州市本级 | C10: 泰地储告〔2017〕5-1号 | D10: 泰州医药高新区曙光路北侧、会展路西侧 | E10: 商业 | F10: 42943 | G10: 35621 | H10: 9600 | I10: =H10*10000/G10 -> 2695.04 | J10: 3.30≤容积率≤3.50 | K10: 1.514 | N10: =H10*10000/G10 -> 2695.04 | Q10: 出让年限（年） | R10: 40 | S10: 交易方式 | T10: 挂牌
B11: 泰州市本级 | C11: 泰地储告〔2017〕4-3号 | D11: 海陵区迎宾路南侧、春晖路东侧 | E11: 商住 | F11: 42916 | G11: 57099 | H11: 60400 | I11: =H11*10000/G11 -> 10578.12 | J11: 1.50≤容积率≤1.70 | K11: 1.253 | L11: 1.113 | N11: =H11*10000/G11 -> 10578.12 | Q11: 起始价（万元） | R11: 560 | S11: 竞得价（万元） | T11: 600
B12: 泰州市本级 | C12: 泰地储告〔2017〕4-2号 | D12: 周山河街区引江路南侧、东周港路西测 | E12: 住宅 | F12: 42916 | G12: 77609 | H12: 94400 | I12: =H12*10000/G12 -> 12163.54 | J12: 2≤容积率≤2.20 | L12: 1.392 | N12: =H12*10000/G12 -> 12163.54 | Q12: 竞得单位 | R12: 泰州凤城河建设发展有限公司 | S12: 成交时间 | T12: 42404
B13: 泰州市本级 | C13: 泰地储告〔2017〕4-1号 | D13: 周山河街区海军大道北侧约50米、东周港... | E13: 住宅 | F13: 42916 | G13: 56724 | H13: 66400 | I13: =H13*10000/G13 -> 11705.8 | J13: 1.90≤容积率≤2.10 | L13: 1.336 | N13: =H13*10000/G13 -> 11705.8
B14: 泰州市本级 | C14: 泰地储告[2017]3-1号 | D14: 海陵区青年南路西侧、规划虹桥西街北侧约... | E14: 商业 | F14: 42908 | G14: 2943 | H14: 2600 | I14: =H14*10000/G14 -> 8834.52 | J14: 1.20≤容积率≤1.40 | K14: 1.138 | N14: =H14*10000/G14 -> 8834.52 | R14: 商业案例B
B15: 泰州市本级 | C15: 泰地示告[2017]2-1号 | D15: 泰州市海陵区周武巷34号 | E15: 住宅 | F15: 42858 | G15: 463.8 | H15: 51.02 | I15: =H15*10000/G15 -> 1100.04 | N15: =H15*10000/G15 -> 1100.04 | Q15: 地块编号 | R15: 泰地储告[2017]3-1号
B16: 泰州市本级 | C16: 泰地储告[2017]2-1号 | D16: 东至海陵区海阳大酒店、南至泰州市光孝律... | E16: 商业 | F16: 42852 | G16: 1507 | H16: 1280 | I16: =H16*10000/G16 -> 8493.7 | J16: 1.80≤容积率≤2 | K16: 1.348 | N16: =H16*10000/G16 -> 8493.7 | Q16: 公告编号 | R16: 泰地储告[2017]3号
B17: 泰州市本级 | C17: 泰地储告[2017]1-2号 | D17: 医药高新区会展2号支路北侧、3号支路西侧 | E17: 商业 | F17: 42747 | G17: 9248 | H17: 2500 | I17: =H17*10000/G17 -> 2703.29 | J17: 容积率=4.66 | K17: 1.514 | N17: =H17*10000/G17 -> 2703.29 | Q17: 土地位置 | R17: 海陵区青年南路西侧、规划虹桥西街北侧约30米
B18: 泰州市本级 | C18: 泰地储告[2016]17-4号 | D18: 海陵区海陵北路东侧、森园路南侧 | E18: 商住 | F18: 42733 | G18: 32122 | H18: 14700 | I18: =H18*10000/G18 -> 4576.3 | J18: 1.40≤容积率≤1.60 | K18: 1.217 | L18: 1.057 | N18: =H18*10000/G18 -> 4576.3 | Q18: 公示开始时间 | R18: 42913 | S18: 公示截止时间
B19: 泰州市本级 | C19: 泰地储告[2016]17-3号 | D19: 海陵区南通路北侧约60米、海陵北路东侧 | E19: 商住 | F19: 42733 | G19: 95526 | H19: 47200 | I19: =H19*10000/G19 -> 4941.06 | J19: 1.17≤容积率≤1.37 | K19: 1.138 | L19: 0.944 | N19: =H19*10000/G19 -> 4941.06 | Q19: 所属行政区 | R19: 泰州市本级 | S19: 出让面积（平方米） | T19: 2943
B20: 泰州市本级 | C20: 泰地储告[2016]17-2号 | D20: 医药高新区兴泰南路东侧、永兴路北侧 | E20: 商住 | F20: 42733 | G20: 52394 | H20: 21300 | I20: =H20*10000/G20 -> 4065.35 | J20: 1.10≤容积率≤1.30 | K20: 1.094 | L20: 0.888 | N20: =H20*10000/G20 -> 4065.35 | Q20: 建筑面积（平方米） | S20: 规划用途 | T20: 商业
B21: 泰州市本级 | C21: 泰地储告[2016]17-1号 | D21: 高港区永安洲镇高港大道西侧、国学路北侧 | E21: 商住 | F21: 42733 | G21: 71613 | H21: 11700 | I21: =H21*10000/G21 -> 1633.78 | J21: 1.60≤容积率≤1.80 | K21: 1.287 | L21: 1.169 | N21: =H21*10000/G21 -> 1633.78 | Q21: 出让年限（年） | R21: 40 | S21: 交易方式 | T21: 挂牌
B22: 泰州市本级 | C22: 泰地示告[2016]8-1号 | D22: 海陵区莲花1号小区37幢南大门西第5间 | E22: 商业 | F22: 42730 | G22: 97.8 | H22: 34.2363 | I22: =H22*10000/G22 -> 3500.64 | N22: =H22*10000/G22 -> 3500.64 | Q22: 起始价（万元） | R22: 2400 | S22: 竞得价（万元） | T22: 2600
B23: 泰州市本级 | C23: 泰地储告〔2016〕16-1号 | D23: 医药高新区泰州大道西侧、学院路南侧 | E23: 商业 | F23: 42726 | G23: 97720 | H23: 19000 | I23: =H23*10000/G23 -> 1944.33 | J23: 1.01≤容积率≤1.12 | K23: 1.024 | N23: =H23*10000/G23 -> 1944.33 | Q23: 竞得单位 | R23: 泰州市鑫通停车场建设管理有限公司 | S23: 成交时间 | T23: 42908
B24: 泰州市本级 | C24: 泰地储告[2016]15-2号 | D24: 海陵区迎春东路北侧、231省道东侧约5... | E24: 商业 | F24: 42712 | G24: 26740 | H24: 7600 | I24: =H24*10000/G24 -> 2842.18 | J24: 2.35≤容积率≤2.55 | K24: 1.475 | N24: =H24*10000/G24 -> 2842.18
B25: 泰州市本级 | C25: 泰地储告[2016]15-1号 | D25: 泰州经济开发区梅兰西路北侧、天虹路西侧 | E25: 住宅 | F25: 42712 | G25: 58082 | H25: 19900 | I25: =H25*10000/G25 -> 3426.19 | J25: 1.01≤容积率≤1.20 | L25: 0.831 | N25: =H25*10000/G25 -> 3426.19 | R25: 商业案例C
B26: 泰州市本级 | C26: [2016]14-2号 | D26: 医药高新区口泰路东侧、鸭子河南侧 | E26: 商业 | F26: 42705 | G26: 54652 | H26: 8300 | I26: =H26*10000/G26 -> 1518.7 | J26: 容积率=0.52 | K26: 0.725 | N26: =H26*10000/G26 -> 1518.7 | Q26: 地块编号 | R26: 泰地储告[2017]2-1号
B27: 泰州市本级 | C27: [2016]14-1号 | D27: 医药高新区海陵南路东侧、药城大道北侧 | E27: 住宅 | F27: 42705 | G27: 122113 | H27: 33200 | I27: =H27*10000/G27 -> 2718.79 | J27: 1.42≤容积率≤1.62 | L27: 1.057 | N27: =H27*10000/G27 -> 2718.79 | Q27: 公告编号 | R27: 泰地储告[2017]2号
B28: 泰州市本级 | C28: 泰地示告[2016]6-1号 | D28: 海陵区莲花1号小区B1（8-9） | E28: 商业 | F28: 42643 | G28: 87 | H28: 52.1948 | I28: =H28*10000/G28 -> 5999.4 | N28: =H28*10000/G28 -> 5999.4 | Q28: 土地位置 | R28: 东至海陵区海阳大酒店、南至泰州市光孝律寺、西至巷道、北至人民西路
B29: 泰州市本级 | C29: 〔2016〕12-1号 | D29: 高港区永安洲镇沿江高等级公路西侧、联江... | E29: 商业 | F29: 42635 | G29: 3450 | H29: 640 | I29: =H29*10000/G29 -> 1855.07 | J29: 容积率≤0.70 | K29: 0.842 | N29: =H29*10000/G29 -> 1855.07 | Q29: 公示开始时间 | R29: 42854 | S29: 公示截止时间
B30: 泰州市本级 | C30: 泰地示告[2016]5-1号 | D30: 海陵区西仓路11号1幢13室 | E30: 商业 | F30: 42618 | G30: 8.03 | H30: 19.2183 | I30: =H30*10000/G30 -> 23933.13 | N30: =H30*10000/G30 -> 23933.13 | Q30: 所属行政区 | R30: 泰州市本级 | S30: 出让面积（平方米） | T30: 1507
B31: 泰州市本级 | C31: 〔2016〕11-1号 | D31: 海陵区祥泰路东侧、规划泰九路北侧 | E31: 商业 | F31: 42600 | G31: 6237 | H31: 880 | I31: =H31*10000/G31 -> 1410.93 | J31: 0.20≤容积率≤0.40 | K31: 0.598 | N31: =H31*10000/G31 -> 1410.93 | Q31: 建筑面积（平方米） | S31: 规划用途 | T31: 商业
B32: 泰州市本级 | C32: 〔2016〕10-1号 | D32: 海陵区扬州路北侧、杰盛西苑东侧 | E32: 商业 | F32: 42593 | G32: 7702 | H32: 2650 | I32: =H32*10000/G32 -> 3440.66 | J32: 2.15≤容积率≤2.35 | K32: 1.442 | N32: =H32*10000/G32 -> 3440.66 | Q32: 出让年限（年） | R32: 40 | S32: 交易方式 | T32: 挂牌
B33: 泰州市本级 | C33: [2016]9-1号 | D33: 泰州经济开发区梅兰西路南侧、南官河西侧 | E33: 商住 | F33: 42572 | G33: 82170 | H33: 24100 | I33: =H33*10000/G33 -> 2932.94 | J33: 1.20≤容积率≤1.29 | K33: 1.094 | L33: 0.888 | N33: =H33*10000/G33 -> 2932.94 | Q33: 起始价（万元） | R33: 1220 | S33: 竞得价（万元） | T33: 1280
B34: 泰州市本级 | C34: [2016]8-1号 | D34: 高港区王营路东侧、春港路南侧 | E34: 商住 | F34: 42565 | G34: 74170 | H34: 2700 | I34: =H34*10000/G34 -> 364.03 | J34: 2≤容积率≤2.20 | K34: 1.4 | L34: 1.392 | N34: =H34*10000/G34 -> 364.03 | Q34: 竞得单位 | R34: 泰州市鑫通置业有限公司 | S34: 成交时间 | T34: 42852
B35: 泰州市本级 | C35: 泰地示告[2016]3-1号 | D35: 海陵区迎春路二期04、05室 | E35: 商业 | F35: 42538 | G35: 40.58 | H35: 93.4684 | I35: =H35*10000/G35 -> 23033.12 | N35: =H35*10000/G35 -> 23033.12
B36: 泰州市本级 | C36: [2016]6-4号 | D36: 医药高新区药城大道南侧、工业邻里中心西侧 | E36: 住宅 | F36: 42495 | G36: 26218 | H36: 11700 | I36: =H36*10000/G36 -> 4462.58 | J36: 2.80≤容积率≤3 | L36: 1.831 | N36: =H36*10000/G36 -> 4462.58
B37: 泰州市本级 | C37: [2016]6-3号 | D37: 医药高新区仲野路北侧、会展路东侧 | E37: 住宅 | F37: 42495 | G37: 34380 | H37: 15300 | I37: =H37*10000/G37 -> 4450.26 | J37: 2.80≤容积率≤3 | L37: 1.831 | N37: =H37*10000/G37 -> 4450.26
B38: 泰州市本级 | C38: [2016]6-2号 | D38: 医药高新区海陵南路东侧、药城大道南侧 | E38: 住宅 | F38: 42495 | G38: 58141 | H38: 26600 | I38: =H38*10000/G38 -> 4575.08 | J38: 2.80≤容积率≤3 | L38: 1.831 | N38: =H38*10000/G38 -> 4575.08
B39: 泰州市本级 | C39: [2016]6-1号 | D39: 医药高新区海陵南路东侧约300米、药城... | E39: 住宅 | F39: 42495 | G39: 61693 | H39: 28000 | I39: =H39*10000/G39 -> 4538.6 | J39: 2.80≤容积率≤3 | L39: 1.831 | N39: =H39*10000/G39 -> 4538.6
B40: 泰州市本级 | C40: 泰地示告[2016]1-1号 | D40: 海陵区梅兰东路58号 | E40: 商业 | F40: 42475 | G40: 261.83 | H40: 84.2726 | I40: =H40*10000/G40 -> 3218.6 | N40: =H40*10000/G40 -> 3218.6
...

Sheet 商服用地市场法
A1: 被评估单位： | B1: 泰州市**** | C1: 评估人员： | E1: 索引号： | F1: C4-12-1/3
A2: 评估基准日： | B2: 43167 | C2: 复核人员： | D2: =[5]步骤复核表!B5 | E2: 页 次：
A3: 市场比较法计算表
A4: 宗地及实例 比较因素 | C4: 待估宗地 | D4: 案例A | E4: 案例B | F4: 案例C | I4: http://www.landvalue.com.cn/Lvmonitor/Index
A5: 土地单价（元/m2） | C5: 待评估 | D5: =[4]评估案例!I48 -> 8450.7 | E5: =[4]评估案例!I14 -> 8834.52 | F5: =[4]评估案例!I16 -> 8493.7 | I5: 苏中地区监测指标情况一览表
A6: 交易时间 | C6: 2017/12/31 | D6: =[4]评估案例!F48 -> 42404 | E6: =[4]评估案例!F14 -> 42908 | F6: =[4]评估案例!F16 -> 42852 | I6: 商业 | N6: 住宅
A7: 交易情况 | C7: 正常 | D7: 正常 | E7: 正常 | F7: 正常 | I7: 时间 | J7: 水平值 | K7: 环比增长率 | L7: 指数 | N7: 时间 | O7: 水平值 | P7: 环比增长率 | Q7: 指数
A8: 交易方式 | C8: 出让 | D8: 出让 | E8: 出让 | F8: 出让
A9: 土地用途 | C9: 商业 | D9: 商业 | E9: 商业 | F9: 商业 | I9: 2017.1 | J9: 2679 | K9: 0.19 | L9: =ROUND(J9/$J$12*100,2) -> 99.19 | N9: 2017.1 | O9: 1818 | P9: 2.02 | Q9: =ROUND(O9/$O$12*100,2) -> 97.53
A10: 土地使用年期 | C10: =C52 -> 35.85 | D10: 40 | E10: 40 | F10: 40 | I10: 2017.2 | J10: 2685 | K10: 0.22 | L10: =ROUND(J10/$J$12*100,2) -> 99.41 | N10: 2017.2 | O10: 1826 | P10: 0.44 | Q10: =ROUND(O10/$O$12*100,2) -> 97.96
A11: 区域因素 | B11: 区域繁华程度 | C11: 位于海陵区泰九路，商服繁华程度优 | D11: 位于海陵区鼓楼南路东侧，商服繁华程度优 | E11: 位于海陵区规划虹桥西街北侧，商服繁华程度一般 | F11: 位于海陵区海阳大酒店附近，商服繁华程度一般 | I11: 2017.3 | J11: 2694 | K11: 0.34 | L11: =ROUND(J11/$J$12*100,2) -> 99.74 | N11: 2017.3 | O11: 1834 | P11: 0.44 | Q11: =ROUND(O11/$O$12*100,2) -> 98.39
B12: 道路通达度 | C12: 位于泰九路，道路通达度较优 | D12: 位于鼓楼南路，道路通达度较优 | E12: 位于规划虹桥西街，道路通达度一般 | F12: 位于巷道 ，道路通达度一般 | I12: 2017.4 | J12: 2701 | K12: 0.26 | L12: 100 | N12: 2017.4 | O12: 1864 | P12: 1.64 | Q12: 100
B13: 交通便捷度 | C13: 周边有22路;23路;301路;301路夜班，公交便捷度较优 | D13: 周边有15路;16路;18路;603路，公交便捷度较优 | E13: 周边有1路;3路;12路;15路;26路;113路;118路，公交便捷度较优 | F13: 周边有17路;23路;公交便捷度一般 | I13: 2015.4 | J13: 2666 | K13: 0.04 | L13: =ROUND(J13/$J$12*100,2) -> 98.7 | N13: 2015.4 | O13: 1778 | P13: -0.06 | Q13: =ROUND(O13/$O$12*100,2) -> 95.39
B14: 基础设施状况 | C14: 宗地红线外市政基础设施达到五通一平，水电气较完备，基础设施较优 | D14: 宗地红线外市政基础设施达到五通一平，水电气较完备，基础设施较优 | E14: 宗地红线外市政基础设施达到五通一平，水电气较完备，基础设施较优 | F14: 宗地红线外市政基础设施达到五通一平，水电气一般，基础设施一般 | I14: 2016.1 | J14: 2665 | K14: -0.04 | L14: =ROUND(J14/$J$12*100,2) -> 98.67 | N14: 2016.1 | O14: 1776 | P14: -0.11 | Q14: =ROUND(O14/$O$12*100,2) -> 95.28
B15: 公用设施状况 | C15: 超市、银行、医院、教育、农贸市场等较完备，公用设施状况一般 | D15: 超市、银行、医院、教育、农贸市场等较完备，公用设施状况一般 | E15: 超市、银行、医院、教育、农贸市场等较完备，公用设施状况一般 | F15: 超市、银行、医院、教育、农贸市场等较完备，公用设施状况一般 | I15: 2016.2 | J15: 2666 | K15: 0.04 | L15: =ROUND(J15/$J$12*100,2) -> 98.7 | N15: 2016.2 | O15: 1776 | P15: 0 | Q15: =ROUND(O15/$O$12*100,2) -> 95.28
B16: 区域规划 | C16: 区域规划无限制，一般 | D16: 区域规划无限制，一般 | E16: 区域规划无限制，一般 | F16: 区域规划无限制，一般 | I16: 2016.3 | J16: 2668 | K16: 0.08 | L16: =ROUND(J16/$J$12*100,2) -> 98.78 | N16: 2016.3 | O16: 1777 | P16: 0.06 | Q16: =ROUND(O16/$O$12*100,2) -> 95.33
B17: 环境条件 | C17: 人文环境、自然环境一般 | D17: 人文环境、自然环境一般 | E17: 人文环境、自然环境一般 | F17: 人文环境、自然环境一般 | I17: 2016.4 | J17: 2674 | K17: 0.22 | L17: =ROUND(J17/$J$12*100,2) -> 99 | N17: 2016.4 | O17: 1782 | P17: 0.28 | Q17: =ROUND(O17/$O$12*100,2) -> 95.6
A18: 个别因素 | B18: 宗地位置 | C18: 位于海陵区泰九路，位置较优 | D18: 位于海陵区鼓楼南路东侧，位置较优 | E18: 位于海陵区规划虹桥西街北侧，位置较优 | F18: 位于海陵区海阳大酒店附近，位置较优
B19: 宗地面积 | C19: 面积适宜 | D19: 面积适宜 | E19: 面积适宜 | F19: 面积适宜
B20: 宗地形状 | C20: 较规则，基本无影响 | D20: 较规则，基本无影响 | E20: 较规则，基本无影响 | F20: 较规则，基本无影响
B21: 宗地内开发水平 | C21: 场地内平整 | D21: 场地内平整 | E21: 场地内平整 | F21: 场地内平整
B22: 地质条件 | C22: 地质条件一般，地基承载力一般 | D22: 地质条件一般，地基承载力一般 | E22: 地质条件一般，地基承载力一般 | F22: 地质条件一般，地基承载力一般
B23: 容积率 | C23: 2.8<容积率≤3 | D23: 0.89≤容积率≤0.99 | E23: 1.20≤容积率≤1.40 | F23: 1.80≤容积率≤2
A25: 宗地及实例 比较因素 | C25: 待估宗地 | D25: 案例A | E25: 案例B | F25: 案例C
A26: 土地单价（元/m2） | C26: 待评估 | D26: =D5 -> 8450.7 | E26: =E5 -> 8834.52 | F26: =F5 -> 8493.7
A27: 交易时间 | C27: 100 | D27: 98.67 | E27: 99.41 | F27: 99.41
A28: 交易情况 | C28: 100 | D28: 100 | E28: 100 | F28: 100
A29: 交易方式 | C29: 100 | D29: 100 | E29: 100 | F29: 100
A30: 土地用途 | C30: 100 | D30: 100 | E30: 100 | F30: 100
A31: 土地使用年期 | C31: =C53 -> 0.9366 | D31: =ROUND(1-1/(1+0.08)^40,4) -> 0.954 | E31: =ROUND(1-1/(1+0.08)^40,4) -> 0.954 | F31: =ROUND(1-1/(1+0.08)^40,4) -> 0.954
A32: 区域因素 | B32: 区域繁华程度 | C32: 100 | D32: 100 | E32: 95 | F32: 95
B33: 道路通达度 | C33: 100 | D33: 100 | E33: 95 | F33: 95
B34: 交通便捷度 | C34: 100 | D34: 100 | E34: 100 | F34: 95
B35: 基础设施状况 | C35: 100 | D35: 100 | E35: 100 | F35: 95
B36: 公用设施状况 | C36: 100 | D36: 100 | E36: 100 | F36: 100
B37: 区域规划 | C37: 100 | D37: 100 | E37: 100 | F37: 100
B38: 环境质量优劣度 | C38: 100 | D38: 100 | E38: 100 | F38: 100
A39: 个别因素 | B39: 宗地位置 | C39: 100 | D39: 100 | E39: 100 | F39: 100
B40: 宗地面积 | C40: 100 | D40: 100 | E40: 100 | F40: 100
B41: 宗地形状 | C41: 100 | D41: 100 | E41: 100 | F41: 100
...
