Workbook
Name _2003_6_25: [1]ITEM!#REF!
Name _2003_6_25: [1]ITEM!#REF!
Name _2003_6_25: [1]ITEM!#REF!
Name _2003_6_25: [1]ITEM!#REF!
Name _2003_6_25: [1]ITEM!#REF!
Name _2003_6_25: [1]ITEM!#REF!
Name _BSP2: #REF!
Name _BSP2: #REF!
Name _BSP2: #REF!
Name _BSP2: #REF!
Name _BSP2: #REF!
Name _BSP2: #REF!
Name _BSP2: #REF!
Name _pgz101: #REF!
Name _pgz101: #REF!
Name _pgz101: #REF!
Name _pgz101: #REF!
Name _pgz101: #REF!
Name _pgz101: #REF!
Name _pgz101: #REF!
Name _pgz102: #REF!
Name _pgz102: #REF!
Name _pgz102: #REF!
Name _pgz102: #REF!
Name _pgz102: #REF!
Name _pgz102: #REF!
Name _pgz102: #REF!
Name _pgz103: #REF!
Name _pgz103: #REF!
Name _pgz103: #REF!
Name _pgz103: #REF!
Name _pgz103: #REF!
Name _pgz103: #REF!
Name _pgz103: #REF!
Name _pgz104: #REF!
Name _pgz104: #REF!
Name _pgz104: #REF!
Name _pgz104: #REF!
Name _pgz104: #REF!
Name _pgz104: #REF!
Name _pgz104: #REF!
Name _pgz105: #REF!
Name _pgz105: #REF!
Name _pgz105: #REF!
Name _pgz105: #REF!
Name _pgz105: #REF!
Name _pgz105: #REF!
Name _pgz105: #REF!
Name _pgz106: #REF!
Name _pgz106: #REF!
Name _pgz106: #REF!
Name _pgz106: #REF!
Name _pgz106: #REF!
Name _pgz106: #REF!
Name _pgz106: #REF!
Name _pgz511: #REF!
Name _pgz511: #REF!
Name _pgz511: #REF!
Name _pgz511: #REF!
Name _pgz511: #REF!

Sheet 记事
C2: 应用前提
C3: 1、稳定期增长率假设为零，如考虑永续增长，终值需另外用价值驱动因素模型计算。
C4: 2、未考虑预测期内被评估企业依靠收购所创造的收入增长。
C5: 3、FCFE模型只适用评估基准日及未来预测期间无付息负债的情形。
C6: 建模的规则
C7: 表中数字 | D7: 蓝字黄底表示手动录入数据
C8: 表中数字 | D8: 红字表示在该单元格中的公式左右不一样，或强调关注。
D9: 同一年的数据在不同表中均在同一列中，方便查找错误。
D10: 不要隐藏行和列，采用数据中的创建组和取消组合处理，易于查找数据。
D11: 单元格中的公式不要直接写入数据，数据由表外单元格链入。
D12: 工作底稿完成后无关数据全部删除，只保留有关数据。
C14: 密码0528
C15: V5.0修改记录
C16: 1、“1报表”营运能力分析财务指标非整年进行年化处理。
C17: 2、表“7折旧”、“8摊销”、“9溢余现金”、“10营运”进行拆分，表“7折旧”和“8摊销”“+”后隐藏的是自动计算公式，一般无需改动。
C18: 限制用途现金位置进行了移动；“9溢余现金”、“10营运”，增加了历史数据分析，反映趋势变化。
C19: 3、表“预测财报”布局调整：增加完成资产负债表、利润表剩余项目，后面报表自动计算得出财务指标，用于分析历史与未来趋势。
C20: 预测资产负债表可以合理分析企业未来的借款金额。
C21: 4、表“9财务费用”末端行增加(由预测资产负债表计算得出)新增借款，反映企业未来是否有资金缺口，需要融多少资金。
C22: 5、表“13FCFF”修改折现率计算方法——迭代计算。
C24: V5.1修改记录
C25: 1、表“7折旧”行42即“期末设备类账面净值”公式汇总错误，已修改。该行数据不影响估值，但影响“预测财报”数据。

Sheet 步骤
E1: 索引号：SY1
B2: 企业价值评估现金流量折现法(DCF)计算及步骤复核表
B3: ='1报表'!B12 -> 被评估单位：YLSJ公司 | D3: 评估基准日 | E3: ='1报表'!E5 -> 43281
B4: 评估人员 | D4: 现场工作日期
B5: 复核人 | D5: 复核日期
B6: 操作步骤与要求 | D6: 是 | E6: 不适用
B7: 一、前期工作
B8: 1.取得被评估企业前3~5年和本期审计报告、会计报表、科目明细表，以及相关收入、成本、费用等统计资料
B9: 2.取得企业资产、财务、经营状况资料，着重了解经营活动涉及的范围，收入、收益结构，资产配置情况，在此基础上区分企业经营活动和经营活动之外的其他活动涉及相关资产、负债、损益等。布置企业填报资产基础法申报表、收益预测申报表，并在资产基础法的申报表上标识经营性资产（负债）与非经营性资产（负债）。以上资料由企业盖章或签字确认。
B10: 二、统计、调整
B11: 3.根据评估业务的具体情况，在分析企业各科目明细的基础上，分析和调整被评估企业（1）财务报表编制基础；（2）非经常性收入和支出；（3）非经营性资产、负债和溢余资产及其相关的收入和支出。如涉及可比企业同理处理。
B12: 4.区分经营活动与其他活动，并统计、分析： a\营业收入；b\营业成本(材料、燃料动力、人工、制造费用)；c\税金及附加；d\折旧及摊销、固定及无形资产、长期待摊；e\销售、管理费用；f\资产减值损失、公允价值变动收益；g\营业外收支；h\财务费用
B13: 5.区分经营活动和其他活动，编制利润调整表
B14: 6.计算经营最低保有现金，测算溢余现金
B15: 7.区分经营活动和其他活动编制资产负债调整表
B16: 8.根据调整后的资产负债表、利润表，分析历史财务指标。
B17: 9.正确识别被评估企业所属行业，审慎选择参考上市公司，并统计相关财务指标
B18: 三、分析、预测
... B40: 金融资产、未并表的长期股权投资、投资性房地产以及溢余及非经营资产、负债等相关活动。

Sheet 1报表
B2: 输入信息
B3: 被评估单位： | E3: YLSJ公司
B4: 评估对象： | E4: 股东全部权益价值
B5: 评估基准日： | E5: 43281
B6: 短期预测(期)： | E6: 6
B7: 预测期间： | C7: =E5+1 -> 43282 | D7: To | E7: =DATE(YEAR(E5)+E6-1,12,31) -> 45291
B10: 资产负债表
B11: =B5&TEXT(E5,"YYYY/M/D") -> 评估基准日：2018/6/30
B12: =B3&E3 -> 被评估单位：YLSJ公司 | E12: 单位：万元
B13: 科目 | C13: =EDATE(D13,-12) -> 42735 | D13: =DATE(YEAR(E13)-1,12,31) -> 43100 | E13: =E5 -> 43281
B14: 流动资产：
B15: 货币资金 | C15: 606.91602 | D15: 422.55445 | E15: 125.24516
B16: 以公允价值计量且其变动计入当期损益的金融资产 | C16: 744.71178 | D16: 42.244674 | E16: 143.964
B17: 衍生金融资产
B18: 应收票据及应收账款 | C18: 915.13378 | D18: 747.61612 | E18: 479.66661
B19: 预付款项
A20: 保留 | B20: 应收利息
A21: 保留 | B21: 应收股利
B22: 其他应收款 | C22: 186.2834 | D22: 217.9241 | E22: 950.31863
B23: 存货
A24: 新准则 | B24: 合同资产
B25: 持有待售资产
B26: 一年内到期的非流动资产
B27: 其他流动资产 | C27: 0.575 | D27: 0.575 | E27: 0.575
B28: 流动资产合计 | C28: =SUM(C15:C27) -> 2453.62 | D28: =SUM(D15:D27) -> 1430.9143 | E28: =SUM(E15:E27) -> 1699.7694
B29: 非流动资产：
B30: 可供出售金融资产 | C30: 1.332422 | D30: 1.332422 | E30: 1.332422
B31: 持有至到期投资
A32: 新准则 | B32: 债权投资
A33: 新准则 | B33: 其他债权投资
B34: 长期应收款
B35: 长期股权投资 | C35: 3.465172 | D35: 3.465172 | E35: 3.465172
A36: 新准则 | B36: 其他权益工具投资
A37: 新准则 | B37: 其他非流动金融资产
B38: 投资性房地产
B39: 固定资产 | C39: 108.53785 | D39: 111.62056 | E39: 94.661335
B40: 在建工程
B41: 生产性生物资产
B42: 油气资产
B43: 无形资产 | C43: 0.477818 | D43: 9.480241 | E43: 5.916019
...

Sheet 2报表调整
B2: 资产负债调整表 | J2: 非经营性资产和负债分析表
B3: ='1报表'!B11 -> 评估基准日：2018/6/30 | K3: 根据资产负债核实表填写
B4: ='1报表'!B12 -> 被评估单位：YLSJ公司 | H4: 单位：万元
B5: 科目 | C5: ='1报表'!E13 -> 43281 | N5: 单位：万元
C6: 账面值 | D6: 重分类 | E6: 其中：非经营性资产、负债 | F6: 溢余资产 | G6: 经营性资产及负债账面值 | H6: 调整原因 | J6: 项目 | K6: ='1报表'!C13 -> 42735 | L6: ='1报表'!D13 -> 43100 | M6: ='1报表'!E13 -> 43281 | N6: 评估值
B7: 流动资产： | J7: 非经营性资产
B8: 货币资金 | C8: ='1报表'!E15 -> 125.24516 | D8: =C8 -> 125.24516 | F8: ='9溢余现金'!E25 -> 0 | G8: =D8-(E8+F8) -> 125.24516 | J8: 货币资金
B9: 交易性金融资产 | C9: ='1报表'!E16 -> 143.964 | D9: =C9 -> 143.964 | E9: 143.964 | G9: =D9-(E9+F9) -> 0 | H9: 非经常性损益 | J9: 交易性金融资产 | K9: ='1报表'!C16 -> 744.71178 | L9: ='1报表'!D16 -> 42.244674 | M9: =E9 -> 143.964 | N9: =M9 -> 143.964
B10: 衍生金融资产 | C10: ='1报表'!E17 -> 0 | D10: =C10 -> 0 | G10: =D10-(E10+F10) -> 0 | J10: 衍生金融资产 | K10: ='1报表'!C17 -> 0 | L10: ='1报表'!D17 -> 0 | M10: =E10 -> 0 | N10: =M10 -> 0
B11: 应收票据及应收账款 | C11: ='1报表'!E18 -> 479.66661 | D11: =C11 -> 479.66661 | G11: =D11-(E11+F11) -> 479.66661 | J11: 非经营性应收票据及应收账款 | M11: =E11 -> 0 | N11: =M11 -> 0
B12: 预付款项 | C12: ='1报表'!E19 -> 0 | D12: =C12 -> 0 | G12: =D12-(E12+F12) -> 0 | J12: 非经营性预付款项 | M12: =E12 -> 0 | N12: 0
B13: 应收利息 | C13: ='1报表'!E20 -> 0 | D13: =C13 -> 0 | G13: =D13-(E13+F13) -> 0 | J13: 应收利息 | K13: ='1报表'!C20 -> 0 | L13: ='1报表'!D20 -> 0 | M13: =E13 -> 0 | N13: =M13 -> 0
B14: 应收股利 | C14: ='1报表'!E21 -> 0 | D14: =C14 -> 0 | G14: =D14-(E14+F14) -> 0 | J14: 应收股利 | K14: ='1报表'!C21 -> 0 | L14: ='1报表'!D21 -> 0 | M14: =E14 -> 0 | N14: =M14 -> 0
B15: 其他应收款 | C15: ='1报表'!E22 -> 950.31863 | D15: =C15 -> 950.31863 | E15: 759.29843 | G15: =D15-(E15+F15) -> 191.0202 | H15: 退休股东费用和调整应收回的自然人股东分红 | J15: 非经营性其他应收款 | K15: 62.159376 | L15: 22.875 | M15: =E15 -> 759.29843 | N15: =M15 -> 759.29843 | O15: 退休股东费用和调整应收回的自然人股东分红
B16: 存货 | C16: ='1报表'!E23 -> 0 | D16: =C16 -> 0 | G16: =D16-(E16+F16) -> 0 | J16: 非经营、报废的存货 | M16: =E16 -> 0 | N16: =M16 -> 0
B17: 合同资产 | C17: ='1报表'!E24 -> 0 | D17: =C17 -> 0 | G17: =D17-(E17+F17) -> 0 | J17: 非经营性合同资产 | M17: =E17 -> 0 | N17: =M17 -> 0
B18: 持有待售资产 | C18: ='1报表'!E25 -> 0 | D18: =C18 -> 0 | G18: =D18-(E18+F18) -> 0 | J18: 持有待售资产 | K18: ='1报表'!C25 -> 0 | L18: ='1报表'!D25 -> 0 | M18: =E18 -> 0 | N18: =M18 -> 0
B19: 一年内到期的非流动资产 | C19: ='1报表'!E26 -> 0 | D19: =C19 -> 0 | G19: =D19-(E19+F19) -> 0 | J19: 非经营性一年内到期的非流动资产 | M19: =E19 -> 0 | N19: =M19 -> 0
B20: 其他流动资产 | C20: ='1报表'!E27 -> 0.575 | D20: =C20 -> 0.575 | E20: 0.575 | G20: =D20-(E20+F20) -> 0 | H20: 应收的预计无法收回的设计费 | J20: 非经营性其他流动资产 | K20: 0.575 | L20: 0.575 | M20: =E20 -> 0.575 | N20: 0 | O20: 应收的预计无法收回的设计费
B21: 流动资产合计 | C21: =SUM(C8:C20) -> 1699.7694 | D21: =SUM(D8:D20) -> 1699.7694 | E21: =SUM(E8:E20) -> 903.83743 | F21: =SUM(F8:F20) -> 0 | G21: =SUM(G8:G20) -> 795.93197 | J21: 非经营性流动资产小计 | K21: =SUM(K9:K20) -> 807.44615 | L21: =SUM(L9:L20) -> 65.694674 | M21: =SUM(M9:M20) -> 903.83743 | N21: =SUM(N9:N20) -> 903.26243
B22: 非流动资产：
B23: 可供出售金融资产 | C23: ='1报表'!E30 -> 1.332422 | D23: =C23 -> 1.332422 | E23: 1.332422 | G23: =D23-(E23+F23) -> 0 | H23: 电力基金，非经营性资产 | J23: 可供出售金融资产 | K23: ='1报表'!C30 -> 1.332422 | L23: ='1报表'!D30 -> 1.332422 | M23: =E23 -> 1.332422 | N23: =M23 -> 1.332422 | O23: 电力基金
B24: 持有至到期投资 | C24: ='1报表'!E31 -> 0 | D24: =C24 -> 0 | G24: =D24-(E24+F24) -> 0 | J24: 持有至到期投资 | K24: ='1报表'!C31 -> 0 | L24: ='1报表'!D31 -> 0 | M24: =E24 -> 0
B25: 债权投资 | C25: ='1报表'!E32 -> 0 | D25: =C25 -> 0 | G25: =D25-(E25+F25) -> 0 | J25: 债权投资 | K25: ='1报表'!C32 -> 0 | L25: ='1报表'!D32 -> 0 | M25: =E25 -> 0
B26: 其他债权投资 | C26: ='1报表'!E33 -> 0 | D26: =C26 -> 0 | G26: =D26-(E26+F26) -> 0 | J26: 其他债权投资 | K26: ='1报表'!C33 -> 0 | L26: ='1报表'!D33 -> 0 | M26: =E26 -> 0
B27: 长期应收款 | C27: ='1报表'!E34 -> 0 | D27: =C27 -> 0 | G27: =D27-(E27+F27) -> 0 | J27: 非经营性长期应收款 | M27: =E27 -> 0
B28: 长期股权投资 | C28: ='1报表'!E35 -> 3.465172 | D28: =C28 -> 3.465172 | E28: 3.465172 | G28: =D28-(E28+F28) -> 0 | H28: xx开发有限公司,作为非经营性资产单独评估 | J28: 长期股权投资 | K28: ='1报表'!C35 -> 3.465172 | L28: ='1报表'!D35 -> 3.465172 | M28: =E28 -> 3.465172 | N28: 0 | O28: xx园林开发有限公司，已破产，无资产可收回
B29: 其他权益工具投资 | C29: ='1报表'!E36 -> 0 | D29: =C29 -> 0 | G29: =D29-(E29+F29) -> 0 | J29: 其他权益工具投资 | K29: ='1报表'!C36 -> 0 | L29: ='1报表'!D36 -> 0 | M29: =E29 -> 0
B30: 其他非流动金融资产 | C30: ='1报表'!E37 -> 0 | D30: =C30 -> 0 | G30: =D30-(E30+F30) -> 0 | J30: 其他非流动金融资产 | K30: ='1报表'!C37 -> 0 | L30: ='1报表'!D37 -> 0 | M30: =E30 -> 0
B31: 投资性房地产 | C31: ='1报表'!E38 -> 0 | D31: =C31 -> 0 | G31: =D31-(E31+F31) -> 0 | J31: 投资性房地产 | K31: ='1报表'!C38 -> 0 | L31: ='1报表'!D38 -> 0 | M31: =E31 -> 0
B32: 固定资产 | C32: ='1报表'!E39 -> 94.661335 | D32: =C32 -> 94.661335 | G32: =D32-(E32+F32) -> 94.661335 | J32: 非经营性固定资产 | M32: =E32 -> 0
B33: 在建工程 | C33: ='1报表'!E40 -> 0 | D33: =C33 -> 0 | G33: =D33-(E33+F33) -> 0 | J33: 非经营性在建工程 | M33: =E33 -> 0
B34: 生产性生物资产 | C34: ='1报表'!E41 -> 0 | D34: =C34 -> 0 | G34: =D34-(E34+F34) -> 0 | J34: 非经营性生产性生物资产 | M34: =E34 -> 0
B35: 油气资产 | C35: ='1报表'!E42 -> 0 | D35: =C35 -> 0 | G35: =D35-(E35+F35) -> 0 | J35: 非经营性油气资产 | M35: =E35 -> 0
B36: 无形资产 | C36: ='1报表'!E43 -> 5.916019 | D36: =C36 -> 5.916019 | G36: =D36-(E36+F36) -> 5.916019 | J36: 非经营性无形资产 | M36: =E36 -> 0
B37: 开发支出 | C37: ='1报表'!E44 -> 0 | D37: =C37 -> 0 | G37: =D37-(E37+F37) -> 0 | J37: 非经营性开发支出 | M37: =E37 -> 0
B38: 商誉 | C38: ='1报表'!E45 -> 0 | D38: =C38 -> 0 | G38: =D38-(E38+F38) -> 0 | J38: 商誉
B39: 长期待摊费用 | C39: ='1报表'!E46 -> 0 | D39: =C39 -> 0 | G39: =D39-(E39+F39) -> 0 | J39: 非经营性长期待摊费用 | M39: =E39 -> 0
B40: 递延所得税资产 | C40: ='1报表'!E47 -> 0 | D40: =C40 -> 0 | G40: =D40-(E40+F40) -> 0 | J40: 递延所得税资产 | M40: =E40 -> 0
B41: 其他非流动资产 | C41: ='1报表'!E48 -> 0 | D41: =C41 -> 0 | G41: =D41-(E41+F41) -> 0 | J41: 非经营性其他非流动资产 | M41: =E41 -> 0
...

Sheet 3收入
B1: 营业收入预测表
B2: ='1报表'!B11 -> 评估基准日：2018/6/30
B3: ='1报表'!B12 -> 被评估单位：YLSJ公司 | K3: 单位：万元
B4: 年度 | C4: ='1报表'!C96 -> 2016年 | D4: ='1报表'!D96 -> 2017年 | E4: ='1报表'!E96 -> 2018年1-6 | F4: =YEAR('1报表'!E5)&"年" -> 2018年 | G4: =LEFT(F4,4)+1&"年" -> 2019年 | H4: =LEFT(G4,4)+1&"年" -> 2020年 | I4: =LEFT(H4,4)+1&"年" -> 2021年 | J4: =LEFT(I4,4)+1&"年" -> 2022年 | K4: =LEFT(J4,4)+1&"年" -> 2023年
B5: 数据汇总 | C5: ='1报表'!C97 -> 6309.9996 | D5: ='1报表'!D97 -> 6454.082 | E5: ='1报表'!E97 -> 2068.9888 | F5: 4500 | G5: =F5*1.1 -> 4950 | H5: =G5*1.08 -> 5346 | I5: =H5*1.05 -> 5613.3 | J5: =I5*1.03 -> 5781.699 | K5: =J5 -> 5781.699
B6: 增长率 | D6: =IF(C5,D5/C5-1,"na") -> 0.022833987 | E6: na | F6: =IF(D5,F5/D5-1,"na") -> -0.30276684 | G6: =IF(F5,G5/F5-1,"na") -> 0.1 | H6: =IF(G5,H5/G5-1,"na") -> 0.08 | I6: =IF(H5,I5/H5-1,"na") -> 0.05 | J6: =IF(I5,J5/I5-1,"na") -> 0.03 | K6: =IF(J5,K5/J5-1,"na") -> 0
B9: 具体预测见“收益法预测操作手册”

Sheet 4成本
B1: 营业成本预测表
B2: ='1报表'!B11 -> 评估基准日：2018/6/30
B3: ='1报表'!B12 -> 被评估单位：YLSJ公司 | K3: 单位：万元
B4: 年度 | C4: ='3收入'!C4 -> 2016年 | D4: ='3收入'!D4 -> 2017年 | E4: ='3收入'!E4 -> 2018年1-6 | F4: ='3收入'!F4 -> 2018年 | G4: ='3收入'!G4 -> 2019年 | H4: ='3收入'!H4 -> 2020年 | I4: ='3收入'!I4 -> 2021年 | J4: ='3收入'!J4 -> 2022年 | K4: ='3收入'!K4 -> 2023年
B5: 数据汇总 | C5: ='1报表'!C98 -> 5325.209 | D5: ='1报表'!D98 -> 5874.6686 | E5: ='1报表'!E98 -> 2248.3124 | F5: =F84 -> 3958.79 | G5: =G84 -> 4362.54 | H5: =H84 -> 4708.1747 | I5: =I84 -> 4917.871 | J5: =J84 -> 5074.1781 | K5: =K84 -> 5081.3281
B6: 营业收入 | C6: ='3收入'!C5 -> 6309.9996 | D6: ='3收入'!D5 -> 6454.082 | E6: ='3收入'!E5 -> 2068.9888 | F6: ='3收入'!F5 -> 4500 | G6: ='3收入'!G5 -> 4950 | H6: ='3收入'!H5 -> 5346 | I6: ='3收入'!I5 -> 5613.3 | J6: ='3收入'!J5 -> 5781.699 | K6: ='3收入'!K5 -> 5781.699
B7: 毛利率 | C7: =IF(C6,(C6-C5)/C6,"na") -> 0.15606824 | D7: =IF(D6,(D6-D5)/D6,"na") -> 0.089774725 | E7: =IF(E6,(E6-E5)/E6,"na") -> -0.08667207 | F7: =IF(F6,(F6-F5)/F6,"na") -> 0.12026889 | G7: =IF(G6,(G6-G5)/G6,"na") -> 0.11867879 | H7: =IF(H6,(H6-H5)/H6,"na") -> 0.11930888 | I7: =IF(I6,(I6-I5)/I6,"na") -> 0.12388951 | J7: =IF(J6,(J6-J5)/J6,"na") -> 0.12237248 | K7: =IF(K6,(K6-K5)/K6,"na") -> 0.12113582
B8: 营业成本预测（生产型企业）（方式一）
B9: 项目1 | C9: =C4 -> 2016年 | D9: =D4 -> 2017年 | E9: =E4 -> 2018年1-6 | F9: =F4 -> 2018年 | G9: =G4 -> 2019年 | H9: =H4 -> 2020年 | I9: =I4 -> 2021年 | J9: =J4 -> 2022年 | K9: =K4 -> 2023年 | M9: 按科目进行分析
B10: 原材料 | M10: 评估实务中还应当对原材料的变化趋势作一说明，公司消化原材料价格变化的经营措施。
B11: 占收入比 | C11: =IF(C6,C10/C6,"na") -> 0 | D11: =IF(D6,D10/D6,"na") -> 0 | E11: =IF(E6,E10/E6,"na") -> 0 | M11: 员工人数是否会随着收入增长而增加，消化人工成本的措施。
B12: =B10 -> 原材料 | C12: =C10 -> 0 | D12: =D10 -> 0 | E12: =E10 -> 0 | F12: =IF(F10,F10,F11*F6) -> 0 | G12: =IF(G10,G10,G11*G6) -> 0 | H12: =IF(H10,H10,H11*H6) -> 0 | I12: =IF(I10,I10,I11*I6) -> 0 | J12: =IF(J10,J10,J11*J6) -> 0 | K12: =IF(K10,K10,K11*K6) -> 0 | M12: （要有具体的纸质底稿支撑）
B13: 占收入比 | F13: =IF(F6,F12/F6,"na") -> 0 | G13: =IF(G6,G12/G6,"na") -> 0 | H13: =IF(H6,H12/H6,"na") -> 0 | I13: =IF(I6,I12/I6,"na") -> 0 | J13: =IF(J6,J12/J6,"na") -> 0 | K13: =IF(K6,K12/K6,"na") -> 0
B15: 项目2 | C15: =C4 -> 2016年 | D15: =D4 -> 2017年 | E15: =E4 -> 2018年1-6 | F15: =F4 -> 2018年 | G15: =G4 -> 2019年 | H15: =H4 -> 2020年 | I15: =I4 -> 2021年 | J15: =J4 -> 2022年 | K15: =K4 -> 2023年
B16: 燃料及动力
B17: 占收入比 | C17: =IF(C6,C16/C6,"na") -> 0 | D17: =IF(D6,D16/D6,"na") -> 0 | E17: =IF(E6,E16/E6,"na") -> 0
B18: =B16 -> 燃料及动力 | C18: =C16 -> 0 | D18: =D16 -> 0 | E18: =E16 -> 0 | F18: =IF(F16,F16,F17*F6) -> 0 | G18: =IF(G16,G16,G17*G6) -> 0 | H18: =IF(H16,H16,H17*H6) -> 0 | I18: =IF(I16,I16,I17*I6) -> 0 | J18: =IF(J16,J16,J17*J6) -> 0 | K18: =IF(K16,K16,K17*K6) -> 0
B19: 占收入比 | F19: =IF(F6,F18/F6,"na") -> 0 | G19: =IF(G6,G18/G6,"na") -> 0 | H19: =IF(H6,H18/H6,"na") -> 0 | I19: =IF(I6,I18/I6,"na") -> 0 | J19: =IF(J6,J18/J6,"na") -> 0 | K19: =IF(K6,K18/K6,"na") -> 0
B21: 项目3 | C21: =C4 -> 2016年 | D21: =D4 -> 2017年 | E21: =E4 -> 2018年1-6 | F21: =F4 -> 2018年 | G21: =G4 -> 2019年 | H21: =H4 -> 2020年 | I21: =I4 -> 2021年 | J21: =J4 -> 2022年 | K21: =K4 -> 2023年
B22: 生产人员工资及附加
B23: 占收入比 | C23: =IF(C6,C22/C6,"na") -> 0 | D23: =IF(D6,D22/D6,"na") -> 0 | E23: =IF(E6,E22/E6,"na") -> 0 | G23: =F23 -> 0 | H23: =G23 -> 0 | I23: =H23 -> 0 | J23: =I23 -> 0 | K23: =J23 -> 0
B24: =B22 -> 生产人员工资及附加 | C24: =C22 -> 0 | D24: =D22 -> 0 | E24: =E22 -> 0 | F24: =IF(F22,F22,F23*F6) -> 0 | G24: =IF(G22,G22,G23*G6) -> 0 | H24: =IF(H22,H22,H23*H6) -> 0 | I24: =IF(I22,I22,I23*I6) -> 0 | J24: =IF(J22,J22,J23*J6) -> 0 | K24: =IF(K22,K22,K23*K6) -> 0
B25: 占收入比 | F25: =IF(F6,F24/F6,"na") -> 0 | G25: =IF(G6,G24/G6,"na") -> 0 | H25: =IF(H6,H24/H6,"na") -> 0 | I25: =IF(I6,I24/I6,"na") -> 0 | J25: =IF(J6,J24/J6,"na") -> 0 | K25: =IF(K6,K24/K6,"na") -> 0
B27: 项目4 | C27: =C4 -> 2016年 | D27: =D4 -> 2017年 | E27: =E4 -> 2018年1-6 | F27: =F4 -> 2018年 | G27: =G4 -> 2019年 | H27: =H4 -> 2020年 | I27: =I4 -> 2021年 | J27: =J4 -> 2022年 | K27: =K4 -> 2023年
B28: 折旧（及摊销） | F28: ='7折旧'!F5 -> 43.79 | G28: ='7折旧'!G5 -> 56.04 | H28: ='7折旧'!H5 -> 57.154732 | I28: ='7折旧'!I5 -> 34.3 | J28: ='7折旧'!J5 -> 44.1 | K28: ='7折旧'!K5 -> 51.25
B29: 占收入比 | C29: =IF(C6,C28/C6,"na") -> 0 | D29: =IF(D6,D28/D6,"na") -> 0 | E29: =IF(E6,E28/E6,"na") -> 0 | F29: =IF(F6,F28/F6,"na") -> 0.0097311111 | G29: =IF(G6,G28/G6,"na") -> 0.011321212 | H29: =IF(H6,H28/H6,"na") -> 0.010691121 | I29: =IF(I6,I28/I6,"na") -> 0.0061104876 | J29: =IF(J6,J28/J6,"na") -> 0.0076275157 | K29: =IF(K6,K28/K6,"na") -> 0.0088641764
B31: 项目5 | C31: =C4 -> 2016年 | D31: =D4 -> 2017年 | E31: =E4 -> 2018年1-6 | F31: =F4 -> 2018年 | G31: =G4 -> 2019年 | H31: =H4 -> 2020年 | I31: =I4 -> 2021年 | J31: =J4 -> 2022年 | K31: =K4 -> 2023年
B32: 其他
B33: 占收入比 | C33: =IF(C6,C32/C6,"na") -> 0 | D33: =IF(D6,D32/D6,"na") -> 0 | E33: =IF(E6,E32/E6,"na") -> 0
B34: =B32 -> 其他 | C34: =C32 -> 0 | D34: =D32 -> 0 | E34: =E32 -> 0 | F34: =IF(F32,F32,F33*F6) -> 0 | G34: =IF(G32,G32,G33*G6) -> 0 | H34: =IF(H32,H32,H33*H6) -> 0 | I34: =IF(I32,I32,I33*I6) -> 0 | J34: =IF(J32,J32,J33*J6) -> 0 | K34: =IF(K32,K32,K33*K6) -> 0
B35: 占收入比 | F35: =IF(F6,F34/F6,"na") -> 0 | G35: =IF(G6,G34/G6,"na") -> 0 | H35: =IF(H6,H34/H6,"na") -> 0 | I35: =IF(I6,I34/I6,"na") -> 0 | J35: =IF(J6,J34/J6,"na") -> 0 | K35: =IF(K6,K34/K6,"na") -> 0
B37: 项目（汇总） | C37: =C4 -> 2016年 | D37: =D4 -> 2017年 | E37: =E4 -> 2018年1-6 | F37: =F4 -> 2018年 | G37: =G4 -> 2019年 | H37: =H4 -> 2020年 | I37: =I4 -> 2021年 | J37: =J4 -> 2022年 | K37: =K4 -> 2023年
B38: 营业成本 | C38: =C12+C18+C24+C28+C34 -> 0 | D38: =D12+D18+D24+D28+D34 -> 0 | E38: =E12+E18+E24+E28+E34 -> 0 | F38: =F12+F18+F24+F28+F34 -> 43.79 | G38: =G12+G18+G24+G28+G34 -> 56.04 | H38: =H12+H18+H24+H28+H34 -> 57.154732 | I38: =I12+I18+I24+I28+I34 -> 34.3 | J38: =J12+J18+J24+J28+J34 -> 44.1 | K38: =K12+K18+K24+K28+K34 -> 51.25
B39: 占收入比 | C39: =IF(C6,C38/C6,"na") -> 0 | D39: =IF(D6,D38/D6,"na") -> 0 | E39: =IF(E6,E38/E6,"na") -> 0 | F39: =IF(F6,F38/F6,"na") -> 0.0097311111 | G39: =IF(G6,G38/G6,"na") -> 0.011321212 | H39: =IF(H6,H38/H6,"na") -> 0.010691121 | I39: =IF(I6,I38/I6,"na") -> 0.0061104876 | J39: =IF(J6,J38/J6,"na") -> 0.0076275157 | K39: =IF(K6,K38/K6,"na") -> 0.0088641764
B40: 毛利率 | C40: =IF(C6,1-C39,"na") -> 1 | D40: =IF(D6,1-D39,"na") -> 1 | E40: =IF(E6,1-E39,"na") -> 1 | F40: =IF(F6,1-F39,"na") -> 0.99026889 | G40: =IF(G6,1-G39,"na") -> 0.98867879 | H40: =IF(H6,1-H39,"na") -> 0.98930888 | I40: =IF(I6,1-I39,"na") -> 0.99388951 | J40: =IF(J6,1-J39,"na") -> 0.99237248 | K40: =IF(K6,1-K39,"na") -> 0.99113582
B42: 按产品/项目毛利率分析（方式二） | E42: 需具体分析毛利率变动原因，以及提高或降低措施，而不是仅仅列张汇总表（要有具体的纸质底稿支撑）
B43: 毛利率 | C43: =C4 -> 2016年 | D43: =D4 -> 2017年 | E43: =E4 -> 2018年1-6 | F43: =F4 -> 2018年 | G43: =G4 -> 2019年 | H43: =H4 -> 2020年 | I43: =I4 -> 2021年 | J43: =J4 -> 2022年 | K43: =K4 -> 2023年
B44: 产品a
B45: 产品b
B46: 产品c
...

Sheet 5税金
B1: 税金及附加预测表
B2: ='1报表'!B11 -> 评估基准日：2018/6/30
B3: ='1报表'!B12 -> 被评估单位：YLSJ公司 | K3: 单位：万元
B4: 年度 | C4: ='3收入'!C4 -> 2016年 | D4: ='3收入'!D4 -> 2017年 | E4: ='3收入'!E4 -> 2018年1-6 | F4: ='3收入'!F4 -> 2018年 | G4: ='3收入'!G4 -> 2019年 | H4: ='3收入'!H4 -> 2020年 | I4: ='3收入'!I4 -> 2021年 | J4: ='3收入'!J4 -> 2022年 | K4: ='3收入'!K4 -> 2023年
B5: 数据汇总 | C5: ='1报表'!C99 -> 32.988746 | D5: ='1报表'!D99 -> 28.542702 | E5: ='1报表'!E99 -> 19.638479 | F5: =F13 -> 22.5 | G5: =G13 -> 24.75 | H5: =H13 -> 26.73 | I5: =I13 -> 28.0665 | J5: =J13 -> 28.908495 | K5: =K13 -> 28.908495
B6: 营业收入 | C6: ='3收入'!C5 -> 6309.9996 | D6: ='3收入'!D5 -> 6454.082 | E6: ='3收入'!E5 -> 2068.9888 | F6: ='3收入'!F5 -> 4500 | G6: ='3收入'!G5 -> 4950 | H6: ='3收入'!H5 -> 5346 | I6: ='3收入'!I5 -> 5613.3 | J6: ='3收入'!J5 -> 5781.699 | K6: ='3收入'!K5 -> 5781.699
B7: 占收入比 | C7: =IF(C6,C5/C6,"na") -> 0.0052280108 | D7: =IF(D6,D5/D6,"na") -> 0.0044224263 | E7: =IF(E6,E5/E6,"na") -> 0.0094918246 | F7: =IF(F6,F5/F6,"na") -> 0.005 | G7: =IF(G6,G5/G6,"na") -> 0.005 | H7: =IF(H6,H5/H6,"na") -> 0.005 | I7: =IF(I6,I5/I6,"na") -> 0.005 | J7: =IF(J6,J5/J6,"na") -> 0.005 | K7: =IF(K6,K5/K6,"na") -> 0.005
B8: 按收入占比分析（方式一） | D8: 实务中如果历史数据比较平稳，可采用下例简化处理。
C9: =C4 -> 2016年 | D9: =D4 -> 2017年 | E9: =E4 -> 2018年1-6 | F9: =F4 -> 2018年 | G9: =G4 -> 2019年 | H9: =H4 -> 2020年 | I9: =I4 -> 2021年 | J9: =J4 -> 2022年 | K9: =K4 -> 2023年
B10: 营业收入 | C10: =C6 -> 6309.9996 | D10: =D6 -> 6454.082 | E10: =E6 -> 2068.9888 | F10: =F6 -> 4500 | G10: =G6 -> 4950 | H10: =H6 -> 5346 | I10: =I6 -> 5613.3 | J10: =J6 -> 5781.699 | K10: =K6 -> 5781.699
B11: 税金及附加 | C11: =C5 -> 32.988746 | D11: =D5 -> 28.542702
B12: 占收入比 | C12: =IF(C10,C11/C10,"na") -> 0.0052280108 | D12: =IF(D10,D11/D10,"na") -> 0.0044224263 | E12: =IF(E10,E11/E10,"na") -> 0 | F12: 0.005 | G12: =F12 -> 0.005 | H12: =G12 -> 0.005 | I12: =H12 -> 0.005 | J12: =I12 -> 0.005 | K12: =J12 -> 0.005
B13: 税金及附加 | F13: =IF(F11,F11,F12*F10) -> 22.5 | G13: =IF(G11,G11,G12*G10) -> 24.75 | H13: =IF(H11,H11,H12*H10) -> 26.73 | I13: =IF(I11,I11,I12*I10) -> 28.0665 | J13: =IF(J11,J11,J12*J10) -> 28.908495 | K13: =IF(K11,K11,K12*K10) -> 28.908495
B14: 占收入比 | F14: =IF(F10,F13/F10,"na") -> 0.005 | G14: =IF(G10,G13/G10,"na") -> 0.005 | H14: =IF(H10,H13/H10,"na") -> 0.005 | I14: =IF(I10,I13/I10,"na") -> 0.005 | J14: =IF(J10,J13/J10,"na") -> 0.005 | K14: =IF(K10,K13/K10,"na") -> 0.005
B16: 分项目进行分析（方式二） | D16: 实务中如果企业产品不单一，每种产品或服务适用的税率不同，以及金额较大，应分项目评估。示例如下
B17: 项目 | C17: =C4 -> 2016年 | D17: =D4 -> 2017年 | E17: =E4 -> 2018年1-6 | F17: =F4 -> 2018年 | G17: =G4 -> 2019年 | H17: =H4 -> 2020年 | I17: =I4 -> 2021年 | J17: =J4 -> 2022年 | K17: =K4 -> 2023年 | L17: 税率 | M17: 计税公式 | N17: 计税依据的主要内容
B18: 增值税销项 | L18: 0.16
B19: 增值税进项 | L19: 0.16 | N19: 注意资本性支出中设备的增值税要加上
B20: 应缴增值税 | C20: =C18-C19 -> 0 | D20: =D18-D19 -> 0 | E20: =E18-E19 -> 0 | F20: =F18-F19 -> 0 | G20: =G18-G19 -> 0 | H20: =H18-H19 -> 0 | I20: =I18-I19 -> 0 | J20: =J18-J19 -> 0 | K20: =K18-K19 -> 0 | M20: (1)-(2)
B21: 应缴营业税 | N21: 营改增后，该项无。
B22: 应缴流转税合计 | C22: =C20+C21 -> 0 | D22: =D20+D21 -> 0 | E22: =E20+E21 -> 0 | F22: =IF(F20+F21<0,0,F20+F21) -> 0 | G22: =IF(G20+G21<0,0,G20+G21) -> 0 | H22: =IF(H20+H21<0,0,H20+H21) -> 0 | I22: =IF(I20+I21<0,0,I20+I21) -> 0 | J22: =IF(J20+J21<0,0,J20+J21) -> 0 | K22: =IF(K20+K21<0,0,K20+K21) -> 0 | M22: (3)+(4)
B23: 消费税
B24: 城市维护建设税 | F24: =F48*$L$24 -> 0 | G24: =G48*$L$24 -> 0 | H24: =H48*$L$24 -> 0 | I24: =I48*$L$24 -> 0 | J24: =J48*$L$24 -> 0 | K24: =K48*$L$24 -> 0 | L24: 0.07 | M24: 应交流转税项
B25: 资源税
B26: 教育费附加 | F26: =F48*$L$26 -> 0 | G26: =G48*$L$26 -> 0 | H26: =H48*$L$26 -> 0 | I26: =I48*$L$26 -> 0 | J26: =J48*$L$26 -> 0 | K26: =K48*$L$26 -> 0 | L26: 0.05 | M26: 应交流转税项
B27: 房产税
B28: 土地使用税
B29: 车船使用税
B30: 印花税 | L30: 0.0003 | N30: 特殊行业要具实考虑
B31: 其他
B32: 合计 | C32: =C21+SUM(C23:C31) -> 0 | D32: =D21+SUM(D23:D31) -> 0 | E32: =E21+SUM(E23:E31) -> 0 | F32: =F21+SUM(F23:F31) -> 0 | G32: =G21+SUM(G23:G31) -> 0 | H32: =H21+SUM(H23:H31) -> 0 | I32: =I21+SUM(I23:I31) -> 0 | J32: =J21+SUM(J23:J31) -> 0 | K32: =K21+SUM(K23:K31) -> 0
B33: 占收入比 | F33: =IF(F6,F32/F6,"na") -> 0 | G33: =IF(G6,G32/G6,"na") -> 0 | H33: =IF(H6,H32/H6,"na") -> 0 | I33: =IF(I6,I32/I6,"na") -> 0 | J33: =IF(J6,J32/J6,"na") -> 0 | K33: =IF(K6,K32/K6,"na") -> 0
B35: 实务中如果企业产品不单一，每种产品或服务适用的增值税率不同，以及金额较大，应分项目评估。示例如下
B36: 增值税计算 | F36: =F4 -> 2018年 | G36: =G4 -> 2019年 | H36: =H4 -> 2020年 | I36: =I4 -> 2021年 | J36: =J4 -> 2022年 | K36: =K4 -> 2023年
B37: 增值税销项税
B39: 原辅材料进项税
B40: 运输费
B41: 水电费
B42: 其他科目转入进项税
B43: 购买设备进项税
...

Sheet 6销管
B1: 销售费用、管理费用、研发费用预测表
B2: ='1报表'!B11 -> 评估基准日：2018/6/30
B3: ='1报表'!B12 -> 被评估单位：YLSJ公司 | K3: 单位：万元
B4: 数据汇总 | C4: ='3收入'!C4 -> 2016年 | D4: ='3收入'!D4 -> 2017年 | E4: ='3收入'!E4 -> 2018年1-6 | F4: ='3收入'!F4 -> 2018年 | G4: ='3收入'!G4 -> 2019年 | H4: ='3收入'!H4 -> 2020年 | I4: ='3收入'!I4 -> 2021年 | J4: ='3收入'!J4 -> 2022年 | K4: ='3收入'!K4 -> 2023年
B5: 销售费用 | C5: ='1报表'!C100 -> 0 | D5: ='1报表'!D100 -> 0 | E5: ='1报表'!E100 -> 0 | F5: =F41 -> 0 | G5: =G41 -> 0 | H5: =H41 -> 0 | I5: =I41 -> 0 | J5: =J41 -> 0 | K5: =K41 -> 0
B6: 管理费用 | C6: ='1报表'!C101 -> 668.47256 | D6: ='1报表'!D101 -> 615.9856 | E6: ='1报表'!E101 -> 268.92924 | F6: =F75 -> 475.43751 | G6: =G75 -> 512.95 | H6: =H75 -> 554.946 | I6: =I75 -> 583.4433 | J6: =J75 -> 599.9516 | K6: =K75 -> 599.9516
B7: 研发费用 | C7: ='1报表'!C102 -> 0 | D7: ='1报表'!D102 -> 0 | E7: ='1报表'!E102 -> 0 | F7: =F82 -> 0 | G7: =G82 -> 0 | H7: =H82 -> 0 | I7: =I82 -> 0 | J7: =J82 -> 0 | K7: =K82 -> 0
B8: 销售、管理、研发费用 | C8: =SUM(C5:C7) -> 668.47256 | D8: =SUM(D5:D7) -> 615.9856 | E8: =SUM(E5:E7) -> 268.92924 | F8: =SUM(F5:F7) -> 475.43751 | G8: =SUM(G5:G7) -> 512.95 | H8: =SUM(H5:H7) -> 554.946 | I8: =SUM(I5:I7) -> 583.4433 | J8: =SUM(J5:J7) -> 599.9516 | K8: =SUM(K5:K7) -> 599.9516
B9: 营业收入 | C9: ='3收入'!C5 -> 6309.9996 | D9: ='3收入'!D5 -> 6454.082 | E9: ='3收入'!E5 -> 2068.9888 | F9: ='3收入'!F5 -> 4500 | G9: ='3收入'!G5 -> 4950 | H9: ='3收入'!H5 -> 5346 | I9: ='3收入'!I5 -> 5613.3 | J9: ='3收入'!J5 -> 5781.699 | K9: ='3收入'!K5 -> 5781.699
B10: SGA/Sale | C10: =IF(C9,C8/C9,"na") -> 0.10593861 | D10: =IF(D9,D8/D9,"na") -> 0.095441241 | E10: =IF(E9,E8/E9,"na") -> 0.129981 | F10: =IF(F9,F8/F9,"na") -> 0.10565278 | G10: =IF(G9,G8/G9,"na") -> 0.10362626 | H10: =IF(H9,H8/H9,"na") -> 0.10380584 | I10: =IF(I9,I8/I9,"na") -> 0.10393945 | J10: =IF(J9,J8/J9,"na") -> 0.10376735 | K10: =IF(K9,K8/K9,"na") -> 0.10376735
B11: 销售费用分析（点行"+" 号展开） | E11: 科目内容只是示例，根据具体项目改动！ | I11: 金额大、变动大的科目要具体分析
B12: 销售费用 | C12: =C4 -> 2016年 | D12: =D4 -> 2017年 | E12: =E4 -> 2018年1-6 | F12: =F4 -> 2018年 | G12: =G4 -> 2019年 | H12: =H4 -> 2020年 | I12: =I4 -> 2021年 | J12: =J4 -> 2022年 | K12: =K4 -> 2023年
B13: 差旅费
B14: 招待费
B15: 运输费
B16: 广告/宣传费
B17: 商检/报关费
B18: 检定费/检测费
B19: 工资
B20: 社保费
B21: 其他
B23: 合计 | C23: =SUM(C13:C22) -> 0 | D23: =SUM(D13:D22) -> 0 | E23: =SUM(E13:E22) -> 0 | F23: =SUM(F13:F22) -> 0 | G23: =SUM(G13:G22) -> 0 | H23: =SUM(H13:H22) -> 0 | I23: =SUM(I13:I22) -> 0 | J23: =SUM(J13:J22) -> 0 | K23: =SUM(K13:K22) -> 0
B24: 检查核对 | C24: =C23-C5 -> 0 | D24: =D23-D5 -> 0 | E24: =E23-E5 -> 0
B25: 与报表一致? | C25: =IF(ROUND(C24,0)=0,"OK","需要检查") -> OK | D25: =IF(ROUND(D24,0)=0,"OK","需要检查") -> OK | E25: =IF(ROUND(E24,0)=0,"OK","需要检查") -> OK
B26: 占收入比例 | E26: =C12&"-"&E12 -> 2016年-2018年1-6 | F26: 相关系数 | G26: 平均值 | H26: 评估取值
B27: =B13 -> 差旅费 | C27: =IF(C13,C13/C$9,"") | D27: =IF(D13,D13/D$9,"") | E27: =IF(E13,E13/E$9,"") | F27: =IF(COUNT(C27:E27)>2,CORREL(C$9:E$9,C13:E13),"") | G27: =AVERAGE(C27:E27) -> #DIV/0!
B28: =B14 -> 招待费 | C28: =IF(C14,C14/C$9,"") | D28: =IF(D14,D14/D$9,"") | E28: =IF(E14,E14/E$9,"") | F28: =IF(COUNT(C28:E28)>2,CORREL(C$9:E$9,C14:E14),"") | G28: =AVERAGE(C28:E28) -> #DIV/0!
B29: =B15 -> 运输费 | C29: =IF(C15,C15/C$9,"") | D29: =IF(D15,D15/D$9,"") | E29: =IF(E15,E15/E$9,"") | F29: =IF(COUNT(C29:E29)>2,CORREL(C$9:E$9,C15:E15),"") | G29: =AVERAGE(C29:E29) -> #DIV/0!
B30: =B16 -> 广告/宣传费 | C30: =IF(C16,C16/C$9,"") | D30: =IF(D16,D16/D$9,"") | E30: =IF(E16,E16/E$9,"") | F30: =IF(COUNT(C30:E30)>2,CORREL(C$9:E$9,C16:E16),"") | G30: =AVERAGE(C30:E30) -> #DIV/0!
B31: =B17 -> 商检/报关费 | C31: =IF(C17,C17/C$9,"") | D31: =IF(D17,D17/D$9,"") | E31: =IF(E17,E17/E$9,"") | F31: =IF(COUNT(C31:E31)>2,CORREL(C$9:E$9,C17:E17),"") | G31: =AVERAGE(C31:E31) -> #DIV/0!
B32: =B18 -> 检定费/检测费 | C32: =IF(C18,C18/C$9,"") | D32: =IF(D18,D18/D$9,"") | E32: =IF(E18,E18/E$9,"") | F32: =IF(COUNT(C32:E32)>2,CORREL(C$9:E$9,C18:E18),"") | G32: =AVERAGE(C32:E32) -> #DIV/0!
B33: =B19 -> 工资 | C33: =IF(C19,C19/C$9,"") | D33: =IF(D19,D19/D$9,"") | E33: =IF(E19,E19/E$9,"") | F33: =IF(COUNT(C33:E33)>2,CORREL(C$9:E$9,C19:E19),"") | G33: =AVERAGE(C33:E33) -> #DIV/0!
B34: =B20 -> 社保费 | C34: =IF(C20,C20/C$9,"") | D34: =IF(D20,D20/D$9,"") | E34: =IF(E20,E20/E$9,"") | F34: =IF(COUNT(C34:E34)>2,CORREL(C$9:E$9,C20:E20),"") | G34: =AVERAGE(C34:E34) -> #DIV/0!
B35: =B21 -> 其他 | C35: =IF(C21,C21/C$9,"") | D35: =IF(D21,D21/D$9,"") | E35: =IF(E21,E21/E$9,"") | F35: =IF(COUNT(C35:E35)>2,CORREL(C$9:E$9,C21:E21),"") | G35: =AVERAGE(C35:E35) -> #DIV/0!
B37: 销售费用分析
B38: 项目 | C38: =C4 -> 2016年 | D38: =D4 -> 2017年 | E38: =E4 -> 2018年1-6 | F38: =F4 -> 2018年 | G38: =G4 -> 2019年 | H38: =H4 -> 2020年 | I38: =I4 -> 2021年 | J38: =J4 -> 2022年 | K38: =K4 -> 2023年
B39: 销售费用 | C39: =C23 -> 0 | D39: =D23 -> 0 | E39: =E23 -> 0 | F39: =F23 -> 0 | G39: =G23 -> 0 | H39: =H23 -> 0 | I39: =I23 -> 0 | J39: =J23 -> 0 | K39: =K23 -> 0
B40: 占收入比 | C40: =IF(C9,C39/C9,"na") -> 0 | D40: =IF(D9,D39/D9,"na") -> 0 | E40: =IF(E9,E39/E9,"na") -> 0
B41: 销售费用 | F41: =IF(F39,F39,F40*F9) -> 0 | G41: =IF(G39,G39,G40*G9) -> 0 | H41: =IF(H39,H39,H40*H9) -> 0 | I41: =IF(I39,I39,I40*I9) -> 0 | J41: =IF(J39,J39,J40*J9) -> 0 | K41: =IF(K39,K39,K40*K9) -> 0
B42: 占收入比 | F42: =IF(F9,F41/F9,"na") -> 0 | G42: =IF(G9,G41/G9,"na") -> 0 | H42: =IF(H9,H41/H9,"na") -> 0 | I42: =IF(I9,I41/I9,"na") -> 0 | J42: =IF(J9,J41/J9,"na") -> 0 | K42: =IF(K9,K41/K9,"na") -> 0
...

Sheet 7折旧
B1: 固定资产支出与折旧预测表
B2: ='1报表'!B11 -> 评估基准日：2018/6/30 | L2: 该工作表已保护！
B3: ='1报表'!B12 -> 被评估单位：YLSJ公司 | E3: =12-MONTH('1报表'!E5) -> 6 | F3: =F4&"剩余折摊月数" -> 2018年剩余折摊月数 | K3: 单位：万元
B4: 项目 | C4: =D4&"占比" -> 2018年1-6占比 | D4: ='3收入'!E4 -> 2018年1-6 | E4: =F4&(RIGHT(D4,1)+1)&"-12" -> 2018年7-12 | F4: ='3收入'!F4 -> 2018年 | G4: ='3收入'!G4 -> 2019年 | H4: ='3收入'!H4 -> 2020年 | I4: ='3收入'!I4 -> 2021年 | J4: ='3收入'!J4 -> 2022年 | K4: ='3收入'!K4 -> 2023年 | L4: 评估取值
B5: 生产成本中的折旧 | C5: =IF(D5,D5/D$9,"") -> 1 | D5: 20.67 | F5: =F$9*$L5 -> 43.79 | G5: =G$9*$L5 -> 56.04 | H5: =H$9*$L5 -> 57.154732 | I5: =I$9*$L5 -> 34.3 | J5: =J$9*$L5 -> 44.1 | K5: =K$9*$L5 -> 51.25 | L5: 1
B6: 销售费用中的折旧 | C6: =IF(D6,D6/D$9,"") | F6: =F$9*$L6 -> 0 | G6: =G$9*$L6 -> 0 | H6: =H$9*$L6 -> 0 | I6: =I$9*$L6 -> 0 | J6: =J$9*$L6 -> 0 | K6: =K$9*$L6 -> 0
B7: 管理费用中的折旧 | C7: =IF(D7,D7/D$9,"") | F7: =F$9*$L7 -> 0 | G7: =G$9*$L7 -> 0 | H7: =H$9*$L7 -> 0 | I7: =I$9*$L7 -> 0 | J7: =J$9*$L7 -> 0 | K7: =K$9*$L7 -> 0
B8: 研发费用中的折旧 | C8: =IF(D8,D8/D$9,"") | F8: =F$9*$L8 -> 0 | G8: =G$9*$L8 -> 0 | H8: =H$9*$L8 -> 0 | I8: =I$9*$L8 -> 0 | J8: =J$9*$L8 -> 0 | K8: =K$9*$L8 -> 0
B9: 固定资产折旧额 | C9: =SUM(C5:C8) -> 1 | D9: =SUM(D5:D8) -> 20.67 | E9: =E28+E43 -> 23.12 | F9: =D9+E9 -> 43.79 | G9: =G28+G43 -> 56.04 | H9: =H28+H43 -> 57.154732 | I9: =I28+I43 -> 34.3 | J9: =J28+J43 -> 44.1 | K9: =K28+K43 -> 51.25 | L9: =SUM(L5:L8) -> 1
B10: 固定资产支出 | E10: =E26+SUM(E37:E39) -> 49 | G10: =G26+SUM(G37:G39) -> 49 | H10: =H26+SUM(H37:H39) -> 49 | I10: =I26+SUM(I37:I39) -> 49 | J10: =J26+SUM(J37:J39) -> 49 | K10: =K26+SUM(K37:K39) -> 47
B11: 未转固资产的处理
B12: 科目 | D12: =D4 -> 2018年1-6 | E12: =E4 -> 2018年7-12 | F12: =F4 -> 2018年 | G12: =G4 -> 2019年 | H12: =H4 -> 2020年 | I12: =I4 -> 2021年 | J12: =J4 -> 2022年 | K12: =K4 -> 2023年 | L12: 折旧年限
B13: 未转固建筑物的账面值
B14: 年度转固金额
B15: 未转固设备的账面值
B16: 年度转固金额-机器
B17: 年度转固金额-车辆
B18: 年度转固金额-电子设备
B20: 房屋建筑物
B21: 数据汇总 | C21: 折旧率 | D21: =D4 -> 2018年1-6 | E21: =E4 -> 2018年7-12 | F21: =F4 -> 2018年 | G21: =G4 -> 2019年 | H21: =H4 -> 2020年 | I21: =I4 -> 2021年 | J21: =J4 -> 2022年 | K21: =K4 -> 2023年 | L21: 折旧年限
B22: 基准日已提足折旧建筑类账面原值
B23: 基准日未提足折旧建筑类账面原值
B24: 基准日建筑类账面净值
B25: 存量建筑类折旧额 | E25: =IF(D24>D23*C25/12*E3,D23*C25/12*E3,D24) -> 0 | G25: =IF((D24-E25)>D23*C25,D23*C25,D24-E25) -> 0 | H25: =IF(($D24-$E25-SUM($G25:G25))>$G25,$G25,$D24-$E25-SUM($G25:G25)) -> 0 | I25: =IF(($D24-$E25-SUM($G25:H25))>$G25,$G25,$D24-$E25-SUM($G25:H25)) -> 0 | J25: =IF(($D24-$E25-SUM($G25:I25))>$G25,$G25,$D24-$E25-SUM($G25:I25)) -> 0 | K25: =IF(($D24-$E25-SUM($G25:J25))>$G25,$G25,$D24-$E25-SUM($G25:J25)) -> 0
B26: 新增建筑物投入原值
B27: 新增建筑类折旧额 | E27: =IF($L13,E14/$L13/12*E3,0)+IF($L27,E26/$L27/12*E3,0) -> 0 | G27: =IF($L13,($E14+SUM($G14:G14))/$L13,0)+IF($L27,($E26+SUM($G26:G26))/$L27,0) -> 0 | H27: =IF($L13,($E14+SUM($G14:H14))/$L13,0)+IF($L27,($E26+SUM($G26:H26))/$L27,0) -> 0 | I27: =IF($L13,($E14+SUM($G14:I14))/$L13,0)+IF($L27,($E26+SUM($G26:I26))/$L27,0) -> 0 | J27: =IF($L13,($E14+SUM($G14:J14))/$L13,0)+IF($L27,($E26+SUM($G26:J26))/$L27,0) -> 0 | K27: =IF($L13,($E14+SUM($G14:K14))/$L13,0)+IF($L27,($E26+SUM($G26:K26))/$L27,0) -> 0
B28: 建筑类折旧额小计 | E28: =E25+E27 -> 0 | G28: =G25+G27 -> 0 | H28: =H25+H27 -> 0 | I28: =I25+I27 -> 0 | J28: =J25+J27 -> 0 | K28: =K25+K27 -> 0
B29: 期末建筑物类账面净值 | E29: =D24+E14+E26-E28 -> 0 | F29: =E29 -> 0 | G29: =F29+G14+G26-G28 -> 0 | H29: =G29+H14+H26-H28 -> 0 | I29: =H29+I14+I26-I28 -> 0 | J29: =I29+J14+J26-J28 -> 0 | K29: =J29+K14+K26-K28 -> 0
B31: 设备
B32: 项目 | C32: 折旧率 | D32: =D4 -> 2018年1-6 | E32: =E4 -> 2018年7-12 | F32: =F4 -> 2018年 | G32: =G4 -> 2019年 | H32: =H4 -> 2020年 | I32: =I4 -> 2021年 | J32: =J4 -> 2022年 | K32: =K4 -> 2023年 | L32: 折旧年限
B33: 基准日已提足折旧设备类账面原值 | D33: 0
B34: 基准日未提足折旧设备类账面原值 | D34: 451.86
B35: 基准日账面净值 | D35: 94.664732
B36: 存量设备类折旧额 | C36: 0.091488514 | E36: =IF(D35>D34*C36/12*E3,D34*C36/12*E3,D35) -> 20.67 | G36: =IF((D35-E36)>D34*C36,D34*C36,D35-E36) -> 41.34 | H36: =IF(($D35-$E36-SUM($G36:G36))>$G36,$G36,$D35-$E36-SUM($G36:G36)) -> 32.654732 | I36: =IF(($D35-$E36-SUM($G36:H36))>$G36,$G36,$D35-$E36-SUM($G36:H36)) -> 0 | J36: =IF(($D35-$E36-SUM($G36:I36))>$G36,$G36,$D35-$E36-SUM($G36:I36)) -> 0 | K36: =IF(($D35-$E36-SUM($G36:J36))>$G36,$G36,$D35-$E36-SUM($G36:J36)) -> 0
B37: 新增机器投入原值
B38: 新增车辆投入原值 | E38: 14 | G38: 14 | H38: 14 | I38: 14 | J38: 14 | K38: 12 | L38: 5
B39: 新增电子设备投入原值 | E39: 35 | G39: 35 | H39: 35 | I39: 35 | J39: 35 | K39: 35 | L39: 5
B40: 新增机器折旧额 | E40: =E55 -> 0 | G40: =G55 -> 0 | H40: =H55 -> 0 | I40: =I55 -> 0 | J40: =J55 -> 0 | K40: =K55 -> 0
B41: 新增车辆折旧额 | E41: =E64 -> 0.7 | G41: =G64 -> 4.2 | H41: =H64 -> 7 | I41: =I64 -> 9.8 | J41: =J64 -> 12.6 | K41: =K64 -> 14.5
B42: 新增电子设备折旧额 | E42: =E73 -> 1.75 | G42: =G73 -> 10.5 | H42: =H73 -> 17.5 | I42: =I73 -> 24.5 | J42: =J73 -> 31.5 | K42: =K73 -> 36.75
...

Sheet 8摊销
B1: 长摊和无形资产支出与摊销预测表
B2: ='1报表'!B11 -> 评估基准日：2018/6/30 | M2: 该工作表已保护！
B3: ='1报表'!B12 -> 被评估单位：YLSJ公司 | E3: ='7折旧'!E3 -> 6 | F3: ='7折旧'!F3 -> 2018年剩余折摊月数 | K3: 单位：万元
B4: 数据汇总 | D4: ='3收入'!E4 -> 2018年1-6 | E4: =F4&(RIGHT(D4,1)+1)&"-12" -> 2018年7-12 | F4: ='3收入'!F4 -> 2018年 | G4: ='3收入'!G4 -> 2019年 | H4: ='3收入'!H4 -> 2020年 | I4: ='3收入'!I4 -> 2021年 | J4: ='3收入'!J4 -> 2022年 | K4: ='3收入'!K4 -> 2023年
B5: 长期待摊费用摊销 | D5: =D52 -> 0 | E5: =E52 -> 0 | F5: =D5+E5 -> 0 | G5: =G52 -> 0 | H5: =H52 -> 0 | I5: =I52 -> 0 | J5: =J52 -> 0 | K5: =K52 -> 0
B6: 无形资产摊销 | D6: =D25+D34 -> 4.521487 | E6: =E25+E34 -> 6.416019 | F6: =D6+E6 -> 10.937506 | G6: =G25+G34 -> 3 | H6: =H25+H34 -> 5 | I6: =I25+I34 -> 6.5 | J6: =J25+J34 -> 6 | K6: =K25+K34 -> 6
B7: 摊销合计 | E7: =SUM(E5:E6) -> 6.416019 | F7: =SUM(F5:F6) -> 10.937506 | G7: =SUM(G5:G6) -> 3 | H7: =SUM(H5:H6) -> 5 | I7: =SUM(I5:I6) -> 6.5 | J7: =SUM(J5:J6) -> 6 | K7: =SUM(K5:K6) -> 6
B8: 长摊资产支出 | E8: =E50 -> 0 | G8: =G50 -> 0 | H8: =H50 -> 0 | I8: =I50 -> 0 | J8: =J50 -> 0 | K8: =K50 -> 0
B9: 无形资产支出 | E9: =E23+E32 -> 6 | G9: =G23+G32 -> 6 | H9: =H23+H32 -> 6 | I9: =I23+I32 -> 6 | J9: =J23+J32 -> 6 | K9: =K23+K32 -> 6
B10: 长摊和无形资产支出 | E10: =SUM(E8:E9) -> 6 | G10: =SUM(G8:G9) -> 6 | H10: =SUM(H8:H9) -> 6 | I10: =SUM(I8:I9) -> 6 | J10: =SUM(J8:J9) -> 6 | K10: =SUM(K8:K9) -> 6
B11: 未资本化无形资产的处理
B12: 科目 | C12: 摊销年限 | D12: =D4 -> 2018年1-6 | E12: =E4 -> 2018年7-12 | F12: =F4 -> 2018年 | G12: =G4 -> 2019年 | H12: =H4 -> 2020年 | I12: =I4 -> 2021年 | J12: =J4 -> 2022年 | K12: =K4 -> 2023年
B13: 未资本化的土地
B14: 年度资本化金额
B15: 未资本化的无形资产 | D15: ='2报表调整'!G37 -> 0
B16: 年度资本化金额
B18: 土地使用权
B19: 项目 | C19: 摊销年限 | D19: =D4 -> 2018年1-6 | E19: =E4 -> 2018年7-12 | F19: =F4 -> 2018年 | G19: =G4 -> 2019年 | H19: =H4 -> 2020年 | I19: =I4 -> 2021年 | J19: =J4 -> 2022年 | K19: =K4 -> 2023年
B20: 基准日土地账面原值
B21: 基准日土地账面净值
B22: 存量土地摊销额 | E22: =IF(C22,IF(D21>D20/C22/12*E3,D20/C22/12*E3,D21),0) -> 0 | G22: =IF(C22,IF((D21-E22)>D20/C22,D20/C22,D21-E22),0) -> 0 | H22: =IF(($D21-$E22-SUM($G22:G22))>$G22,$G22,$D21-$E22-SUM($G22:G22)) -> 0 | I22: =IF(($D21-$E22-SUM($G22:H22))>$G22,$G22,$D21-$E22-SUM($G22:H22)) -> 0 | J22: =IF(($D21-$E22-SUM($G22:I22))>$G22,$G22,$D21-$E22-SUM($G22:I22)) -> 0 | K22: =IF(($D21-$E22-SUM($G22:J22))>$G22,$G22,$D21-$E22-SUM($G22:J22)) -> 0
B23: 新增土地投入原值
B24: 新增土地摊销额 | E24: =IF($C13,E14/$C13/12*E3,0)+IF($C24,E23/$C24/12*E3,0) -> 0 | G24: =IF($C13,($E14+SUM($G14:G14))/$C13,0)+IF($C24,($E23+SUM($G23:G23))/$C24,0) -> 0 | H24: =IF($C13,($E14+SUM($G14:H14))/$C13,0)+IF($C24,($E23+SUM($G23:H23))/$C24,0) -> 0 | I24: =IF($C13,($E14+SUM($G14:I14))/$C13,0)+IF($C24,($E23+SUM($G23:I23))/$C24,0) -> 0 | J24: =IF($C13,($E14+SUM($G14:J14))/$C13,0)+IF($C24,($E23+SUM($G23:J23))/$C24,0) -> 0 | K24: =IF($C13,($E14+SUM($G14:K14))/$C13,0)+IF($C24,($E23+SUM($G23:K23))/$C24,0) -> 0
B25: 土地摊销额小计 | D25: =D22+D24 -> 0 | E25: =E22+E24 -> 0 | F25: =D25+E25 -> 0 | G25: =G22+G24 -> 0 | H25: =H22+H24 -> 0 | I25: =I22+I24 -> 0 | J25: =J22+J24 -> 0 | K25: =K22+K24 -> 0
B26: 土地使用权账面净值 | E26: =D21+E14+E23-E25 -> 0 | F26: =E26 -> 0 | G26: =F26+G14+G23-G25 -> 0 | H26: =G26+H14+H23-H25 -> 0 | I26: =H26+I14+I23-I25 -> 0 | J26: =I26+J14+J23-J25 -> 0 | K26: =J26+K14+K23-K25 -> 0
B27: 其他无形资产
B28: 项目 | C28: 摊销年限 | D28: =D19 -> 2018年1-6 | E28: =E19 -> 2018年7-12 | F28: =F19 -> 2018年 | G28: =G19 -> 2019年 | H28: =H19 -> 2020年 | I28: =I19 -> 2021年 | J28: =J19 -> 2022年 | K28: =K19 -> 2023年
B29: 基准日其他无形资产账面原值 | D29: 125.66642
B30: 基准日其他无形资产账面净值 | D30: 5.916019
B31: 存量其他无形资产摊销额 | C31: 3 | D31: 4.521487 | E31: =IF(C31,IF(D30>D29/C31/12*E3,D29/C31/12*E3,D30),0) -> 5.916019 | G31: =IF(C31,IF((D30-E31)>D29/C31,D29/C31,D30-E31),0) -> 0 | H31: =IF(($D30-$E31-SUM($G31:G31))>$G31,$G31,$D30-$E31-SUM($G31:G31)) -> 0 | I31: =IF(($D30-$E31-SUM($G31:H31))>$G31,$G31,$D30-$E31-SUM($G31:H31)) -> 0 | J31: =IF(($D30-$E31-SUM($G31:I31))>$G31,$G31,$D30-$E31-SUM($G31:I31)) -> 0 | K31: =IF(($D30-$E31-SUM($G31:J31))>$G31,$G31,$D30-$E31-SUM($G31:J31)) -> 0
B32: 新增技术类无形资产投入原值 | C32: 3 | E32: 6 | G32: 6 | H32: 6 | I32: 6 | J32: 6 | K32: 6
B33: 新增无形资产摊销额 | E33: =E44 -> 0.5 | G33: =G44 -> 3 | H33: =H44 -> 5 | I33: =I44 -> 6.5 | J33: =J44 -> 6 | K33: =K44 -> 6
B34: 无形资产摊销额小计 | D34: =D31+D33 -> 4.521487 | E34: =E31+E33 -> 6.416019 | G34: =G31+G33 -> 3 | H34: =H31+H33 -> 5 | I34: =I31+I33 -> 6.5 | J34: =J31+J33 -> 6 | K34: =K31+K33 -> 6
B35: 其他无形资产账面净值 | E35: =D30+E16+E32-E33 -> 11.416019 | F35: =E35 -> 11.416019 | G35: =F35+G16+G32-G33 -> 14.416019 | H35: =G35+H16+H32-H33 -> 15.416019 | I35: =H35+I16+I32-I33 -> 14.916019 | J35: =I35+J16+J32-J33 -> 14.916019 | K35: =J35+K16+K32-K33 -> 14.916019
B37: 年度 | E37: =E28 -> 2018年7-12 | F37: =F28 -> 2018年 | G37: =G28 -> 2019年 | H37: =H28 -> 2020年 | I37: =I28 -> 2021年 | J37: =J28 -> 2022年 | K37: =K28 -> 2023年
B38: =E37 -> 2018年7-12 | E38: =IF(C32,(E16+E32)/C32/12*E3/2,0) -> 0.5 | G38: =IF(C32,IF((E16+E32-E38)>(E16+E32)/C32,(E16+E32)/C32,E16+E32-E38),0) -> 2 | H38: =IF(($E16+$E32-$E38-SUM($G38:G38))>$G38,$G38,$E16+$E32-$E38-SUM($G38:G38)) -> 2 | I38: =IF(($E16+$E32-$E38-SUM($G38:H38))>$G38,$G38,$E16+$E32-$E38-SUM($G38:H38)) -> 1.5 | J38: =IF(($E16+$E32-$E38-SUM($G38:I38))>$G38,$G38,$E16+$E32-$E38-SUM($G38:I38)) -> 0 | K38: =IF(($E16+$E32-$E38-SUM($G38:J38))>$G38,$G38,$E16+$E32-$E38-SUM($G38:J38)) -> 0
B39: =G37 -> 2019年 | C39: 技术无形资产摊销额自动计算过程 | G39: =IF(C32,(G16+G32)/C32/2,0) -> 1 | H39: =IF(C32,(G16+G32)/C32,0) -> 2 | I39: =IF(($G16+$G32-SUM($G39:H39))>$H39,$H39,$G16+$G32-SUM($G39:H39)) -> 2 | J39: =IF(($G16+$G32-SUM($G39:I39))>$H39,$H39,$G16+$G32-SUM($G39:I39)) -> 1 | K39: =IF(($G16+$G32-SUM($G39:J39))>$H39,$H39,$G16+$G32-SUM($G39:J39)) -> 0
B40: =H37 -> 2020年 | H40: =IF(C32,(H16+H32)/C32/2,0) -> 1 | I40: =IF(C32,(H16+H32)/C32,0) -> 2 | J40: =IF(($H16+$H32-SUM($H40:I40))>$I40,$I40,$H16+$H32-SUM($H40:I40)) -> 2 | K40: =IF(($H16+$H32-SUM($H40:J40))>$I40,$I40,$H16+$H32-SUM($H40:J40)) -> 1
B41: =I37 -> 2021年 | I41: =IF(C32,(I16+I32)/C32/2,0) -> 1 | J41: =IF(C32,(I16+I32)/C32,0) -> 2 | K41: =IF(($I16+$I32-SUM($I41:J41))>$J41,$J41,$I16+$I32-SUM($I41:J41)) -> 2
B42: =J37 -> 2022年 | J42: =IF(C32,(J16+J32)/C32/2,0) -> 1 | K42: =IF(C32,(J16+J32)/C32,0) -> 2
...

Sheet 9溢余现金
B1: 经营最低保有现金分析表
B2: ='1报表'!B11 -> 评估基准日：2018/6/30
B3: ='1报表'!B12 -> 被评估单位：YLSJ公司 | K3: 单位：万元
B4: 项目 | C4: ='3收入'!C4 -> 2016年 | D4: ='3收入'!D4 -> 2017年 | E4: ='3收入'!E4 -> 2018年1-6 | F4: ='3收入'!F4 -> 2018年 | G4: ='3收入'!G4 -> 2019年 | H4: ='3收入'!H4 -> 2020年 | I4: ='3收入'!I4 -> 2021年 | J4: ='3收入'!J4 -> 2022年 | K4: ='3收入'!K4 -> 2023年
B5: 生产成本的人工费用 | C5: ='4成本'!C70+'4成本'!C76 -> 2782.3618 | D5: ='4成本'!D70+'4成本'!D76 -> 3300.8299 | E5: ='4成本'!E70+'4成本'!E76 -> 1646.5653 | F5: ='4成本'!F70+'4成本'!F76 -> 2160 | G5: ='4成本'!G70+'4成本'!G76 -> 2376 | H5: ='4成本'!H70+'4成本'!H76 -> 2566.08 | I5: ='4成本'!I70+'4成本'!I76 -> 2694.384 | J5: ='4成本'!J70+'4成本'!J76 -> 2775.2155 | K5: ='4成本'!K70+'4成本'!K76 -> 2775.2155 | L5: 还要加上办公差旅费用
B6: 营业税金及附加 | C6: ='5税金'!C5 -> 32.988746 | D6: ='5税金'!D5 -> 28.542702 | E6: ='5税金'!E5 -> 19.638479 | F6: ='5税金'!F5 -> 22.5 | G6: ='5税金'!G5 -> 24.75 | H6: ='5税金'!H5 -> 26.73 | I6: ='5税金'!I5 -> 28.0665 | J6: ='5税金'!J5 -> 28.908495 | K6: ='5税金'!K5 -> 28.908495
B7: 销售费用 | C7: ='6销管'!C5 -> 0 | D7: ='6销管'!D5 -> 0 | E7: ='6销管'!E5 -> 0 | F7: ='6销管'!F5 -> 0 | G7: ='6销管'!G5 -> 0 | H7: ='6销管'!H5 -> 0 | I7: ='6销管'!I5 -> 0 | J7: ='6销管'!J5 -> 0 | K7: ='6销管'!K5 -> 0
B8: 管理费用 | C8: ='6销管'!C6 -> 668.47256 | D8: ='6销管'!D6 -> 615.9856 | E8: ='6销管'!E6 -> 268.92924 | F8: ='6销管'!F6 -> 475.43751 | G8: ='6销管'!G6 -> 512.95 | H8: ='6销管'!H6 -> 554.946 | I8: ='6销管'!I6 -> 583.4433 | J8: ='6销管'!J6 -> 599.9516 | K8: ='6销管'!K6 -> 599.9516
B9: 研发费用 | C9: ='6销管'!C7 -> 0 | D9: ='6销管'!D7 -> 0 | E9: ='6销管'!E7 -> 0 | F9: ='6销管'!F7 -> 0 | G9: ='6销管'!G7 -> 0 | H9: ='6销管'!H7 -> 0 | I9: ='6销管'!I7 -> 0 | J9: ='6销管'!J7 -> 0 | K9: ='6销管'!K7 -> 0
B10: 财务费用中的利息支出 | C10: ='11财务费用'!C18 -> 0.473709 | D10: ='11财务费用'!D18 -> 0.956799 | E10: ='11财务费用'!E18 -> 0.0238 | F10: ='11财务费用'!F18 -> 0 | G10: ='11财务费用'!G18 -> 0 | H10: ='11财务费用'!H18 -> 0 | I10: ='11财务费用'!I18 -> 0 | J10: ='11财务费用'!J18 -> 0 | K10: ='11财务费用'!K18 -> 0
B11: 减：销售费用中折旧与摊销
B12: 减：管理费用中折旧与摊销 | C12: ='6销管'!C48 -> 2.895436 | D12: ='6销管'!D48 -> 8.042885 | E12: ='6销管'!E48 -> 4.521487 | F12: ='6销管'!F48 -> 10.937506 | G12: ='6销管'!G48 -> 3 | H12: ='6销管'!H48 -> 5 | I12: ='6销管'!I48 -> 6.5 | J12: ='6销管'!J48 -> 6 | K12: ='6销管'!K48 -> 6
B13: 减：研发费用中折旧与摊销
B14: 估计的付现成本合计 | C14: =SUM(C5:C10)-SUM(C11:C13) -> 3481.4014 | D14: =SUM(D5:D10)-SUM(D11:D13) -> 3938.2721 | E14: =SUM(E5:E10)-SUM(E11:E13) -> 1930.6353 | F14: =SUM(F5:F10)-SUM(F11:F13) -> 2647 | G14: =SUM(G5:G10)-SUM(G11:G13) -> 2910.7 | H14: =SUM(H5:H10)-SUM(H11:H13) -> 3142.756 | I14: =SUM(I5:I10)-SUM(I11:I13) -> 3299.3938 | J14: =SUM(J5:J10)-SUM(J11:J13) -> 3398.0756 | K14: =SUM(K5:K10)-SUM(K11:K13) -> 3398.0756
B15: 月数 | C15: 12 | D15: 12 | E15: =MONTH('1报表'!E5) -> 6 | F15: 12 | G15: 12 | H15: 12 | I15: 12 | J15: 12 | K15: 12
B16: 月均付现成本 | C16: =C14/C15 -> 290.11678 | D16: =D14/D15 -> 328.18934 | E16: =E14/E15 -> 321.77255 | F16: =F14/F15 -> 220.58333 | G16: =G14/G15 -> 242.55833 | H16: =H14/H15 -> 261.89633 | I16: =I14/I15 -> 274.94948 | J16: =J14/J15 -> 283.17297 | K16: =K14/K15 -> 283.17297
B17: 保有现金系数(月） | C17: =D17 -> 1 | D17: =E17 -> 1 | E17: 1 | F17: =E17 -> 1 | G17: =F17 -> 1 | H17: =G17 -> 1 | I17: =H17 -> 1 | J17: =I17 -> 1 | K17: =J17 -> 1 | L17: 一般取1，取其他数据应结合行业特点说明
B18: 限制用途现金 | C18: 31.161043 | D18: 31.278408 | E18: 31.315556 | F18: =E18 -> 31.315556 | G18: =F18 -> 31.315556 | H18: =G18 -> 31.315556 | I18: =H18 -> 31.315556 | J18: =I18 -> 31.315556 | K18: =J18 -> 31.315556 | L18: 职工房款和职工住房维修基金
B19: 经营最低保有现金测算 | C19: =MIN(C16*C17,C23)+C18 -> 321.27782 | D19: =MIN(D16*D17,D23)+D18 -> 359.46775 | E19: =MIN(E16*E17,E23)+E18 -> 156.56072 | F19: =F16*F17+F18 -> 251.89889 | G19: =G16*G17+G18 -> 273.87389 | H19: =H16*H17+H18 -> 293.21189 | I19: =I16*I17+I18 -> 306.26504 | J19: =J16*J17+J18 -> 314.48852 | K19: =K16*K17+K18 -> 314.48852
B20: 经营必备现金/收入（检查） | C20: =C19/'3收入'!C5 -> 0.050915665 | D20: =D19/'3收入'!D5 -> 0.055696186 | E20: =E19/'3收入'!E5 -> 0.07567016 | F20: =F19/'3收入'!F5 -> 0.055977531 | G20: =G19/'3收入'!G5 -> 0.055328058 | H20: =H19/'3收入'!H5 -> 0.054846968 | I20: =I19/'3收入'!I5 -> 0.054560604 | J20: =J19/'3收入'!J5 -> 0.05439379 | K20: =K19/'3收入'!K5 -> 0.05439379
B21: 评估基准日溢余现金分析表
B22: 项目 | E22: =E4 -> 2018年1-6
B23: 资产负债表中的货币资金 | E23: ='2报表调整'!D8 -> 125.24516
B24: 其中：经营最低保有现金 | E24: =E19 -> 156.56072
B25: 溢余现金 | E25: =MAX(E23-E24,0) -> 0

Sheet 10营运
B1: 营运资金预测表
B2: ='1报表'!B11 -> 评估基准日：2018/6/30
B3: ='1报表'!B12 -> 被评估单位：YLSJ公司 | E3: =MONTH('1报表'!E5) -> 6 | F3: 基准年已经营月数 | K3: 单位：万元
B4: 项目 | C4: ='3收入'!C4 -> 2016年 | D4: ='3收入'!D4 -> 2017年 | E4: ='3收入'!E4 -> 2018年1-6 | F4: ='3收入'!F4 -> 2018年 | G4: ='3收入'!G4 -> 2019年 | H4: ='3收入'!H4 -> 2020年 | I4: ='3收入'!I4 -> 2021年 | J4: ='3收入'!J4 -> 2022年 | K4: ='3收入'!K4 -> 2023年 | L4: 全部为经营性资产负债；不含非经营！
B5: 经营最低保有现金 | C5: ='9溢余现金'!C19 -> 321.27782 | D5: ='9溢余现金'!D19 -> 359.46775 | E5: ='9溢余现金'!E19 -> 156.56072 | F5: ='9溢余现金'!F19 -> 251.89889 | G5: ='9溢余现金'!G19 -> 273.87389 | H5: ='9溢余现金'!H19 -> 293.21189 | I5: ='9溢余现金'!I19 -> 306.26504 | J5: ='9溢余现金'!J19 -> 314.48852 | K5: ='9溢余现金'!K19 -> 314.48852 | L5: 当企业不稳定时，不能用周转天数预测！采用绝对额进行预测！
B6: 应收票据及应收账款计算行 | C6: ='1报表'!C18-'2报表调整'!K11 -> 915.13378 | D6: ='1报表'!D18-'2报表调整'!L11 -> 747.61612 | E6: ='2报表调整'!G11 -> 479.66661
B7: 周转天数 | C7: =IF(C41,360*C6/C41,0) -> 52.210489 | D7: =IF(D41,360*D6/D41,0) -> 41.70102 | E7: =IF(E41,360*E6*E3/E41/12,0) -> 41.730525 | F7: 42 | G7: =F7 -> 42 | H7: =G7 -> 42 | I7: =H7 -> 42 | J7: =I7 -> 42 | K7: =J7 -> 42
B8: 应收票据及应收账款 | C8: =C6 -> 915.13378 | D8: =D6 -> 747.61612 | E8: =E6 -> 479.66661 | F8: =IF(F6,F6,F41*F7/360) -> 525 | G8: =IF(G6,G6,G41*G7/360) -> 577.5 | H8: =IF(H6,H6,H41*H7/360) -> 623.7 | I8: =IF(I6,I6,I41*I7/360) -> 654.885 | J8: =IF(J6,J6,J41*J7/360) -> 674.53155 | K8: =IF(K6,K6,K41*K7/360) -> 674.53155
B9: 预付款项计算行 | C9: ='1报表'!C19-'2报表调整'!K12 -> 0 | D9: ='1报表'!D19-'2报表调整'!L12 -> 0 | E9: ='2报表调整'!G12 -> 0
B10: 周转天数 | C10: =IF(C42,360*C9/C42,0) -> 0 | D10: =IF(D42,360*D9/D42,0) -> 0 | E10: =IF(E42,360*E9*E3/E42/12,0) -> 0 | G10: =F10 -> 0 | H10: =G10 -> 0 | I10: =H10 -> 0 | J10: =I10 -> 0 | K10: =J10 -> 0
B11: 预付款项 | C11: =C9 -> 0 | D11: =D9 -> 0 | E11: =E9 -> 0 | F11: =IF(F9,F9,F42*F10/360) -> 0 | G11: =IF(G9,G9,G42*G10/360) -> 0 | H11: =IF(H9,H9,H42*H10/360) -> 0 | I11: =IF(I9,I9,I42*I10/360) -> 0 | J11: =IF(J9,J9,J42*J10/360) -> 0 | K11: =IF(K9,K9,K42*K10/360) -> 0
B12: 其他应收款计算行 | C12: ='1报表'!C22-'2报表调整'!K15 -> 124.12402 | D12: ='1报表'!D22-'2报表调整'!L15 -> 195.0491 | E12: ='2报表调整'!G15 -> 191.0202
B13: 周转天数 | C13: =IF(C41,360*C12/C41,0) -> 7.0815613 | D13: =IF(D41,360*D12/D41,0) -> 10.879576 | E13: =IF(E41,360*E12*E3/E41/12,0) -> 16.61857 | F13: 15 | G13: =F13 -> 15 | H13: =G13 -> 15 | I13: =H13 -> 15 | J13: =I13 -> 15 | K13: =J13 -> 15
B14: 其他应收款 | C14: =C12 -> 124.12402 | D14: =D12 -> 195.0491 | E14: =E12 -> 191.0202 | F14: =IF(F12,F12,F41*F13/360) -> 187.5 | G14: =IF(G12,G12,G41*G13/360) -> 206.25 | H14: =IF(H12,H12,H41*H13/360) -> 222.75 | I14: =IF(I12,I12,I41*I13/360) -> 233.8875 | J14: =IF(J12,J12,J41*J13/360) -> 240.90413 | K14: =IF(K12,K12,K41*K13/360) -> 240.90413
B15: 存货计算行 | C15: ='1报表'!C23-'2报表调整'!K16 -> 0 | D15: ='1报表'!D23-'2报表调整'!L16 -> 0 | E15: ='2报表调整'!G16 -> 0
B16: 周转天数 | C16: =IF(C42,360*C15/C42,0) -> 0 | D16: =IF(D42,360*D15/D42,0) -> 0 | E16: =IF(E42,360*E15*E3/E42/12,0) -> 0 | G16: =F16 -> 0 | H16: =G16 -> 0 | I16: =H16 -> 0 | J16: =I16 -> 0 | K16: =J16 -> 0
B17: 存货 | C17: =C15 -> 0 | D17: =D15 -> 0 | E17: =E15 -> 0 | F17: =IF(F15,F15,F42*F16/360) -> 0 | G17: =IF(G15,G15,G42*G16/360) -> 0 | H17: =IF(H15,H15,H42*H16/360) -> 0 | I17: =IF(I15,I15,I42*I16/360) -> 0 | J17: =IF(J15,J15,J42*J16/360) -> 0 | K17: =IF(K15,K15,K42*K16/360) -> 0
B18: 合同资产 | C18: ='1报表'!C24-'2报表调整'!K17 -> 0 | D18: ='1报表'!D24-'2报表调整'!L17 -> 0 | E18: ='2报表调整'!G17 -> 0
B19: 一年内到期的非流动资产 | C19: ='1报表'!C26-'2报表调整'!K19 -> 0 | D19: ='1报表'!D26-'2报表调整'!L19 -> 0 | E19: ='2报表调整'!G19 -> 0
B20: 其他流动资产 | C20: ='1报表'!C27-'2报表调整'!K20 -> 0 | D20: ='1报表'!D27-'2报表调整'!L20 -> 0 | E20: ='2报表调整'!G20 -> 0
B21: 流动资产合计 | C21: =C5+C8+C11+C14+C17+C18+C19+C20 -> 1360.5356 | D21: =D5+D8+D11+D14+D17+D18+D19+D20 -> 1302.133 | E21: =E5+E8+E11+E14+E17+E18+E19+E20 -> 827.24752 | F21: =F5+F8+F11+F14+F17+F18+F19+F20 -> 964.39889 | G21: =G5+G8+G11+G14+G17+G18+G19+G20 -> 1057.6239 | H21: =H5+H8+H11+H14+H17+H18+H19+H20 -> 1139.6619 | I21: =I5+I8+I11+I14+I17+I18+I19+I20 -> 1195.0375 | J21: =J5+J8+J11+J14+J17+J18+J19+J20 -> 1229.9242 | K21: =K5+K8+K11+K14+K17+K18+K19+K20 -> 1229.9242
B23: 应付票据及应付款项计算行 | C23: ='1报表'!C55-'2报表调整'!K48 -> 0 | D23: ='1报表'!D55-'2报表调整'!L48 -> 0 | E23: ='2报表调整'!G48 -> 297.39516
B24: 周转天数 | C24: =IF(C42,360*C23/C42,0) -> 0 | D24: =IF(D42,360*D23/D42,0) -> 0 | E24: =IF(E42,360*E23*E3/E42/12,0) -> 23.809471 | F24: 20 | G24: =F24 -> 20 | H24: =G24 -> 20 | I24: =H24 -> 20 | J24: =I24 -> 20 | K24: =J24 -> 20
B25: 应付票据及应付账款 | C25: =C23 -> 0 | D25: =D23 -> 0 | E25: =E23 -> 297.39516 | F25: =IF(F23,F23,F42*F24/360) -> 219.93278 | G25: =IF(G23,G23,G42*G24/360) -> 242.36333 | H25: =IF(H23,H23,H42*H24/360) -> 261.56526 | I25: =IF(I23,I23,I42*I24/360) -> 273.21506 | J25: =IF(J23,J23,J42*J24/360) -> 281.89879 | K25: =IF(K23,K23,K42*K24/360) -> 282.29601
B26: 预收款项计算行 | C26: ='1报表'!C56-'2报表调整'!K49 -> 124.37 | D26: ='1报表'!D56-'2报表调整'!L49 -> 78 | E26: ='2报表调整'!G49 -> 99.1537
B27: 周转天数 | C27: =IF(C41,360*C26/C41,0) -> 7.0955948 | D27: =IF(D41,360*D26/D41,0) -> 4.3507349 | E27: =IF(E41,360*E26*E3/E41/12,0) -> 8.6262747 | F27: 6 | G27: =F27 -> 6 | H27: =G27 -> 6 | I27: =H27 -> 6 | J27: =I27 -> 6 | K27: =J27 -> 6
B28: 预收款项 | C28: =C26 -> 124.37 | D28: =D26 -> 78 | E28: =E26 -> 99.1537 | F28: =IF(F26,F26,F41*F27/360) -> 75 | G28: =IF(G26,G26,G41*G27/360) -> 82.5 | H28: =IF(H26,H26,H41*H27/360) -> 89.1 | I28: =IF(I26,I26,I41*I27/360) -> 93.555 | J28: =IF(J26,J26,J41*J27/360) -> 96.36165 | K28: =IF(K26,K26,K41*K27/360) -> 96.36165
B29: 合同负债 | C29: ='1报表'!C57-'2报表调整'!K50 -> 0 | D29: ='1报表'!D57-'2报表调整'!L50 -> 0 | E29: ='2报表调整'!G50 -> 0
B30: 应付职工薪酬 | C30: ='1报表'!C58-'2报表调整'!K51 -> 0 | D30: ='1报表'!D58-'2报表调整'!L51 -> -0.188809 | E30: ='2报表调整'!G51 -> 0
B31: 应交税费 | C31: ='1报表'!C59 -> 100.54686 | D31: ='1报表'!D59 -> 28.32304 | E31: ='2报表调整'!G52 -> 2.22638
B32: 其他应付款计算行 | C32: ='1报表'!C62-'2报表调整'!K55 -> 499.382 | D32: ='1报表'!D62-'2报表调整'!L55 -> 567.3349 | E32: ='2报表调整'!G55 -> 211.23041
B33: 占成本比例 | C33: =IF(C42,C32/C42,0) -> 0.093776977 | D33: =IF(D42,D32/D42,0) -> 0.09657309 | E33: =IF(E42,E32*E3/E42/12,0) -> 0.046975325 | F33: 0.1 | G33: =F33 -> 0.1 | H33: =G33 -> 0.1 | I33: =H33 -> 0.1 | J33: =I33 -> 0.1 | K33: =J33 -> 0.1
B34: 其他应付款 | C34: =C32 -> 499.382 | D34: =D32 -> 567.3349 | E34: =E32 -> 211.23041 | F34: =IF(F32,F32,F42*F33) -> 395.879 | G34: =IF(G32,G32,G42*G33) -> 436.254 | H34: =IF(H32,H32,H42*H33) -> 470.81747 | I34: =IF(I32,I32,I42*I33) -> 491.7871 | J34: =IF(J32,J32,J42*J33) -> 507.41781 | K34: =IF(K32,K32,K42*K33) -> 508.13281
B35: 其他流动负债计算行 | C35: ='1报表'!C65-'2报表调整'!K58 -> 0 | D35: ='1报表'!D65-'2报表调整'!L58 -> 0 | E35: ='2报表调整'!G58 -> 0
B36: 占成本比例 | C36: =IF(C42,C35/C42,0) -> 0 | D36: =IF(D42,D35/D42,0) -> 0 | E36: =IF(E42,E35*E3/E42/12,0) -> 0
B37: 其他流动负债 | C37: =C35 -> 0 | D37: =D35 -> 0 | E37: =E35 -> 0 | F37: =IF(F35,F35,F42*F36) -> 0 | G37: =IF(G35,G35,G42*G36) -> 0 | H37: =IF(H35,H35,H42*H36) -> 0 | I37: =IF(I35,I35,I42*I36) -> 0 | J37: =IF(J35,J35,J42*J36) -> 0 | K37: =IF(K35,K35,K42*K36) -> 0
B38: 流动负债合计 | C38: =C25+C28+C29+C30+C31+C34+C37 -> 724.29886 | D38: =D25+D28+D29+D30+D31+D34+D37 -> 673.46913 | E38: =E25+E28+E29+E30+E31+E34+E37 -> 610.00565 | F38: =F25+F28+F29+F30+F31+F34+F37 -> 690.81178 | G38: =G25+G28+G29+G30+G31+G34+G37 -> 761.11733 | H38: =H25+H28+H29+H30+H31+H34+H37 -> 821.48274 | I38: =I25+I28+I29+I30+I31+I34+I37 -> 858.55716 | J38: =J25+J28+J29+J30+J31+J34+J37 -> 885.67825 | K38: =K25+K28+K29+K30+K31+K34+K37 -> 886.79047
B39: 营运资金 | C39: =C21-C38 -> 636.23677 | D39: =D21-D38 -> 628.66384 | E39: =E21-E38 -> 217.24188 | F39: =F21-F38 -> 273.58711 | G39: =G21-G38 -> 296.50656 | H39: =H21-H38 -> 318.17915 | I39: =I21-I38 -> 336.48038 | J39: =J21-J38 -> 344.24595 | K39: =K21-K38 -> 343.13373
B40: 营运资金增加额 | F40: =F39-E39 -> 56.345235 | G40: =G39-F39 -> 22.919444 | H40: =H39-G39 -> 21.672597 | I40: =I39-H39 -> 18.301231 | J40: =J39-I39 -> 7.7655671 | K40: =K39-J39 -> -1.1122222
B41: 营业收入 | C41: ='3收入'!C5 -> 6309.9996 | D41: ='3收入'!D5 -> 6454.082 | E41: ='3收入'!E5 -> 2068.9888 | F41: ='3收入'!F5 -> 4500 | G41: ='3收入'!G5 -> 4950 | H41: ='3收入'!H5 -> 5346 | I41: ='3收入'!I5 -> 5613.3 | J41: ='3收入'!J5 -> 5781.699 | K41: ='3收入'!K5 -> 5781.699
...

Sheet 11财务费用
B1: 财务费用预测表
B2: ='1报表'!B11 -> 评估基准日：2018/6/30
B3: ='1报表'!B12 -> 被评估单位：YLSJ公司 | E3: ='7折旧'!F3 -> 2018年剩余折摊月数 | F3: ='7折旧'!E3 -> 6 | K3: 单位：万元
B4: 汇总数据 | C4: 利息率% | D4: 借款起讫日期 | E4: ='3收入'!E4 -> 2018年1-6 | F4: ='7折旧'!E4 -> 2018年7-12 | G4: ='3收入'!G4 -> 2019年 | H4: ='3收入'!H4 -> 2020年 | I4: ='3收入'!I4 -> 2021年 | J4: ='3收入'!J4 -> 2022年 | K4: ='3收入'!K4 -> 2023年
B5: 短期借款
B6: 一年内到期的非流动负债
B7: 长期借款
B8: 新增借款 | C8: 0.054 | L8: 该行迭代计算得出
B9: 应付债券
B10: 付息负债合计 | E10: =SUM(E5:E9) -> 0 | F10: =SUM(F5:F9) -> 0 | G10: =SUM(G5:G9) -> 0 | H10: =SUM(H5:H9) -> 0 | I10: =SUM(I5:I9) -> 0 | J10: =SUM(J5:J9) -> 0 | K10: =SUM(K5:K9) -> 0
B11: 财务费用测算
B12: 利息支出 | C12: ='3收入'!C4 -> 2016年 | D12: ='3收入'!D4 -> 2017年 | E12: =E4 -> 2018年1-6 | F12: =F4 -> 2018年7-12 | G12: =G4 -> 2019年 | H12: =H4 -> 2020年 | I12: =I4 -> 2021年 | J12: =J4 -> 2022年 | K12: =K4 -> 2023年
B13: 短期借款 | F13: =$C5*E5/12*$F$3 -> 0 | G13: =$C5*F5 -> 0 | H13: =$C5*G5 -> 0 | I13: =$C5*H5 -> 0 | J13: =$C5*I5 -> 0 | K13: =$C5*J5 -> 0 | L13: 采用上年数计算，可根据具体发生情况填列
B14: 一年内到期的非流动负债 | F14: =$C6*E6/12*$F$3 -> 0 | G14: =$C6*F6 -> 0 | H14: =$C6*G6 -> 0 | I14: =$C6*H6 -> 0 | J14: =$C6*I6 -> 0 | K14: =$C6*J6 -> 0
B15: 长期借款 | F15: =$C7*E7/12*$F$3 -> 0 | G15: =$C7*F7 -> 0 | H15: =$C7*G7 -> 0 | I15: =$C7*H7 -> 0 | J15: =$C7*I7 -> 0 | K15: =$C7*J7 -> 0
B16: 新增借款 | F16: =$C8*E8/12*$F$3 -> 0 | G16: =$C8*F8 -> 0 | H16: =$C8*G8 -> 0 | I16: =$C8*H8 -> 0 | J16: =$C8*I8 -> 0 | K16: =$C8*J8 -> 0
B17: 应付债券 | F17: =$C9*E9/12*$F$3 -> 0 | G17: =$C9*F9 -> 0 | H17: =$C9*G9 -> 0 | I17: =$C9*H9 -> 0 | J17: =$C9*I9 -> 0 | K17: =$C9*J9 -> 0
B18: 利息支出小计 | C18: ='1报表'!C104 -> 0.473709 | D18: ='1报表'!D104 -> 0.956799 | E18: ='1报表'!E104 -> 0.0238 | F18: =SUM(F13:F17) -> 0 | G18: =SUM(G13:G17) -> 0 | H18: =SUM(H13:H17) -> 0 | I18: =SUM(I13:I17) -> 0 | J18: =SUM(J13:J17) -> 0 | K18: =SUM(K13:K17) -> 0
B19: 利息收入 | C19: ='1报表'!C105 -> 34.373249 | D19: ='1报表'!D105 -> 12.14111 | E19: ='1报表'!E105 -> 1.036709
B20: 汇兑损益及手续费等 | C20: =C21-C18+C19 -> 0 | D20: =D21-D18+D19 -> 0 | E20: =E21-E18+E19 -> 0 | L20: 预测期只考虑手续费，不考虑汇兑损益
B21: 财务费用合计 | C21: ='1报表'!C103 -> -33.89954 | D21: ='1报表'!D103 -> -11.184311 | E21: ='1报表'!E103 -> -1.012909 | F21: =SUM(F18:F20) -> 0 | G21: =SUM(G18:G20) -> 0 | H21: =SUM(H18:H20) -> 0 | I21: =SUM(I18:I20) -> 0 | J21: =SUM(J18:J20) -> 0 | K21: =SUM(K18:K20) -> 0
B23: 新增借款(由预测资产负债表计算得出) | D23: 无“预测财报”表删除 | F23: =预测财报!F83 -> 0 | G23: =预测财报!G83 -> 0 | H23: =预测财报!H83 -> 0 | I23: =预测财报!I83 -> 0 | J23: =预测财报!J83 -> 0 | K23: =预测财报!K83 -> 0 | L23: 企业未来是否有资金缺口，需要融多少资金，
B24: 是否相等？ | F24: =F8-F23 -> 0 | G24: =G8-G23 -> 0 | H24: =H8-H23 -> 0 | I24: =I8-I23 -> 0 | J24: =J8-J23 -> 0 | L24: 只有通过预测资产负债表计算才能得出。
B27: 借款明细核实如下

Sheet 12收益表
B1: 收益预测表
B2: ='1报表'!B11 -> 评估基准日：2018/6/30
B3: ='1报表'!B12 -> 被评估单位：YLSJ公司 | K3: 单位：万元
B4: 利润表（经营性） | C4: ='3收入'!C4 -> 2016年 | D4: ='3收入'!D4 -> 2017年 | E4: ='3收入'!E4 -> 2018年1-6 | F4: ='3收入'!F4 -> 2018年 | G4: ='3收入'!G4 -> 2019年 | H4: ='3收入'!H4 -> 2020年 | I4: ='3收入'!I4 -> 2021年 | J4: ='3收入'!J4 -> 2022年 | K4: ='3收入'!K4 -> 2023年
B5: 一、营业收入 | C5: ='3收入'!C5 -> 6309.9996 | D5: ='3收入'!D5 -> 6454.082 | E5: ='3收入'!E5 -> 2068.9888 | F5: ='3收入'!F5 -> 4500 | G5: ='3收入'!G5 -> 4950 | H5: ='3收入'!H5 -> 5346 | I5: ='3收入'!I5 -> 5613.3 | J5: ='3收入'!J5 -> 5781.699 | K5: ='3收入'!K5 -> 5781.699
B6: 减:营业成本 | C6: ='4成本'!C5 -> 5325.209 | D6: ='4成本'!D5 -> 5874.6686 | E6: ='4成本'!E5 -> 2248.3124 | F6: ='4成本'!F5 -> 3958.79 | G6: ='4成本'!G5 -> 4362.54 | H6: ='4成本'!H5 -> 4708.1747 | I6: ='4成本'!I5 -> 4917.871 | J6: ='4成本'!J5 -> 5074.1781 | K6: ='4成本'!K5 -> 5081.3281
B7: 减:税金及附加 | C7: ='5税金'!C5 -> 32.988746 | D7: ='5税金'!D5 -> 28.542702 | E7: ='5税金'!E5 -> 19.638479 | F7: ='5税金'!F5 -> 22.5 | G7: ='5税金'!G5 -> 24.75 | H7: ='5税金'!H5 -> 26.73 | I7: ='5税金'!I5 -> 28.0665 | J7: ='5税金'!J5 -> 28.908495 | K7: ='5税金'!K5 -> 28.908495
B8: 减:销售费用 | C8: ='6销管'!C5 -> 0 | D8: ='6销管'!D5 -> 0 | E8: ='6销管'!E5 -> 0 | F8: ='6销管'!F5 -> 0 | G8: ='6销管'!G5 -> 0 | H8: ='6销管'!H5 -> 0 | I8: ='6销管'!I5 -> 0 | J8: ='6销管'!J5 -> 0 | K8: ='6销管'!K5 -> 0
B9: 减:管理费用 | C9: ='6销管'!C6 -> 668.47256 | D9: ='6销管'!D6 -> 615.9856 | E9: ='6销管'!E6 -> 268.92924 | F9: ='6销管'!F6 -> 475.43751 | G9: ='6销管'!G6 -> 512.95 | H9: ='6销管'!H6 -> 554.946 | I9: ='6销管'!I6 -> 583.4433 | J9: ='6销管'!J6 -> 599.9516 | K9: ='6销管'!K6 -> 599.9516
B10: 减:研发费用 | C10: ='6销管'!C7 -> 0 | D10: ='6销管'!D7 -> 0 | E10: ='6销管'!E7 -> 0 | F10: ='6销管'!F7 -> 0 | G10: ='6销管'!G7 -> 0 | H10: ='6销管'!H7 -> 0 | I10: ='6销管'!I7 -> 0 | J10: ='6销管'!J7 -> 0 | K10: ='6销管'!K7 -> 0
B11: 减:财务费用 | C11: ='11财务费用'!C21 -> -33.89954 | D11: ='11财务费用'!D21 -> -11.184311 | E11: ='11财务费用'!E21 -> -1.012909 | F11: ='11财务费用'!F21+E11 -> -1.012909 | G11: ='11财务费用'!G21 -> 0 | H11: ='11财务费用'!H21 -> 0 | I11: ='11财务费用'!I21 -> 0 | J11: ='11财务费用'!J21 -> 0 | K11: ='11财务费用'!K21 -> 0
B12: 二、营业利润 | C12: =C5-SUM(C6:C11) -> 317.22878 | D12: =D5-SUM(D6:D11) -> -53.930552 | E12: =E5-SUM(E6:E11) -> -466.87835 | F12: =F5-SUM(F6:F11) -> 44.285403 | G12: =G5-SUM(G6:G11) -> 49.76 | H12: =H5-SUM(H6:H11) -> 56.149268 | I12: =I5-SUM(I6:I11) -> 83.9192 | J12: =J5-SUM(J6:J11) -> 78.660776 | K12: =K5-SUM(K6:K11) -> 71.510776
B13: 三、利润总额 | C13: =C12 -> 317.22878 | D13: =D12 -> -53.930552 | E13: =E12 -> -466.87835 | F13: =F12 -> 44.285403 | G13: =G12 -> 49.76 | H13: =H12 -> 56.149268 | I13: =I12 -> 83.9192 | J13: =J12 -> 78.660776 | K13: =K12 -> 71.510776
B14: 减：弥补以前年度亏损 | F14: =-D13 -> 53.930552 | G14: =F14-F13 -> 9.645149
B15: 减：研发费用加计扣除
B16: 减：其他纳税调减额
B17: 加：其他纳税调增额
B18: 应纳税所得额 | F18: =F13-F14-F15-F16+F17 -> -9.645149 | G18: =G13-G14-G15-G16+G17 -> 40.114851 | H18: =H13-H14-H15-H16+H17 -> 56.149268 | I18: =I13-I14-I15-I16+I17 -> 83.9192 | J18: =J13-J14-J15-J16+J17 -> 78.660776 | K18: =K13-K14-K15-K16+K17 -> 71.510776
B19: 所得税税率 | F19: 0.25 | G19: 0.25 | H19: 0.25 | I19: 0.25 | J19: 0.25 | K19: 0.25
B20: 减:所得税费用 | F20: =IF(F18<0,0,F18*F19) -> 0 | G20: =IF(G18<0,0,G18*G19) -> 10.028713 | H20: =IF(H18<0,0,H18*H19) -> 14.037317 | I20: =IF(I18<0,0,I18*I19) -> 20.9798 | J20: =IF(J18<0,0,J18*J19) -> 19.665194 | K20: =IF(K18<0,0,K18*K19) -> 17.877694
B21: 四、净利润 | F21: =F13-F20 -> 44.285403 | G21: =G13-G20 -> 39.731287 | H21: =H13-H20 -> 42.111951 | I21: =I13-I20 -> 62.9394 | J21: =J13-J20 -> 58.995582 | K21: =K13-K20 -> 53.633082
B22: 减:少数股东损益
B23: 五、归母净利润 | F23: =F21-F22 -> 44.285403 | G23: =G21-G22 -> 39.731287 | H23: =H21-H22 -> 42.111951 | I23: =I21-I22 -> 62.9394 | J23: =J21-J22 -> 58.995582 | K23: =K21-K22 -> 53.633082
B26: 补充预测利润表用数据，无“预测财报”表删除下列数据！
B27: 三、利润总额 | C27: =C13 -> 317.22878 | D27: =D13 -> -53.930552 | E27: =E13 -> -466.87835
B28: 减：弥补以前年度亏损
B29: 减：研发费用加计扣除
B30: 减：其他纳税调减额
B31: 加：其他纳税调增额
B32: 应纳税所得额 | C32: =C27-C28-C29-C30+C31 -> 317.22878 | D32: =D27-D28-D29-D30+D31 -> -53.930552 | E32: =E27-E28-E29-E30+E31 -> -466.87835
B33: 所得税税率 | C33: 0.25 | D33: 0.25 | E33: 0.25
B34: 减:所得税费用 | C34: =IF(C32<0,0,C32*C33) -> 79.307194 | D34: =IF(D32<0,0,D32*D33) -> 0 | E34: =IF(E32<0,0,E32*E33) -> 0

Sheet 13FCFF
B1: 企业自由现金流量测算表
B2: ='1报表'!B11 -> 评估基准日：2018/6/30
B3: ='1报表'!B12 -> 被评估单位：YLSJ公司 | L3: 单位：万元
B4: 项目 | F4: ='7折旧'!E4 -> 2018年7-12 | G4: ='3收入'!G4 -> 2019年 | H4: ='3收入'!H4 -> 2020年 | I4: ='3收入'!I4 -> 2021年 | J4: ='3收入'!J4 -> 2022年 | K4: ='3收入'!K4 -> 2023年 | L4: 永续期
B5: 一、营业收入 | F5: ='12收益表'!F5-'12收益表'!E5 -> 2431.0112 | G5: ='12收益表'!G5 -> 4950 | H5: =预测财报!H20 -> 5346 | I5: =预测财报!I20 -> 5613.3 | J5: =预测财报!J20 -> 5781.699 | K5: =预测财报!K20 -> 5781.699 | L5: =K5 -> 5781.699
B6: 减：营业成本 | F6: ='12收益表'!F6-'12收益表'!E6 -> 1710.4776 | G6: ='12收益表'!G6 -> 4362.54 | H6: ='12收益表'!H6 -> 4708.1747 | I6: ='12收益表'!I6 -> 4917.871 | J6: ='12收益表'!J6 -> 5074.1781 | K6: ='12收益表'!K6 -> 5081.3281 | L6: =K6 -> 5081.3281
B7: 减：税金及附加 | F7: ='12收益表'!F7-'12收益表'!E7 -> 2.861521 | G7: ='12收益表'!G7 -> 24.75 | H7: ='12收益表'!H7 -> 26.73 | I7: ='12收益表'!I7 -> 28.0665 | J7: ='12收益表'!J7 -> 28.908495 | K7: ='12收益表'!K7 -> 28.908495 | L7: =K7 -> 28.908495
B8: 减：销售费用 | F8: ='12收益表'!F8-'12收益表'!E8 -> 0 | G8: ='12收益表'!G8 -> 0 | H8: ='12收益表'!H8 -> 0 | I8: ='12收益表'!I8 -> 0 | J8: ='12收益表'!J8 -> 0 | K8: ='12收益表'!K8 -> 0 | L8: =K8 -> 0
B9: 减：管理费用 | F9: ='12收益表'!F9-'12收益表'!E9 -> 206.50827 | G9: ='12收益表'!G9 -> 512.95 | H9: ='12收益表'!H9 -> 554.946 | I9: ='12收益表'!I9 -> 583.4433 | J9: ='12收益表'!J9 -> 599.9516 | K9: ='12收益表'!K9 -> 599.9516 | L9: =K9 -> 599.9516
B10: 减：研发费用 | F10: ='12收益表'!F10-'12收益表'!E10 -> 0 | G10: ='12收益表'!G10 -> 0 | H10: ='12收益表'!H10 -> 0 | I10: ='12收益表'!I10 -> 0 | J10: ='12收益表'!J10 -> 0 | K10: ='12收益表'!K10 -> 0 | L10: =K10 -> 0
B11: 减：财务费用 | F11: ='12收益表'!F11-'12收益表'!E11 -> 0 | G11: ='12收益表'!G11 -> 0 | H11: ='12收益表'!H11 -> 0 | I11: ='12收益表'!I11 -> 0 | J11: ='12收益表'!J11 -> 0 | K11: ='12收益表'!K11 -> 0 | L11: =IF('11财务费用'!K10,SUMPRODUCT('11财务费用'!C5:C9,'11财务费用'!K5:K9)+'11财务费用'!K20,0) -> 0
B12: 二、营业利润 | F12: =F5-SUM(F6:F11) -> 511.16375 | G12: =G5-SUM(G6:G11) -> 49.76 | H12: =H5-SUM(H6:H11) -> 56.149268 | I12: =I5-SUM(I6:I11) -> 83.9192 | J12: =J5-SUM(J6:J11) -> 78.660776 | K12: =K5-SUM(K6:K11) -> 71.510776 | L12: =L5-SUM(L6:L11) -> 71.510776
B13: 三、利润总额 | F13: =F12 -> 511.16375 | G13: =G12 -> 49.76 | H13: =H12 -> 56.149268 | I13: =I12 -> 83.9192 | J13: =J12 -> 78.660776 | K13: =K12 -> 71.510776 | L13: =L12 -> 71.510776
