Workbook
Name _2003_6_25: [1]ITEM!#REF!
Name _2003_6_25: [1]ITEM!#REF!
Name _2003_6_25: [1]ITEM!#REF!
Name _2003_6_25: [1]ITEM!#REF!
Name _2003_6_25: [1]ITEM!#REF!
Name _BSP2: #REF!
Name _BSP2: #REF!
Name _BSP2: #REF!
Name _BSP2: #REF!
Name _BSP2: #REF!
Name _BSP2: #REF!
Name _pgz101: #REF!
Name _pgz101: #REF!
Name _pgz101: #REF!
Name _pgz101: #REF!
Name _pgz101: #REF!
Name _pgz101: #REF!
Name _pgz102: #REF!
Name _pgz102: #REF!
Name _pgz102: #REF!
Name _pgz102: #REF!
Name _pgz102: #REF!
Name _pgz102: #REF!
Name _pgz103: #REF!
Name _pgz103: #REF!
Name _pgz103: #REF!
Name _pgz103: #REF!
Name _pgz103: #REF!
Name _pgz103: #REF!
Name _pgz104: #REF!
Name _pgz104: #REF!
Name _pgz104: #REF!
Name _pgz104: #REF!
Name _pgz104: #REF!
Name _pgz104: #REF!
Name _pgz105: #REF!
Name _pgz105: #REF!
Name _pgz105: #REF!
Name _pgz105: #REF!
Name _pgz105: #REF!
Name _pgz105: #REF!
Name _pgz106: #REF!
Name _pgz106: #REF!
Name _pgz106: #REF!
Name _pgz106: #REF!
Name _pgz106: #REF!
Name _pgz106: #REF!
Name _pgz511: #REF!
Name _pgz511: #REF!
Name _pgz511: #REF!
Name _pgz511: #REF!
Name _pgz511: #REF!
Name _pgz511: #REF!
Name _pgz512: #REF!
Name _pgz512: #REF!
Name _pgz512: #REF!
Name _pgz512: #REF!
Name _pgz512: #REF!
Name _pgz512: #REF!
Name _pgz513: #REF!

Sheet 记事
C2: 应用前提
C3: 1、稳定期增长率假设为零，如考虑永续增长，终值需另外用价值驱动因素模型计算。
C4: 2、未考虑预测期内被评估企业依靠收购所创造的收入增长。
C5: 3、FCFE模型只适用评估基准日及未来预测期间无付息负债的情形。
C6: 建模的规则
C7: 表中数字 | D7: 蓝字黄底表示手动录入数据
C8: 表中数字 | D8: 红字表示在该单元格中的公式左右不一样，或强调关注。
D9: 同一年的数据在不同表中均在同一列中，方便查找错误。
D10: 不要隐藏行和列，采用数据中的创建组和取消组合处理，易于查找数据。
D11: 单元格中的公式不要直接写入数据，数据由表外单元格链入。
D12: 工作底稿完成后无关数据全部删除，只保留有关数据。
C14: 密码0528
C15: V5.0修改记录
C17: 1、表“7折旧”、“8摊销”、“9溢余现金”、“10营运”进行拆分，表“7折旧”和“8摊销”“+”后隐藏的是自动计算公式，一般无需改动。
C18: 限制用途现金位置进行了移动；“9溢余现金”、“10营运”，增加了历史数据分析，反映趋势变化。
C19: 2、表“预测财报”布局调整：增加完成资产负债表、利润表剩余项目，后面报表自动计算得出财务指标，用于分析历史与未来趋势。
C20: 预测资产负债表可以合理分析企业未来的借款金额。
C21: 3、表“9财务费用”末端行增加(由预测资产负债表计算得出)新增借款，反映企业未来是否有资金缺口，需要融多少资金。
C22: 4、表“13FCFF”修改折现率计算方法——迭代计算。
C24: V5.1修改记录
C25: 1、表“7折旧”行42即“期末设备类账面净值”公式汇总错误，已修改。该行数据不影响估值，但影响“预测财报”数据。

Sheet 步骤
E1: 索引号：SY1
B2: 企业价值评估现金流量折现法(DCF)计算及步骤复核表
B3: ='1报表'!B12 -> 被评估单位：JSBD公司 | D3: 评估基准日 | E3: ='1报表'!E5 -> 43100
B4: 评估人员 | D4: 现场工作日期
B5: 复核人 | D5: 复核日期
B6: 操作步骤与要求 | D6: 是 | E6: 不适用
B7: 一、前期工作
B8: 1.取得被评估企业前3~5年和本期审计报告、会计报表、科目明细表，以及相关收入、成本、费用等统计资料
B9: 2.取得企业资产、财务、经营状况资料，着重了解经营活动涉及的范围，收入、收益结构，资产配置情况，在此基础上区分企业经营活动和经营活动之外的其他活动涉及相关资产、负债、损益等。布置企业填报资产基础法申报表、收益预测申报表，并在资产基础法的申报表上标识经营性资产（负债）与非经营性资产（负债）。以上资料由企业盖章或签字确认。
B10: 二、统计、调整
B11: 3.根据评估业务的具体情况，在分析企业各科目明细的基础上，分析和调整被评估企业（1）财务报表编制基础；（2）非经常性收入和支出；（3）非经营性资产、负债和溢余资产及其相关的收入和支出。如涉及可比企业同理处理。
B12: 4.区分经营活动与其他活动，并统计、分析： a\营业收入；b\营业成本(材料、燃料动力、人工、制造费用)；c\税金及附加；d\折旧及摊销、固定及无形资产、长期待摊；e\销售、管理费用；f\资产减值损失、公允价值变动收益；g\营业外收支；h\财务费用
B13: 5.区分经营活动和其他活动，编制利润调整表
B14: 6.计算经营最低保有现金，测算溢余现金
B15: 7.区分经营活动和其他活动编制资产负债调整表
B16: 8.根据调整后的资产负债表、利润表，分析历史财务指标。
B17: 9.正确识别被评估企业所属行业，审慎选择参考上市公司，并统计相关财务指标
B18: 三、分析、预测
... B40: 金融资产、未并表的长期股权投资、投资性房地产以及溢余及非经营资产、负债等相关活动。

Sheet 1报表
B2: 输入信息
B3: 被评估单位： | E3: JSBD公司
B4: 评估对象： | E4: 股东全部权益价值
B5: 评估基准日： | E5: 43100
B6: 短期预测(期)： | E6: 5
B7: 预测期间： | C7: =E5+1 -> 43101 | D7: To | E7: =EDATE(E5,E6*12) -> 44926
B10: 资产负债表
B11: =B5&TEXT(E5,"YYYY/M/D") -> 评估基准日：2017/12/31
B12: =B3&E3 -> 被评估单位：JSBD公司 | E12: 单位：万元
B13: 科目 | C13: =EDATE(D13,-12) -> 42369 | D13: =EDATE(E13,-12) -> 42735 | E13: =E5 -> 43100
B14: 流动资产：
B15: 货币资金 | C15: 107.23511 | D15: 232.26688 | E15: 276.81451
B16: 以公允价值计量且其变动计入当期损益的金融资产
B17: 衍生金融资产
B18: 应收票据及应收账款 | C18: =9+2168.895942 -> 2177.8959 | D18: =97.73602+2520.404145 -> 2618.1402 | E18: =293.613289+3142.781439 -> 3436.3947
B19: 预付款项 | C19: 163.1034 | D19: 99.846675 | E19: 52.493946
A20: 保留 | B20: 应收利息
A21: 保留 | B21: 应收股利
B22: 其他应收款 | C22: 113.81446 | D22: 191.70885 | E22: 52.199492
B23: 存货 | C23: 879.74901 | D23: 1054.9352 | E23: 1331.2815
A24: 新准则 | B24: 合同资产
B25: 持有待售资产
B26: 一年内到期的非流动资产
B27: 其他流动资产 | C27: 34.793744 | D27: 21.197218 | E27: 162.85866
B28: 流动资产合计 | C28: =SUM(C15:C27) -> 3476.5917 | D28: =SUM(D15:D27) -> 4218.095 | E28: =SUM(E15:E27) -> 5312.0429
B29: 非流动资产：
B30: 可供出售金融资产
B31: 持有至到期投资
A32: 新准则 | B32: 债权投资
A33: 新准则 | B33: 其他债权投资
B34: 长期应收款
B35: 长期股权投资
A36: 新准则 | B36: 其他权益工具投资
A37: 新准则 | B37: 其他非流动金融资产
B38: 投资性房地产
B39: 固定资产 | C39: 2374.1047 | D39: 2109.0141 | E39: 2328.7283
B40: 在建工程 | E40: 201.28205
B41: 生产性生物资产
B42: 油气资产
B43: 无形资产 | C43: 317.96748 | D43: 306.03733 | E43: 459.60841
...

Sheet 2报表调整
B2: 资产负债调整表 | J2: 非经营性资产和负债分析表
B3: ='1报表'!B11 -> 评估基准日：2017/12/31 | K3: 根据资产负债核实表填写
B4: ='1报表'!B12 -> 被评估单位：JSBD公司 | H4: 单位：万元
B5: 科目 | C5: ='1报表'!E13 -> 43100 | N5: 单位：万元
C6: 账面值 | D6: 重分类 | E6: 其中：非经营性资产、负债 | F6: 溢余资产 | G6: 经营性资产及负债账面值 | H6: 调整原因 | J6: 项目 | K6: ='1报表'!C13 -> 42369 | L6: ='1报表'!D13 -> 42735 | M6: ='1报表'!E13 -> 43100 | N6: 评估值
B7: 流动资产： | J7: 非经营性资产
B8: 货币资金 | C8: ='1报表'!E15 -> 276.81451 | D8: =C8 -> 276.81451 | F8: ='9溢余现金'!E25 -> 37.453128 | G8: =D8-(E8+F8) -> 239.36138 | J8: 货币资金
B9: 交易性金融资产 | C9: ='1报表'!E16 -> 0 | D9: =C9 -> 0 | G9: =D9-(E9+F9) -> 0 | J9: 交易性金融资产 | K9: ='1报表'!C16 -> 0 | L9: ='1报表'!D16 -> 0 | M9: =E9 -> 0 | N9: =M9 -> 0
B10: 衍生金融资产 | C10: ='1报表'!E17 -> 0 | D10: =C10 -> 0 | G10: =D10-(E10+F10) -> 0 | J10: 衍生金融资产 | K10: ='1报表'!C17 -> 0 | L10: ='1报表'!D17 -> 0 | M10: =E10 -> 0 | N10: =M10 -> 0
B11: 应收票据及应收账款 | C11: ='1报表'!E18 -> 3436.3947 | D11: =C11 -> 3436.3947 | G11: =D11-(E11+F11) -> 3436.3947 | J11: 非经营性应收票据及应收账款 | M11: =E11 -> 0 | N11: =M11 -> 0
B12: 预付款项 | C12: ='1报表'!E19 -> 52.493946 | D12: =C12 -> 52.493946 | E12: 8.943124 | G12: =D12-(E12+F12) -> 43.550822 | H12: 费用性质无票挂账款项 | J12: 非经营性预付款项 | M12: =E12 -> 8.943124 | N12: 0
B13: 应收利息 | C13: ='1报表'!E20 -> 0 | D13: =C13 -> 0 | G13: =D13-(E13+F13) -> 0 | J13: 应收利息 | K13: ='1报表'!C20 -> 0 | L13: ='1报表'!D20 -> 0 | M13: =E13 -> 0 | N13: =M13 -> 0
B14: 应收股利 | C14: ='1报表'!E21 -> 0 | D14: =C14 -> 0 | G14: =D14-(E14+F14) -> 0 | J14: 应收股利 | K14: ='1报表'!C21 -> 0 | L14: ='1报表'!D21 -> 0 | M14: =E14 -> 0 | N14: =M14 -> 0
B15: 其他应收款 | C15: ='1报表'!E22 -> 52.199492 | D15: =C15 -> 52.199492 | E15: 29.88 | G15: =D15-(E15+F15) -> 22.319492 | J15: 非经营性其他应收款 | M15: =E15 -> 29.88 | N15: =D95 -> 5.880218
B16: 存货 | C16: ='1报表'!E23 -> 1331.2815 | D16: =C16 -> 1331.2815 | G16: =D16-(E16+F16) -> 1331.2815 | J16: 非经营、报废的存货 | M16: =E16 -> 0 | N16: =M16 -> 0
B17: 合同资产 | C17: ='1报表'!E24 -> 0 | D17: =C17 -> 0 | G17: =D17-(E17+F17) -> 0 | J17: 非经营性合同资产 | M17: =E17 -> 0 | N17: =M17 -> 0
B18: 持有待售资产 | C18: ='1报表'!E25 -> 0 | D18: =C18 -> 0 | G18: =D18-(E18+F18) -> 0 | J18: 持有待售资产 | K18: ='1报表'!C25 -> 0 | L18: ='1报表'!D25 -> 0 | M18: =E18 -> 0 | N18: =M18 -> 0
B19: 一年内到期的非流动资产 | C19: ='1报表'!E26 -> 0 | D19: =C19 -> 0 | G19: =D19-(E19+F19) -> 0 | J19: 非经营性一年内到期的非流动资产 | M19: =E19 -> 0 | N19: =M19 -> 0
B20: 其他流动资产 | C20: ='1报表'!E27 -> 162.85866 | D20: =C20 -> 162.85866 | E20: 77.8 | G20: =D20-(E20+F20) -> 85.05866 | H20: 理财产品 | J20: 非经营性其他流动资产 | M20: =E20 -> 77.8 | N20: =M20 -> 77.8
B21: 流动资产合计 | C21: =SUM(C8:C20) -> 5312.0429 | D21: =SUM(D8:D20) -> 5312.0429 | E21: =SUM(E8:E20) -> 116.62312 | F21: =SUM(F8:F20) -> 37.453128 | G21: =SUM(G8:G20) -> 5157.9666 | J21: 非经营性流动资产小计 | K21: =SUM(K9:K20) -> 0 | L21: =SUM(L9:L20) -> 0 | M21: =SUM(M9:M20) -> 116.62312 | N21: =SUM(N9:N20) -> 83.680218
B22: 非流动资产：
B23: 可供出售金融资产 | C23: ='1报表'!E30 -> 0 | D23: =C23 -> 0 | G23: =D23-(E23+F23) -> 0 | J23: 可供出售金融资产 | K23: ='1报表'!C30 -> 0 | L23: ='1报表'!D30 -> 0 | M23: =E23 -> 0
B24: 持有至到期投资 | C24: ='1报表'!E31 -> 0 | D24: =C24 -> 0 | G24: =D24-(E24+F24) -> 0 | J24: 持有至到期投资 | K24: ='1报表'!C31 -> 0 | L24: ='1报表'!D31 -> 0 | M24: =E24 -> 0
B25: 债权投资 | C25: ='1报表'!E32 -> 0 | D25: =C25 -> 0 | G25: =D25-(E25+F25) -> 0 | J25: 债权投资 | K25: ='1报表'!C32 -> 0 | L25: ='1报表'!D32 -> 0 | M25: =E25 -> 0
B26: 其他债权投资 | C26: ='1报表'!E33 -> 0 | D26: =C26 -> 0 | G26: =D26-(E26+F26) -> 0 | J26: 其他债权投资 | K26: ='1报表'!C33 -> 0 | L26: ='1报表'!D33 -> 0 | M26: =E26 -> 0
B27: 长期应收款 | C27: ='1报表'!E34 -> 0 | D27: =C27 -> 0 | G27: =D27-(E27+F27) -> 0 | J27: 非经营性长期应收款 | M27: =E27 -> 0
B28: 长期股权投资 | C28: ='1报表'!E35 -> 0 | D28: =C28 -> 0 | G28: =D28-(E28+F28) -> 0 | J28: 长期股权投资 | K28: ='1报表'!C35 -> 0 | L28: ='1报表'!D35 -> 0 | M28: =E28 -> 0
B29: 其他权益工具投资 | C29: ='1报表'!E36 -> 0 | D29: =C29 -> 0 | G29: =D29-(E29+F29) -> 0 | J29: 其他权益工具投资 | K29: ='1报表'!C36 -> 0 | L29: ='1报表'!D36 -> 0 | M29: =E29 -> 0
B30: 其他非流动金融资产 | C30: ='1报表'!E37 -> 0 | D30: =C30 -> 0 | G30: =D30-(E30+F30) -> 0 | J30: 其他非流动金融资产 | K30: ='1报表'!C37 -> 0 | L30: ='1报表'!D37 -> 0 | M30: =E30 -> 0
B31: 投资性房地产 | C31: ='1报表'!E38 -> 0 | D31: =C31 -> 0 | G31: =D31-(E31+F31) -> 0 | J31: 投资性房地产 | K31: ='1报表'!C38 -> 0 | L31: ='1报表'!D38 -> 0 | M31: =E31 -> 0
B32: 固定资产 | C32: ='1报表'!E39 -> 2328.7283 | D32: =C32 -> 2328.7283 | G32: =D32-(E32+F32) -> 2328.7283 | J32: 非经营性固定资产 | M32: =E32 -> 0
B33: 在建工程 | C33: ='1报表'!E40 -> 201.28205 | D33: =C33+153.51675 -> 354.7988 | G33: =D33-(E33+F33) -> 354.7988 | J33: 非经营性在建工程 | M33: =E33 -> 0
B34: 生产性生物资产 | C34: ='1报表'!E41 -> 0 | D34: =C34 -> 0 | G34: =D34-(E34+F34) -> 0 | J34: 非经营性生产性生物资产 | M34: =E34 -> 0
B35: 油气资产 | C35: ='1报表'!E42 -> 0 | D35: =C35 -> 0 | G35: =D35-(E35+F35) -> 0 | J35: 非经营性油气资产 | M35: =E35 -> 0
B36: 无形资产 | C36: ='1报表'!E43 -> 459.60841 | D36: =C36 -> 459.60841 | G36: =D36-(E36+F36) -> 459.60841 | J36: 非经营性无形资产 | M36: =E36 -> 0
B37: 开发支出 | C37: ='1报表'!E44 -> 0 | D37: =C37 -> 0 | G37: =D37-(E37+F37) -> 0 | J37: 非经营性开发支出 | M37: =E37 -> 0
B38: 商誉 | C38: ='1报表'!E45 -> 0 | D38: =C38 -> 0 | G38: =D38-(E38+F38) -> 0 | J38: 商誉
B39: 长期待摊费用 | C39: ='1报表'!E46 -> 0 | D39: =C39 -> 0 | G39: =D39-(E39+F39) -> 0 | J39: 非经营性长期待摊费用 | M39: =E39 -> 0
B40: 递延所得税资产 | C40: ='1报表'!E47 -> 101.06477 | D40: =C40 -> 101.06477 | G40: =D40-(E40+F40) -> 101.06477 | J40: 递延所得税资产 | M40: =E40 -> 0
B41: 其他非流动资产 | C41: ='1报表'!E48 -> 191.69743 | D41: =C41-153.51675 -> 38.18068 | G41: =D41-(E41+F41) -> 38.18068 | H41: 设备款153.51675万元，重分类到在建工程 | J41: 非经营性其他非流动资产 | M41: =E41 -> 0
...

Sheet 3收入
B1: 营业收入预测表
B2: ='1报表'!B11 -> 评估基准日：2017/12/31
B3: ='1报表'!B12 -> 被评估单位：JSBD公司 | J3: 单位：万元
B4: 年度 | C4: ='1报表'!C96 -> 2015年 | D4: ='1报表'!D96 -> 2016年 | E4: ='1报表'!E96 -> 2017年 | F4: =LEFT(E4,4)+1&"年" -> 2018年 | G4: =LEFT(F4,4)+1&"年" -> 2019年 | H4: =LEFT(G4,4)+1&"年" -> 2020年 | I4: =LEFT(H4,4)+1&"年" -> 2021年 | J4: =LEFT(I4,4)+1&"年" -> 2022年
B5: 数据汇总 | C5: ='1报表'!C97 -> 5647.5609 | D5: ='1报表'!D97 -> 7304.7745 | E5: ='1报表'!E97 -> 9615.5763 | F5: =F60 -> 11935.477 | G5: =G60 -> 14141.384 | H5: =H60 -> 15896.18 | I5: =I60 -> 16863.123 | J5: =J60 -> 17224.451
B6: 增长率 | D6: =IF(C5,D5/C5-1,"na") -> 0.29343883 | E6: =IF(D5,E5/D5-1,"na") -> 0.31634129 | F6: =IF(E5,F5/E5-1,"na") -> 0.24126489 | G6: =IF(F5,G5/F5-1,"na") -> 0.18481929 | H6: =IF(G5,H5/G5-1,"na") -> 0.12408942 | I6: =IF(H5,I5/H5-1,"na") -> 0.060828626 | J6: =IF(I5,J5/I5-1,"na") -> 0.021427138
B8: 项目 | D8: 2015年 | E8: 2016年 | F8: 2017年
B9: 内销 | C9: 可拆 | D9: 849.25232 | E9: 761.74943 | F9: 881.84195 | H9: 营业收入：主营业务收入、其他业务收入
C10: 钎焊 | D10: 3332.4019 | E10: 5230.7696 | F10: 7346.3833 | H10: 非经常性收入调整，形成新的增长率指标。
C11: 其他 | D11: 62.584148 | E11: 126.49229 | F11: 169.47457 | H11: 核实产能的天花板：重点预测期第一年（2018）
B12: 外销 | C12: 可拆 | D12: 189.80228 | E12: 103.84241 | F12: 188.39998 | H12: 后期收入的增长原因分析：
C13: 钎焊 | D13: 759.94412 | E13: 659.68712 | F13: 515.85933 | H13: 价格、产品结构调整→→组合价格的提高
C14: 其他 | D14: 288.58919 | E14: 163.05443 | F14: 294.8955 | H14: 增加资本性支出，提高产能→→原资本性支出不足，提高了支出金额→→ROIC
B15: 材料及板片 | D15: 164.98691 | E15: 259.17922 | F15: 218.72166 | H15: 行业增长率分析→→核实验证
B16: 合计 | D16: =SUM(D9:D15) -> 5647.5609 | E16: =SUM(E9:E15) -> 7304.7745 | F16: =SUM(F9:F15) -> 9615.5763
H17: 如果历史营业收入和成本中的其他收入和成本，未来预测收入成本中没有，则历史报表项需要调整。例如投资性房地产
B18: 按产品分类
B19: 收入分析 | C19: 2015年 | D19: 2016年 | E19: 2017年
B20: 可拆 | C20: =D9+D12 -> 1039.0546 | D20: =E9+E12 -> 865.59183 | E20: =F9+F12 -> 1070.2419
B21: 钎焊 | C21: =D10+D13 -> 4092.346 | D21: =E10+E13 -> 5890.4567 | E21: =F10+F13 -> 7862.2427
B22: 其他 | C22: =D11+D14 -> 351.17334 | D22: =E11+E14 -> 289.54672 | E22: =F11+F14 -> 464.37007
B23: 小计 | C23: =SUM(C20:C22) -> 5482.5739 | D23: =SUM(D20:D22) -> 7045.5953 | E23: =SUM(E20:E22) -> 9396.8547
B25: 产品增长率 | C25: 2015年 | D25: 2016年 | E25: 2017年
B26: 可拆 | D26: =D20/C20-1 -> -0.16694288 | E26: =E20/D20-1 -> 0.23642795
B27: 钎焊 | D27: =D21/C21-1 -> 0.43938385 | E27: =E21/D21-1 -> 0.33474245
B28: 其他 | D28: =D22/C22-1 -> -0.17548774 | E28: =E22/D22-1 -> 0.60378286
B29: 主要产品 | D29: =D23/C23-1 -> 0.28508897 | E29: =E23/D23-1 -> 0.33372047
B31: 产品结构占比 | C31: 2015年 | D31: 2016年 | E31: 2017年
B32: 可拆 | C32: =C20/C$23 -> 0.18951949 | D32: =D20/D$23 -> 0.12285574 | E32: =E20/E$23 -> 0.11389364 | F32: 产品结构下降，核实是否转型？比例继续下降？
B33: 钎焊 | C33: =C21/C$23 -> 0.74642787 | D33: =D21/D$23 -> 0.83604813 | E33: =E21/E$23 -> 0.83668876 | F33: 主要产品在增加，进一步核实驱动因素是组合单价、还是数量？
B34: 其他 | C34: =C22/C$23 -> 0.064052641 | D34: =D22/D$23 -> 0.041096133 | E34: =E22/E$23 -> 0.049417607
B36: 按销售分类
C37: 2015年 | D37: 2016年 | E37: 2017年
B38: 内销 | C38: =(SUM(D9:D11)+D15)/D16 -> 0.7807309 | D38: =(SUM(E9:E11)+E15)/E16 -> 0.87315365 | E38: =(SUM(F9:F11)+F15)/F16 -> 0.89608997 | F38: 主要市场在国内 | H38: 未来销售比例90:10
B39: 外销 | C39: =SUM(D12:D14)/D16 -> 0.2192691 | D39: =SUM(E12:E14)/E16 -> 0.12684635 | E39: =SUM(F12:F14)/F16 -> 0.10391003 | F39: 外销比例在下降 | H39: 外销费用不应大幅变动，即销售费用的外销费用
B41: 内外销影响的是销售毛利的多少，了解这个比例为确定毛利率水平和销售费用的变化。
B42: 采用一种分类方式预测，两种方式组合增加了预测难度
B43: 尽调结论
B44: 1、17年全年产能利用率约65%，产能瓶颈在烧结用炉子和检测设备，已订购相关设备，18年产能可以提高40%； | H44: =E57/0.65 -> 12095.758 | I44: 没超产能
B45: 2、目前的主要产品仍是钎焊换热器，18年销量的主要增长也在钎焊换热器；
...

Sheet 4成本
B1: 营业成本预测表
B2: ='1报表'!B11 -> 评估基准日：2017/12/31
B3: ='1报表'!B12 -> 被评估单位：JSBD公司 | J3: 单位：万元
B4: 年度 | C4: ='3收入'!C4 -> 2015年 | D4: ='3收入'!D4 -> 2016年 | E4: ='3收入'!E4 -> 2017年 | F4: ='3收入'!F4 -> 2018年 | G4: ='3收入'!G4 -> 2019年 | H4: ='3收入'!H4 -> 2020年 | I4: ='3收入'!I4 -> 2021年 | J4: ='3收入'!J4 -> 2022年
B5: 数据汇总 | C5: ='1报表'!C98 -> 3450.9962 | D5: ='1报表'!D98 -> 4625.6862 | E5: ='1报表'!E98 -> 5762.986 | F5: =F106 -> 7161.2864 | G5: =G106 -> 8484.8303 | H5: =H106 -> 9537.7079 | I5: =I106 -> 10117.874 | J5: =J106 -> 10334.671
B6: 营业收入 | C6: ='3收入'!C5 -> 5647.5609 | D6: ='3收入'!D5 -> 7304.7745 | E6: ='3收入'!E5 -> 9615.5763 | F6: ='3收入'!F5 -> 11935.477 | G6: ='3收入'!G5 -> 14141.384 | H6: ='3收入'!H5 -> 15896.18 | I6: ='3收入'!I5 -> 16863.123 | J6: ='3收入'!J5 -> 17224.451
B7: 毛利率 | C7: =IF(C6,(C6-C5)/C6,"na") -> 0.38894042 | D7: =IF(D6,(D6-D5)/D6,"na") -> 0.36675852 | E7: =IF(E6,(E6-E5)/E6,"na") -> 0.40066141 | F7: =IF(F6,(F6-F5)/F6,"na") -> 0.4 | G7: =IF(G6,(G6-G5)/G6,"na") -> 0.4 | H7: =IF(H6,(H6-H5)/H6,"na") -> 0.4 | I7: =IF(I6,(I6-I5)/I6,"na") -> 0.4 | J7: =IF(J6,(J6-J5)/J6,"na") -> 0.4
B8: 营业成本预测（生产型企业）（方式一）
B9: 项目1 | C9: =C4 -> 2015年 | D9: =D4 -> 2016年 | E9: =E4 -> 2017年 | F9: =F4 -> 2018年 | G9: =G4 -> 2019年 | H9: =H4 -> 2020年 | I9: =I4 -> 2021年 | J9: =J4 -> 2022年 | L9: 按科目进行分析
B10: 原材料 | L10: 评估实务中还应当对原材料的变化趋势作一说明，公司消化原材料价格变化的经营措施。
B11: 占收入比 | C11: =IF(C6,C10/C6,"na") -> 0 | D11: =IF(D6,D10/D6,"na") -> 0 | E11: =IF(E6,E10/E6,"na") -> 0 | L11: 员工人数是否会随着收入增长而增加，消化人工成本的措施。
B12: =B10 -> 原材料 | C12: =C10 -> 0 | D12: =D10 -> 0 | E12: =E10 -> 0 | F12: =IF(F10,F10,F11*F6) -> 0 | G12: =IF(G10,G10,G11*G6) -> 0 | H12: =IF(H10,H10,H11*H6) -> 0 | I12: =IF(I10,I10,I11*I6) -> 0 | J12: =IF(J10,J10,J11*J6) -> 0 | L12: （要有具体的纸质底稿支撑）
B13: 占收入比 | F13: =IF(F6,F12/F6,"na") -> 0 | G13: =IF(G6,G12/G6,"na") -> 0 | H13: =IF(H6,H12/H6,"na") -> 0 | I13: =IF(I6,I12/I6,"na") -> 0 | J13: =IF(J6,J12/J6,"na") -> 0
B15: 项目2 | C15: =C4 -> 2015年 | D15: =D4 -> 2016年 | E15: =E4 -> 2017年 | F15: =F4 -> 2018年 | G15: =G4 -> 2019年 | H15: =H4 -> 2020年 | I15: =I4 -> 2021年 | J15: =J4 -> 2022年
B16: 燃料及动力
B17: 占收入比 | C17: =IF(C6,C16/C6,"na") -> 0 | D17: =IF(D6,D16/D6,"na") -> 0 | E17: =IF(E6,E16/E6,"na") -> 0
B18: =B16 -> 燃料及动力 | C18: =C16 -> 0 | D18: =D16 -> 0 | E18: =E16 -> 0 | F18: =IF(F16,F16,F17*F6) -> 0 | G18: =IF(G16,G16,G17*G6) -> 0 | H18: =IF(H16,H16,H17*H6) -> 0 | I18: =IF(I16,I16,I17*I6) -> 0 | J18: =IF(J16,J16,J17*J6) -> 0
B19: 占收入比 | F19: =IF(F6,F18/F6,"na") -> 0 | G19: =IF(G6,G18/G6,"na") -> 0 | H19: =IF(H6,H18/H6,"na") -> 0 | I19: =IF(I6,I18/I6,"na") -> 0 | J19: =IF(J6,J18/J6,"na") -> 0
B21: 项目3 | C21: =C4 -> 2015年 | D21: =D4 -> 2016年 | E21: =E4 -> 2017年 | F21: =F4 -> 2018年 | G21: =G4 -> 2019年 | H21: =H4 -> 2020年 | I21: =I4 -> 2021年 | J21: =J4 -> 2022年
B22: 生产人员工资及附加
B23: 占收入比 | C23: =IF(C6,C22/C6,"na") -> 0 | D23: =IF(D6,D22/D6,"na") -> 0 | E23: =IF(E6,E22/E6,"na") -> 0
B24: =B22 -> 生产人员工资及附加 | C24: =C22 -> 0 | D24: =D22 -> 0 | E24: =E22 -> 0 | F24: =IF(F22,F22,F23*F6) -> 0 | G24: =IF(G22,G22,G23*G6) -> 0 | H24: =IF(H22,H22,H23*H6) -> 0 | I24: =IF(I22,I22,I23*I6) -> 0 | J24: =IF(J22,J22,J23*J6) -> 0
B25: 占收入比 | F25: =IF(F6,F24/F6,"na") -> 0 | G25: =IF(G6,G24/G6,"na") -> 0 | H25: =IF(H6,H24/H6,"na") -> 0 | I25: =IF(I6,I24/I6,"na") -> 0 | J25: =IF(J6,J24/J6,"na") -> 0
B27: 项目4 | C27: =C4 -> 2015年 | D27: =D4 -> 2016年 | E27: =E4 -> 2017年 | F27: =F4 -> 2018年 | G27: =G4 -> 2019年 | H27: =H4 -> 2020年 | I27: =I4 -> 2021年 | J27: =J4 -> 2022年
B28: 折旧（及摊销） | F28: ='7折旧'!F5 -> 538.7712 | G28: ='7折旧'!G5 -> 572.2992 | H28: ='7折旧'!H5 -> 299.2771 | I28: ='7折旧'!I5 -> 147.18807 | J28: ='7折旧'!J5 -> 156.86807
B29: 占收入比 | C29: =IF(C6,C28/C6,"na") -> 0 | D29: =IF(D6,D28/D6,"na") -> 0 | E29: =IF(E6,E28/E6,"na") -> 0 | F29: =IF(F6,F28/F6,"na") -> 0.045140315 | G29: =IF(G6,G28/G6,"na") -> 0.040469816 | H29: =IF(H6,H28/H6,"na") -> 0.018826982 | I29: =IF(I6,I28/I6,"na") -> 0.0087283993 | J29: =IF(J6,J28/J6,"na") -> 0.0091072898
B31: 项目5 | C31: =C4 -> 2015年 | D31: =D4 -> 2016年 | E31: =E4 -> 2017年 | F31: =F4 -> 2018年 | G31: =G4 -> 2019年 | H31: =H4 -> 2020年 | I31: =I4 -> 2021年 | J31: =J4 -> 2022年
B32: 其他
B33: 占收入比 | C33: =IF(C6,C32/C6,"na") -> 0 | D33: =IF(D6,D32/D6,"na") -> 0 | E33: =IF(E6,E32/E6,"na") -> 0
B34: =B32 -> 其他 | C34: =C32 -> 0 | D34: =D32 -> 0 | E34: =E32 -> 0 | F34: =IF(F32,F32,F33*F6) -> 0 | G34: =IF(G32,G32,G33*G6) -> 0 | H34: =IF(H32,H32,H33*H6) -> 0 | I34: =IF(I32,I32,I33*I6) -> 0 | J34: =IF(J32,J32,J33*J6) -> 0
B35: 占收入比 | F35: =IF(F6,F34/F6,"na") -> 0 | G35: =IF(G6,G34/G6,"na") -> 0 | H35: =IF(H6,H34/H6,"na") -> 0 | I35: =IF(I6,I34/I6,"na") -> 0 | J35: =IF(J6,J34/J6,"na") -> 0
B37: 项目（汇总） | C37: =C4 -> 2015年 | D37: =D4 -> 2016年 | E37: =E4 -> 2017年 | F37: =F4 -> 2018年 | G37: =G4 -> 2019年 | H37: =H4 -> 2020年 | I37: =I4 -> 2021年 | J37: =J4 -> 2022年
B38: 营业成本 | C38: =C12+C18+C24+C28+C34 -> 0 | D38: =D12+D18+D24+D28+D34 -> 0 | E38: =E12+E18+E24+E28+E34 -> 0 | F38: =F12+F18+F24+F28+F34 -> 538.7712 | G38: =G12+G18+G24+G28+G34 -> 572.2992 | H38: =H12+H18+H24+H28+H34 -> 299.2771 | I38: =I12+I18+I24+I28+I34 -> 147.18807 | J38: =J12+J18+J24+J28+J34 -> 156.86807
B39: 占收入比 | C39: =IF(C6,C38/C6,"na") -> 0 | D39: =IF(D6,D38/D6,"na") -> 0 | E39: =IF(E6,E38/E6,"na") -> 0 | F39: =IF(F6,F38/F6,"na") -> 0.045140315 | G39: =IF(G6,G38/G6,"na") -> 0.040469816 | H39: =IF(H6,H38/H6,"na") -> 0.018826982 | I39: =IF(I6,I38/I6,"na") -> 0.0087283993 | J39: =IF(J6,J38/J6,"na") -> 0.0091072898
B40: 毛利率 | C40: =IF(C6,1-C39,"na") -> 1 | D40: =IF(D6,1-D39,"na") -> 1 | E40: =IF(E6,1-E39,"na") -> 1 | F40: =IF(F6,1-F39,"na") -> 0.95485969 | G40: =IF(G6,1-G39,"na") -> 0.95953018 | H40: =IF(H6,1-H39,"na") -> 0.98117302 | I40: =IF(I6,1-I39,"na") -> 0.9912716 | J40: =IF(J6,1-J39,"na") -> 0.99089271
B42: 按产品/项目毛利率分析（方式二） | F42: 需具体分析毛利率变动原因，以及提高或降低措施，而不是仅仅列张汇总表（要有具体的纸质底稿支撑）
B43: 毛利率 | C43: =C4 -> 2015年 | D43: =D4 -> 2016年 | E43: =E4 -> 2017年 | F43: =F4 -> 2018年 | G43: =G4 -> 2019年 | H43: =H4 -> 2020年 | I43: =I4 -> 2021年 | J43: =J4 -> 2022年
B44: 产品a
B45: 产品b
B46: 产品c
...

Sheet 5税金
B1: 税金及附加预测表
B2: ='1报表'!B11 -> 评估基准日：2017/12/31
B3: ='1报表'!B12 -> 被评估单位：JSBD公司 | J3: 单位：万元
B4: 年度 | C4: ='3收入'!C4 -> 2015年 | D4: ='3收入'!D4 -> 2016年 | E4: ='3收入'!E4 -> 2017年 | F4: ='3收入'!F4 -> 2018年 | G4: ='3收入'!G4 -> 2019年 | H4: ='3收入'!H4 -> 2020年 | I4: ='3收入'!I4 -> 2021年 | J4: ='3收入'!J4 -> 2022年
B5: 数据汇总 | C5: ='1报表'!C99 -> 53.873421 | D5: ='1报表'!D99 -> 81.416231 | E5: ='1报表'!E99 -> 113.39456 | F5: =F32 -> 107.26836 | G5: =G32 -> 127.21454 | H5: =H32 -> 142.79594 | I5: =I32 -> 152.48181 | J5: =J32 -> 155.38377
B6: 营业收入 | C6: ='3收入'!C5 -> 5647.5609 | D6: ='3收入'!D5 -> 7304.7745 | E6: ='3收入'!E5 -> 9615.5763 | F6: ='3收入'!F5 -> 11935.477 | G6: ='3收入'!G5 -> 14141.384 | H6: ='3收入'!H5 -> 15896.18 | I6: ='3收入'!I5 -> 16863.123 | J6: ='3收入'!J5 -> 17224.451
B7: 占收入比 | C7: =IF(C6,C5/C6,"na") -> 0.0095392369 | D7: =IF(D6,D5/D6,"na") -> 0.011145619 | E7: =IF(E6,E5/E6,"na") -> 0.011792799 | F7: =IF(F6,F5/F6,"na") -> 0.0089873536 | G7: =IF(G6,G5/G6,"na") -> 0.0089959049 | H7: =IF(H6,H5/H6,"na") -> 0.0089830352 | I7: =IF(I6,I5/I6,"na") -> 0.0090423234 | J7: =IF(J6,J5/J6,"na") -> 0.0090211158
B8: 按收入占比分析（方式一） | E8: 实务中如果历史数据比较平稳，可采用下例简化处理。
C9: =C4 -> 2015年 | D9: =D4 -> 2016年 | E9: =E4 -> 2017年 | F9: =F4 -> 2018年 | G9: =G4 -> 2019年 | H9: =H4 -> 2020年 | I9: =I4 -> 2021年 | J9: =J4 -> 2022年
B10: 营业收入 | C10: =C6 -> 5647.5609 | D10: =D6 -> 7304.7745 | E10: =E6 -> 9615.5763 | F10: =F6 -> 11935.477 | G10: =G6 -> 14141.384 | H10: =H6 -> 15896.18 | I10: =I6 -> 16863.123 | J10: =J6 -> 17224.451
B11: 税金及附加 | C11: =C5 -> 53.873421 | D11: =D5 -> 81.416231 | E11: =E5 -> 113.39456
B12: 占收入比 | C12: =IF(C10,C11/C10,"na") -> 0.0095392369 | D12: =IF(D10,D11/D10,"na") -> 0.011145619 | E12: =IF(E10,E11/E10,"na") -> 0.011792799
B13: 税金及附加 | F13: =IF(F11,F11,F12*F10) -> 0 | G13: =IF(G11,G11,G12*G10) -> 0 | H13: =IF(H11,H11,H12*H10) -> 0 | I13: =IF(I11,I11,I12*I10) -> 0 | J13: =IF(J11,J11,J12*J10) -> 0
B14: 占收入比 | F14: =IF(F10,F13/F10,"na") -> 0 | G14: =IF(G10,G13/G10,"na") -> 0 | H14: =IF(H10,H13/H10,"na") -> 0 | I14: =IF(I10,I13/I10,"na") -> 0 | J14: =IF(J10,J13/J10,"na") -> 0
B16: 分项目进行分析（方式二） | D16: 实务中如果企业产品不单一，每种产品或服务适用的税率不同，以及金额较大，应分项目评估。示例如下
B17: 项目 | C17: =C4 -> 2015年 | D17: =D4 -> 2016年 | E17: =E4 -> 2017年 | F17: =F4 -> 2018年 | G17: =G4 -> 2019年 | H17: =H4 -> 2020年 | I17: =I4 -> 2021年 | J17: =J4 -> 2022年 | K17: 税率 | L17: 计税公式 | M17: 计税依据的主要内容
B18: 增值税销项 | K18: 0.16
B19: 增值税进项 | K19: 0.16 | M19: 注意资本性支出中设备的增值税要加上
B20: 应缴增值税 | C20: =C18-C19 -> 0 | D20: =D18-D19 -> 0 | E20: =E18-E19 -> 0 | F20: =F18-F19 -> 0 | G20: =G18-G19 -> 0 | H20: =H18-H19 -> 0 | I20: =I18-I19 -> 0 | J20: =J18-J19 -> 0 | L20: (1)-(2)
B21: 应缴营业税 | M21: 营改增后，该项无。
B22: 应缴流转税合计 | C22: =C20+C21 -> 0 | D22: =D20+D21 -> 0 | E22: =E20+E21 -> 0 | F22: =IF(F20+F21<0,0,F20+F21) -> 0 | G22: =IF(G20+G21<0,0,G20+G21) -> 0 | H22: =IF(H20+H21<0,0,H20+H21) -> 0 | I22: =IF(I20+I21<0,0,I20+I21) -> 0 | J22: =IF(J20+J21<0,0,J20+J21) -> 0 | L22: (3)+(4)
B23: 消费税
B24: 城市维护建设税 | C24: 29.6243 | D24: 36.90478 | E24: 51.920506 | F24: =F48*$K$24 -> 46.785574 | G24: =G48*$K$24 -> 58.112024 | H24: =H48*$K$24 -> 66.955502 | I24: =I48*$K$24 -> 72.470218 | J24: =J48*$K$24 -> 74.112442 | K24: 0.07 | L24: 应交流转税项
B25: 资源税
B26: 教育费附加 | C26: 21.160215 | D26: 26.360555 | E26: 37.086081 | F26: =F48*$K$26 -> 33.418267 | G26: =G48*$K$26 -> 41.508588 | H26: =H48*$K$26 -> 47.825358 | I26: =I48*$K$26 -> 51.764442 | J26: =J48*$K$26 -> 52.937458 | K26: 0.05 | L26: 应交流转税项
B27: 房产税 | D27: 10.499706 | E27: 13.999608 | F27: 16.41 | G27: =F27 -> 16.41 | H27: =G27 -> 16.41 | I27: =H27 -> 16.41 | J27: =I27 -> 16.41 | N27: （土地原值+房屋原值）*0.7*1.2%
B28: 土地使用税 | D28: 5.83875 | E28: 7.785 | F28: 7.79 | G28: =F28 -> 7.79 | H28: =G28 -> 7.79 | I28: =H28 -> 7.79 | J28: =I28 -> 7.79 | N28: 土地面积*6元/平方米
B29: 车船使用税
B30: 印花税 | C30: 0.00975 | D30: 1.81244 | E30: 2.603364 | F30: ='3收入'!F5*0.8*0.03% -> 2.8645146 | G30: ='3收入'!G5*0.8*0.03% -> 3.3939321 | H30: ='3收入'!H5*0.8*0.03% -> 3.8150832 | I30: ='3收入'!I5*0.8*0.03% -> 4.0471494 | J30: ='3收入'!J5*0.8*0.03% -> 4.1338683 | K30: 0.0003 | M30: 特殊行业要具实考虑 | N30: 销售收入*0.8*0.03%
B31: 其他 | C31: 3.079156
B32: 合计 | C32: =C21+SUM(C23:C31) -> 53.873421 | D32: =D21+SUM(D23:D31) -> 81.416231 | E32: =E21+SUM(E23:E31) -> 113.39456 | F32: =F21+SUM(F23:F31) -> 107.26836 | G32: =G21+SUM(G23:G31) -> 127.21454 | H32: =H21+SUM(H23:H31) -> 142.79594 | I32: =I21+SUM(I23:I31) -> 152.48181 | J32: =J21+SUM(J23:J31) -> 155.38377
B33: 占收入比 | F33: =IF(F6,F32/F6,"na") -> 0.0089873536 | G33: =IF(G6,G32/G6,"na") -> 0.0089959049 | H33: =IF(H6,H32/H6,"na") -> 0.0089830352 | I33: =IF(I6,I32/I6,"na") -> 0.0090423234 | J33: =IF(J6,J32/J6,"na") -> 0.0090211158
B35: 实务中如果企业产品不单一，每种产品或服务适用的增值税率不同，以及金额较大，应分项目评估。示例如下
B36: 增值税计算 | F36: =F4 -> 2018年 | G36: =G4 -> 2019年 | H36: =H4 -> 2020年 | I36: =I4 -> 2021年 | J36: =J4 -> 2022年
B37: 增值税销项税 | F37: =F6*0.9*(0.25*17%+0.75*16%) -> 1745.5636 | G37: =G6*0.9*16% -> 2036.3593 | H37: =H6*0.9*16% -> 2289.0499 | I37: =I6*0.9*16% -> 2428.2897 | J37: =J6*0.9*16% -> 2480.321
B39: 直接材料进项税 | F39: ='4成本'!F5*0.8*(0.25*17%+0.75*16%) -> 930.96723 | G39: ='4成本'!G5*0.8*16% -> 1086.0583 | H39: ='4成本'!H5*0.8*16% -> 1220.8266 | I39: ='4成本'!I5*0.8*16% -> 1295.0878 | J39: ='4成本'!J5*0.8*16% -> 1322.8378
B40: 运输费 | F40: ='6销管'!F15*(0.25*11%+0.75*10%) -> 24.467729 | G40: ='6销管'!G15*10% -> 28.282768 | H40: ='6销管'!H15*10% -> 31.79236 | I40: ='6销管'!I15*10% -> 33.726245 | J40: ='6销管'!J15*10% -> 34.448902
B41: 水电费 | F41: =('6销管'!F59+'6销管'!F65)*(0.25*17%+0.75*16%) -> 3.2971756 | G41: =('6销管'!G59+'6销管'!G65)*16% -> 3.8464564 | H41: =('6销管'!H59+'6销管'!H65)*16% -> 4.3237609 | I41: =('6销管'!I59+'6销管'!I65)*16% -> 4.5867694 | J41: =('6销管'!J59+'6销管'!J65)*16% -> 4.6850507
B42: 其他科目转入进项税 | F42: 24.56268
B43: 购买设备进项税 | F43: 91.536404 | G43: 88 | H43: 72 | I43: 56 | J43: 56
...

Sheet 6销管
B1: 销售费用、管理费用、研发费用预测表
B2: ='1报表'!B11 -> 评估基准日：2017/12/31
B3: ='1报表'!B12 -> 被评估单位：JSBD公司 | J3: 单位：万元
B4: 数据汇总 | C4: ='3收入'!C4 -> 2015年 | D4: ='3收入'!D4 -> 2016年 | E4: ='3收入'!E4 -> 2017年 | F4: ='3收入'!F4 -> 2018年 | G4: ='3收入'!G4 -> 2019年 | H4: ='3收入'!H4 -> 2020年 | I4: ='3收入'!I4 -> 2021年 | J4: ='3收入'!J4 -> 2022年
B5: 销售费用 | C5: ='1报表'!C100 -> 481.4591 | D5: ='1报表'!D100 -> 588.55087 | E5: ='1报表'!E100 -> 750.19684 | F5: =F41 -> 950.06399 | G5: =G41 -> 1125.6541 | H5: =H41 -> 1265.3359 | I5: =I41 -> 1342.3046 | J5: =J41 -> 1371.0663
B6: 管理费用 | C6: ='1报表'!C101 -> 694.30698 | D6: ='1报表'!D101 -> 710.43654 | E6: ='1报表'!E101 -> 1052.4467 | F6: =F121 -> 1140.1681 | G6: =G121 -> 1284.8847 | H6: =H121 -> 1341.4961 | I6: =I121 -> 1376.4758 | J6: =J121 -> 1432.4397
B7: 研发费用 | C7: ='1报表'!C102 -> 384.83578 | D7: ='1报表'!D102 -> 369.90657 | E7: ='1报表'!E102 -> 435.369 | F7: =F128 -> 596.77387 | G7: =G128 -> 707.06919 | H7: =H128 -> 794.809 | I7: =I128 -> 843.15614 | J7: =J128 -> 861.22256
B8: 销售、管理、研发费用 | C8: =SUM(C5:C7) -> 1560.6019 | D8: =SUM(D5:D7) -> 1668.894 | E8: =SUM(E5:E7) -> 2238.0126 | F8: =SUM(F5:F7) -> 2687.0059 | G8: =SUM(G5:G7) -> 3117.608 | H8: =SUM(H5:H7) -> 3401.641 | I8: =SUM(I5:I7) -> 3561.9365 | J8: =SUM(J5:J7) -> 3664.7286
B9: 营业收入 | C9: ='3收入'!C5 -> 5647.5609 | D9: ='3收入'!D5 -> 7304.7745 | E9: ='3收入'!E5 -> 9615.5763 | F9: ='3收入'!F5 -> 11935.477 | G9: ='3收入'!G5 -> 14141.384 | H9: ='3收入'!H5 -> 15896.18 | I9: ='3收入'!I5 -> 16863.123 | J9: ='3收入'!J5 -> 17224.451
B10: SGA/Sale | C10: =IF(C9,C8/C9,"na") -> 0.27633201 | D10: =IF(D9,D8/D9,"na") -> 0.22846619 | E10: =IF(E9,E8/E9,"na") -> 0.23274867 | F10: =IF(F9,F8/F9,"na") -> 0.22512765 | G10: =IF(G9,G8/G9,"na") -> 0.2204599 | H10: =IF(H9,H8/H9,"na") -> 0.2139911 | I10: =IF(I9,I8/I9,"na") -> 0.21122639 | J10: =IF(J9,J8/J9,"na") -> 0.21276316
B11: 销售费用分析（点行"+" 号展开） | E11: 科目内容只是示例，根据具体项目改动！ | I11: 金额大、变动大的科目要分析
B12: 销售费用 | C12: =C4 -> 2015年 | D12: =D4 -> 2016年 | E12: =E4 -> 2017年 | F12: =F4 -> 2018年 | G12: =G4 -> 2019年 | H12: =H4 -> 2020年 | I12: =I4 -> 2021年 | J12: =J4 -> 2022年
B13: 差旅费 | C13: 82.784085 | D13: 54.068012 | E13: 73.787718 | F13: =F9*$H$27 -> 89.51608 | G13: =G9*$H$27 -> 106.06038 | H13: =H9*$H$27 -> 119.22135 | I13: =I9*$H$27 -> 126.47342 | J13: =J9*$H$27 -> 129.18338
B14: 招待费 | C14: 29.756603 | D14: 39.310676 | E14: 60.444225 | F14: =F9*$H$28 -> 66.838673 | G14: =G9*$H$28 -> 79.191749 | H14: =H9*$H$28 -> 89.018608 | I14: =I9*$H$28 -> 94.433487 | J14: =J9*$H$28 -> 96.456927
B15: 运输费 | C15: 97.206981 | D15: 162.27442 | E15: 196.42828 | F15: =F9*$H$29 -> 238.70955 | G15: =G9*$H$29 -> 282.82768 | H15: =H9*$H$29 -> 317.9236 | I15: =I9*$H$29 -> 337.26245 | J15: =J9*$H$29 -> 344.48902
B16: 广告/宣传费 | C16: 77.886603 | D16: 78.650505 | E16: 82.714493 | F16: =F9*$H$30 -> 132.4838 | G16: =G9*$H$30 -> 156.96936 | H16: =H9*$H$30 -> 176.4476 | I16: =I9*$H$30 -> 187.18066 | J16: =J9*$H$30 -> 191.19141
B17: 商检/报关费 | C17: 55.205293 | D17: 26.047723 | E17: 20.436228 | F17: =F9*$H$31 -> 25.064502 | G17: =G9*$H$31 -> 29.696906 | H17: =H9*$H$31 -> 33.381978 | I17: =I9*$H$31 -> 35.412558 | J17: =J9*$H$31 -> 36.171347
B18: 检定费/检测费 | C18: 28.890597 | D18: 46.584152 | E18: 97.208652 | F18: =F9*$H$32 -> 119.35477 | G18: =G9*$H$32 -> 141.41384 | H18: =H9*$H$32 -> 158.9618 | I18: =I9*$H$32 -> 168.63123 | J18: =J9*$H$32 -> 172.24451
B19: 工资 | C19: 86.94148 | D19: 159.93703 | E19: 191.96455 | F19: =F9*$H$33 -> 238.70955 | G19: =G9*$H$33 -> 282.82768 | H19: =H9*$H$33 -> 317.9236 | I19: =I9*$H$33 -> 337.26245 | J19: =J9*$H$33 -> 344.48902
B20: 社保费 | C20: 16.949916 | D20: 13.427223 | E20: 14.380442 | F20: =F9*$H$34 -> 25.064502 | G20: =G9*$H$34 -> 29.696906 | H20: =H9*$H$34 -> 33.381978 | I20: =I9*$H$34 -> 35.412558 | J20: =J9*$H$34 -> 36.171347
B21: 其他 | C21: 5.837541 | D21: 8.25112 | E21: 12.832256 | F21: =F9*$H$35 -> 14.322573 | G21: =G9*$H$35 -> 16.969661 | H21: =H9*$H$35 -> 19.075416 | I21: =I9*$H$35 -> 20.235747 | J21: =J9*$H$35 -> 20.669341
B23: 合计 | C23: =SUM(C13:C22) -> 481.4591 | D23: =SUM(D13:D22) -> 588.55087 | E23: =SUM(E13:E22) -> 750.19684 | F23: =SUM(F13:F22) -> 950.06399 | G23: =SUM(G13:G22) -> 1125.6541 | H23: =SUM(H13:H22) -> 1265.3359 | I23: =SUM(I13:I22) -> 1342.3046 | J23: =SUM(J13:J22) -> 1371.0663
B24: 检查核对 | C24: =C23-C5 -> 0 | D24: =D23-D5 -> 0 | E24: =E23-E5 -> 0
B25: 与报表一致? | C25: =IF(ROUND(C24,0)=0,"OK","需要检查") -> OK | D25: =IF(ROUND(D24,0)=0,"OK","需要检查") -> OK | E25: =IF(ROUND(E24,0)=0,"OK","需要检查") -> OK
B26: 占收入比例 | E26: =C12&"-"&E12 -> 2015年-2017年 | F26: 相关系数 | G26: 平均值 | H26: 评估取值
B27: =B13 -> 差旅费 | C27: =IF(C13,C13/C$9,"") -> 0.014658379 | D27: =IF(D13,D13/D$9,"") -> 0.0074017359 | E27: =IF(E13,E13/E$9,"") -> 0.0076737697 | F27: =IF(COUNT(C27:E27)>2,CORREL(C$9:E$9,C13:E13),"") -> -0.21475276 | G27: =AVERAGE(C27:E27) -> 0.0099112947 | H27: 0.0075
B28: =B14 -> 招待费 | C28: =IF(C14,C14/C$9,"") -> 0.00526893 | D28: =IF(D14,D14/D$9,"") -> 0.0053815044 | E28: =IF(E14,E14/E$9,"") -> 0.0062860741 | F28: =IF(COUNT(C28:E28)>2,CORREL(C$9:E$9,C14:E14),"") -> 0.99284575 | G28: =AVERAGE(C28:E28) -> 0.0056455028 | H28: 0.0056
B29: =B15 -> 运输费 | C29: =IF(C15,C15/C$9,"") -> 0.017212206 | D29: =IF(D15,D15/D$9,"") -> 0.022214843 | E29: =IF(E15,E15/E$9,"") -> 0.020428134 | F29: =IF(COUNT(C29:E29)>2,CORREL(C$9:E$9,C15:E15),"") -> 0.96302306 | G29: =AVERAGE(C29:E29) -> 0.019951728 | H29: 0.02
B30: =B16 -> 广告/宣传费 | C30: =IF(C16,C16/C$9,"") -> 0.013791193 | D30: =IF(D16,D16/D$9,"") -> 0.010767 | E30: =IF(E16,E16/E$9,"") -> 0.0086021358 | F30: =IF(COUNT(C30:E30)>2,CORREL(C$9:E$9,C16:E16),"") -> 0.96075935 | G30: =AVERAGE(C30:E30) -> 0.011053443 | H30: 0.0111
B31: =B17 -> 商检/报关费 | C31: =IF(C17,C17/C$9,"") -> 0.0097750683 | D31: =IF(D17,D17/D$9,"") -> 0.003565849 | E31: =IF(E17,E17/E$9,"") -> 0.0021253253 | F31: =IF(COUNT(C31:E31)>2,CORREL(C$9:E$9,C17:E17),"") -> -0.89268551 | G31: =AVERAGE(C31:E31) -> 0.0051554142 | H31: 0.0021
B32: =B18 -> 检定费/检测费 | C32: =IF(C18,C18/C$9,"") -> 0.0051155884 | D32: =IF(D18,D18/D$9,"") -> 0.0063772197 | E32: =IF(E18,E18/E$9,"") -> 0.010109498 | F32: =IF(COUNT(C32:E32)>2,CORREL(C$9:E$9,C18:E18),"") -> 0.98444391 | G32: =AVERAGE(C32:E32) -> 0.0072007688 | H32: 0.01
B33: =B19 -> 工资 | C33: =IF(C19,C19/C$9,"") -> 0.015394518 | D33: =IF(D19,D19/D$9,"") -> 0.021894862 | E33: =IF(E19,E19/E$9,"") -> 0.019963915 | F33: =IF(COUNT(C33:E33)>2,CORREL(C$9:E$9,C19:E19),"") -> 0.95038258 | G33: =AVERAGE(C33:E33) -> 0.019084432 | H33: 0.02
B34: =B20 -> 社保费 | C34: =IF(C20,C20/C$9,"") -> 0.0030012808 | D34: =IF(D20,D20/D$9,"") -> 0.0018381434 | E34: =IF(E20,E20/E$9,"") -> 0.0014955361 | F34: =IF(COUNT(C34:E34)>2,CORREL(C$9:E$9,C20:E20),"") -> -0.63478805 | G34: =AVERAGE(C34:E34) -> 0.0021116534 | H34: 0.0021
B35: =B21 -> 其他 | C35: =IF(C21,C21/C$9,"") -> 0.0010336393 | D35: =IF(D21,D21/D$9,"") -> 0.0011295516 | E35: =IF(E21,E21/E$9,"") -> 0.001334528 | F35: =IF(COUNT(C35:E35)>2,CORREL(C$9:E$9,C21:E21),"") -> 0.99662131 | G35: =AVERAGE(C35:E35) -> 0.0011659063 | H35: 0.0012
B37: 销售费用分析
B38: 项目 | C38: =C4 -> 2015年 | D38: =D4 -> 2016年 | E38: =E4 -> 2017年 | F38: =F4 -> 2018年 | G38: =G4 -> 2019年 | H38: =H4 -> 2020年 | I38: =I4 -> 2021年 | J38: =J4 -> 2022年
B39: 销售费用 | C39: =C23 -> 481.4591 | D39: =D23 -> 588.55087 | E39: =E23 -> 750.19684 | F39: =F23 -> 950.06399 | G39: =G23 -> 1125.6541 | H39: =H23 -> 1265.3359 | I39: =I23 -> 1342.3046 | J39: =J23 -> 1371.0663
B40: 占收入比 | C40: =IF(C9,C39/C9,"na") -> 0.085250803 | D40: =IF(D9,D39/D9,"na") -> 0.080570709 | E40: =IF(E9,E39/E9,"na") -> 0.078018916
B41: 销售费用 | F41: =IF(F39,F39,F40*F9) -> 950.06399 | G41: =IF(G39,G39,G40*G9) -> 1125.6541 | H41: =IF(H39,H39,H40*H9) -> 1265.3359 | I41: =IF(I39,I39,I40*I9) -> 1342.3046 | J41: =IF(J39,J39,J40*J9) -> 1371.0663
B42: 占收入比 | F42: =IF(F9,F41/F9,"na") -> 0.0796 | G42: =IF(G9,G41/G9,"na") -> 0.0796 | H42: =IF(H9,H41/H9,"na") -> 0.0796 | I42: =IF(I9,I41/I9,"na") -> 0.0796 | J42: =IF(J9,J41/J9,"na") -> 0.0796
...

Sheet 7折旧
B1: 固定资产支出与折旧预测表
B2: ='1报表'!B11 -> 评估基准日：2017/12/31 | K2: 该工作表已保护！
B3: ='1报表'!B12 -> 被评估单位：JSBD公司 | J3: 单位：万元
B4: 项目 | C4: 评估取值 | D4: =E4&"占比" -> 2017年占比 | E4: ='3收入'!E4 -> 2017年 | F4: ='3收入'!F4 -> 2018年 | G4: ='3收入'!G4 -> 2019年 | H4: ='3收入'!H4 -> 2020年 | I4: ='3收入'!I4 -> 2021年 | J4: ='3收入'!J4 -> 2022年
B5: 生产成本中的折旧 | C5: 0.88 | D5: =IF(E5,E5/E$9,"") -> 0.87156503 | E5: 505.19395 | F5: =$C5*F$9 -> 538.7712 | G5: =$C5*G$9 -> 572.2992 | H5: =$C5*H$9 -> 299.2771 | I5: =$C5*I$9 -> 147.18807 | J5: =$C5*J$9 -> 156.86807
B6: 销售费用中的折旧 | D6: =IF(E6,E6/E$9,"") | F6: =$C6*F$9 -> 0 | G6: =$C6*G$9 -> 0 | H6: =$C6*H$9 -> 0 | I6: =$C6*I$9 -> 0 | J6: =$C6*J$9 -> 0
B7: 管理费用中的折旧 | C7: 0.12 | D7: =IF(E7,E7/E$9,"") -> 0.12843497 | E7: 74.446046 | F7: =$C7*F$9 -> 73.4688 | G7: =$C7*G$9 -> 78.0408 | H7: =$C7*H$9 -> 40.810513 | I7: =$C7*I$9 -> 20.0711 | J7: =$C7*J$9 -> 21.3911
B8: 研发费用中的折旧 | D8: =IF(E8,E8/E$9,"") | F8: =$C8*F$9 -> 0 | G8: =$C8*G$9 -> 0 | H8: =$C8*H$9 -> 0 | I8: =$C8*I$9 -> 0 | J8: =$C8*J$9 -> 0
B9: 固定资产折旧额 | C9: =SUM(C5:C8) -> 1 | D9: =SUM(D5:D8) -> 1 | E9: =SUM(E5:E8) -> 579.64 | F9: =F28+F43 -> 612.24 | G9: =G28+G43 -> 650.34 | H9: =H28+H43 -> 340.08761 | I9: =I28+I43 -> 167.25917 | J9: =J28+J43 -> 178.25917
B10: 固定资产支出 | F10: =F26+SUM(F37:F39) -> 232 | G10: =G26+SUM(G37:G39) -> 50 | H10: =H26+SUM(H37:H39) -> 50 | I10: =I26+SUM(I37:I39) -> 50 | J10: =J26+SUM(J37:J39) -> 50
B11: 未转固资产的处理
B12: 科目 | C12: 折旧率 | D12: 折旧年限 | E12: =E4 -> 2017年 | F12: =F4 -> 2018年 | G12: =G4 -> 2019年 | H12: =H4 -> 2020年 | I12: =I4 -> 2021年 | J12: =J4 -> 2022年
B13: 未转固建筑物的账面值
B14: 年度转固金额
B15: 未转固设备的账面值 | E15: =201.28+153.52 -> 354.8
B16: 年度转固金额-机器 | F16: =E15 -> 354.8
B17: 年度转固金额-车辆
B18: 年度转固金额-电子设备
B20: 房屋建筑物
B21: 项目 | C21: 折旧率 | D21: 折旧年限 | E21: ='3收入'!E4 -> 2017年 | F21: ='3收入'!F4 -> 2018年 | G21: ='3收入'!G4 -> 2019年 | H21: ='3收入'!H4 -> 2020年 | I21: ='3收入'!I4 -> 2021年 | J21: ='3收入'!J4 -> 2022年
B22: 基准日已提足折旧建筑类账面原值 | E22: 0
B23: 基准日未提足折旧建筑类账面原值 | E23: 1569.6667
B24: 基准日建筑类账面净值 | E24: 1134.7382
B25: 存量建筑类折旧额 | C25: 0.0475 | F25: =IF(E24>E23*C25,E23*C25,E24) -> 74.559169 | G25: =IF(($E24-SUM($F25:F25))>$F25,$F25,$E24-SUM($F25:F25)) -> 74.559169 | H25: =IF(($E24-SUM($F25:G25))>$F25,$F25,$E24-SUM($F25:G25)) -> 74.559169 | I25: =IF(($E24-SUM($F25:H25))>$F25,$F25,$E24-SUM($F25:H25)) -> 74.559169 | J25: =IF(($E24-SUM($F25:I25))>$F25,$F25,$E24-SUM($F25:I25)) -> 74.559169
B26: 新增建筑物投入原值
B27: 新增建筑类折旧额 | F27: =IF($D13,SUM($F14:F14)/$D13,0)+IF($D27,SUM($F26:F26)/$D27,0) -> 0 | G27: =IF($D13,SUM($F14:G14)/$D13,0)+IF($D27,SUM($F26:G26)/$D27,0) -> 0 | H27: =IF($D13,SUM($F14:H14)/$D13,0)+IF($D27,SUM($F26:H26)/$D27,0) -> 0 | I27: =IF($D13,SUM($F14:I14)/$D13,0)+IF($D27,SUM($F26:I26)/$D27,0) -> 0 | J27: =IF($D13,SUM($F14:J14)/$D13,0)+IF($D27,SUM($F26:J26)/$D27,0) -> 0
B28: 建筑类折旧额小计 | F28: =F25+F27 -> 74.559169 | G28: =G25+G27 -> 74.559169 | H28: =H25+H27 -> 74.559169 | I28: =I25+I27 -> 74.559169 | J28: =J25+J27 -> 74.559169
B29: 期末建筑物类账面净值 | F29: =E24+F14+F26-F28 -> 1060.1791 | G29: =F29+G14+G26-G28 -> 985.61989 | H29: =G29+H14+H26-H28 -> 911.06072 | I29: =H29+I14+I26-I28 -> 836.50156 | J29: =I29+J14+J26-J28 -> 761.94239
B31: 设备
B32: 项目 | C32: 折旧率 | D32: 折旧年限 | E32: =E21 -> 2017年 | F32: =F21 -> 2018年 | G32: =G21 -> 2019年 | H32: =H21 -> 2020年 | I32: =I21 -> 2021年 | J32: =J21 -> 2022年
B33: 基准日已提足折旧设备类账面原值 | E33: 0
B34: 基准日未提足折旧设备类账面原值 | E34: 3572.8487
B35: 基准日设备类账面净值 | E35: 1193.9901
B36: 存量设备类折旧额 | C36: 0.14136642 | F36: =IF(E35>E34*C36,E34*C36,E35) -> 505.08083 | G36: =IF(($E35-SUM($F36:F36))>$F36,$F36,$E35-SUM($F36:F36)) -> 505.08083 | H36: =IF(($E35-SUM($F36:G36))>$F36,$F36,$E35-SUM($F36:G36)) -> 183.82844 | I36: =IF(($E35-SUM($F36:H36))>$F36,$F36,$E35-SUM($F36:H36)) -> 0 | J36: =IF(($E35-SUM($F36:I36))>$F36,$F36,$E35-SUM($F36:I36)) -> 0
B37: 新增机器投入原值 | D37: 9 | F37: =232 -> 232
B38: 新增车辆投入原值 | D38: 4 | G38: 20 | H38: 20 | I38: 20 | J38: 20
B39: 新增电子设备投入原值 | D39: 5 | G39: 30 | H39: 30 | I39: 30 | J39: 30
B40: 新增机器折旧额 | F40: =F55 -> 32.6 | G40: =G55 -> 65.2 | H40: =H55 -> 65.2 | I40: =I55 -> 65.2 | J40: =J55 -> 65.2
B41: 新增车辆折旧额 | F41: =F63 -> 0 | G41: =G63 -> 2.5 | H41: =H63 -> 7.5 | I41: =I63 -> 12.5 | J41: =J63 -> 17.5
B42: 新增电子设备折旧额 | F42: =F71 -> 0 | G42: =G71 -> 3 | H42: =H71 -> 9 | I42: =I71 -> 15 | J42: =J71 -> 21
...

Sheet 8摊销
B1: 长摊和无形资产支出与摊销预测表
B2: ='1报表'!B11 -> 评估基准日：2017/12/31 | L2: 该工作表已保护！
B3: ='1报表'!B12 -> 被评估单位：JSBD公司 | J3: 单位：万元
B4: 数据汇总 | E4: ='3收入'!E4 -> 2017年 | F4: ='3收入'!F4 -> 2018年 | G4: ='3收入'!G4 -> 2019年 | H4: ='3收入'!H4 -> 2020年 | I4: ='3收入'!I4 -> 2021年 | J4: ='3收入'!J4 -> 2022年
B5: 长期待摊费用摊销 | F5: =F51 -> 0 | G5: =G51 -> 0 | H5: =H51 -> 0 | I5: =I51 -> 0 | J5: =J51 -> 0
B6: 无形资产摊销 | F6: =F25+F34 -> 71.838051 | G6: =G25+G34 -> 71.838051 | H6: =H25+H34 -> 51.201763 | I6: =I25+I34 -> 37.678504 | J6: =J25+J34 -> 57.678504
B7: 摊销合计 | F7: =F5+F6 -> 71.838051 | G7: =G5+G6 -> 71.838051 | H7: =H5+H6 -> 51.201763 | I7: =I5+I6 -> 37.678504 | J7: =J5+J6 -> 57.678504
B8: 长摊资产支出 | F8: =F49 -> 0 | G8: =G49 -> 0 | H8: =H49 -> 0 | I8: =I49 -> 0 | J8: =J49 -> 0
B9: 无形资产支出 | F9: =F23+F32 -> 0 | G9: =G23+G32 -> 0 | H9: =H23+H32 -> 60 | I9: =I23+I32 -> 60 | J9: =J23+J32 -> 60
B10: 长摊和无形资产支出 | F10: =F8+F9 -> 0 | G10: =G8+G9 -> 0 | H10: =H8+H9 -> 60 | I10: =I8+I9 -> 60 | J10: =J8+J9 -> 60
B11: 未资本化无形资产的处理
B12: 科目 | D12: 摊销年限 | E12: =E4 -> 2017年 | F12: =F4 -> 2018年 | G12: =G4 -> 2019年 | H12: =H4 -> 2020年 | I12: =I4 -> 2021年 | J12: =J4 -> 2022年
B13: 未资本化的土地
B14: 年度资本化金额
B15: 未资本化的无形资产 | E15: ='2报表调整'!G37 -> 0
B16: 年度资本化金额
B18: 土地使用权
B19: 项目 | D19: 摊销年限 | E19: =E4 -> 2017年 | F19: =F4 -> 2018年 | G19: =G4 -> 2019年 | H19: =H4 -> 2020年 | I19: =I4 -> 2021年 | J19: =J4 -> 2022年
B20: 基准日土地账面原值 | E20: 383.9252
B21: 基准日土地账面净值 | E21: 297.7661
B22: 存量土地摊销额 | D22: 50 | F22: =IF(D22,IF(E21>E20/D22,E20/D22,E21),0) -> 7.678504 | G22: =IF(($E21-SUM($F22:F22))>$F22,$F22,$E21-SUM($F22:F22)) -> 7.678504 | H22: =IF(($E21-SUM($F22:G22))>$F22,$F22,$E21-SUM($F22:G22)) -> 7.678504 | I22: =IF(($E21-SUM($F22:H22))>$F22,$F22,$E21-SUM($F22:H22)) -> 7.678504 | J22: =IF(($E21-SUM($F22:I22))>$F22,$F22,$E21-SUM($F22:I22)) -> 7.678504
B23: 新增土地投入原值
B24: 新增土地摊销额 | F24: =IF($D13,SUM($F14:F14)/$D13,0)+IF($D24,SUM($F23:F23)/$D24,0) -> 0 | G24: =IF($D13,SUM($F14:G14)/$D13,0)+IF($D24,SUM($F23:G23)/$D24,0) -> 0 | H24: =IF($D13,SUM($F14:H14)/$D13,0)+IF($D24,SUM($F23:H23)/$D24,0) -> 0 | I24: =IF($D13,SUM($F14:I14)/$D13,0)+IF($D24,SUM($F23:I23)/$D24,0) -> 0 | J24: =IF($D13,SUM($F14:J14)/$D13,0)+IF($D24,SUM($F23:J23)/$D24,0) -> 0
B25: 土地摊销额小计 | F25: =F22+F24 -> 7.678504 | G25: =G22+G24 -> 7.678504 | H25: =H22+H24 -> 7.678504 | I25: =I22+I24 -> 7.678504 | J25: =J22+J24 -> 7.678504
B26: 土地使用权账面净值 | F26: =E21+F14+F23-F25 -> 290.0876 | G26: =F26+G14+G23-G25 -> 282.40909 | H26: =G26+H14+H23-H25 -> 274.73059 | I26: =H26+I14+I23-I25 -> 267.05208 | J26: =I26+J14+J23-J25 -> 259.37358
B27: 其他无形资产
B28: 项目 | D28: 摊销年限 | E28: =E19 -> 2017年 | F28: =F19 -> 2018年 | G28: =G19 -> 2019年 | H28: =H19 -> 2020年 | I28: =I19 -> 2021年 | J28: =J19 -> 2022年
B29: 基准日其他无形资产账面原值 | E29: 192.47864
B30: 基准日其他无形资产账面净值 | E30: 161.84235
B31: 存量其他无形资产摊销额 | D31: 3 | F31: =IF(D31,IF(E30>E29/D31,E29/D31,E30),0) -> 64.159547 | G31: =IF(($E30-SUM($F31:F31))>$F31,$F31,$E30-SUM($F31:F31)) -> 64.159547 | H31: =IF(($E30-SUM($F31:G31))>$F31,$F31,$E30-SUM($F31:G31)) -> 33.523259 | I31: =IF(($E30-SUM($F31:H31))>$F31,$F31,$E30-SUM($F31:H31)) -> 0 | J31: =IF(($E30-SUM($F31:I31))>$F31,$F31,$E30-SUM($F31:I31)) -> 0
B32: 新增技术类无形资产投入原值 | D32: 3 | H32: 60 | I32: 60 | J32: 60
B33: 新增无形资产摊销额 | F33: =F43 -> 0 | G33: =G43 -> 0 | H33: =H43 -> 10 | I33: =I43 -> 30 | J33: =J43 -> 50
B34: 无形资产摊销额小计 | F34: =F31+F33 -> 64.159547 | G34: =G31+G33 -> 64.159547 | H34: =H31+H33 -> 43.523259 | I34: =I31+I33 -> 30 | J34: =J31+J33 -> 50
B35: 其他无形资产账面净值 | F35: =E30+F16+F32-F34 -> 97.682807 | G35: =F35+G16+G32-G34 -> 33.523259 | H35: =G35+H16+H32-H34 -> 50 | I35: =H35+I16+I32-I34 -> 80 | J35: =I35+J16+J32-J34 -> 90
B37: 年度 | C37: 技术无形资产摊销额自动计算过程 | F37: =F19 -> 2018年 | G37: =G19 -> 2019年 | H37: =H19 -> 2020年 | I37: =I19 -> 2021年 | J37: =J19 -> 2022年
B38: =F37 -> 2018年 | F38: =IF(D32,(F16+F32)/D32/2,0) -> 0 | G38: =IF(D32,(F16+F32)/D32,0) -> 0 | H38: =IF(($F16+$F32-SUM($F38:G38))>$G38,$G38,$F16+$F32-SUM($F38:G38)) -> 0 | I38: =IF(($F16+$F32-SUM($F38:H38))>$G38,$G38,$F16+$F32-SUM($F38:H38)) -> 0 | J38: =IF(($F16+$F32-SUM($F38:I38))>$G38,$G38,$F16+$F32-SUM($F38:I38)) -> 0
B39: =G37 -> 2019年 | G39: =IF(D32,(G16+G32)/D32/2,0) -> 0 | H39: =IF(D32,(G16+G32)/D32,0) -> 0 | I39: =IF(($G16+$G32-SUM($G39:H39))>$H39,$H39,$G16+$G32-SUM($G39:H39)) -> 0 | J39: =IF(($G16+$G32-SUM($G39:I39))>$H39,$H39,$G16+$G32-SUM($G39:I39)) -> 0
B40: =H37 -> 2020年 | H40: =IF(D32,(H16+H32)/D32/2,0) -> 10 | I40: =IF(D32,(H16+H32)/D32,0) -> 20 | J40: =IF(($H16+$H32-SUM($H40:I40))>$I40,$I40,$H16+$H32-SUM($H40:I40)) -> 20
B41: =I37 -> 2021年 | I41: =IF(D32,(I16+I32)/D32/2,0) -> 10 | J41: =IF(D32,(I16+I32)/D32,0) -> 20
B42: =J37 -> 2022年 | J42: =IF(D32,(J16+J32)/D32/2,0) -> 10
...

Sheet 9溢余现金
B1: 经营最低保有现金分析表
B2: ='1报表'!B11 -> 评估基准日：2017/12/31
B3: ='1报表'!B12 -> 被评估单位：JSBD公司 | J3: 单位：万元
B4: 项目 | C4: ='3收入'!C4 -> 2015年 | D4: ='3收入'!D4 -> 2016年 | E4: ='3收入'!E4 -> 2017年 | F4: ='3收入'!F4 -> 2018年 | G4: ='3收入'!G4 -> 2019年 | H4: ='3收入'!H4 -> 2020年 | I4: ='3收入'!I4 -> 2021年 | J4: ='3收入'!J4 -> 2022年
B5: 生产成本的人工费用 | C5: 310.03546 | D5: 415.56892 | E5: 517.74326 | F5: 614.54 | G5: 676.29 | H5: 710.1 | I5: 745.61 | J5: 782.89
B6: 营业税金及附加 | C6: ='5税金'!C5 -> 53.873421 | D6: ='5税金'!D5 -> 81.416231 | E6: ='5税金'!E5 -> 113.39456 | F6: ='5税金'!F5 -> 107.26836 | G6: ='5税金'!G5 -> 127.21454 | H6: ='5税金'!H5 -> 142.79594 | I6: ='5税金'!I5 -> 152.48181 | J6: ='5税金'!J5 -> 155.38377
B7: 销售费用 | C7: ='6销管'!C5 -> 481.4591 | D7: ='6销管'!D5 -> 588.55087 | E7: ='6销管'!E5 -> 750.19684 | F7: ='6销管'!F5 -> 950.06399 | G7: ='6销管'!G5 -> 1125.6541 | H7: ='6销管'!H5 -> 1265.3359 | I7: ='6销管'!I5 -> 1342.3046 | J7: ='6销管'!J5 -> 1371.0663
B8: 管理费用 | C8: ='6销管'!C6 -> 694.30698 | D8: ='6销管'!D6 -> 710.43654 | E8: ='6销管'!E6 -> 1052.4467 | F8: ='6销管'!F6 -> 1140.1681 | G8: ='6销管'!G6 -> 1284.8847 | H8: ='6销管'!H6 -> 1341.4961 | I8: ='6销管'!I6 -> 1376.4758 | J8: ='6销管'!J6 -> 1432.4397
B9: 研发费用 | C9: ='6销管'!C7 -> 384.83578 | D9: ='6销管'!D7 -> 369.90657 | E9: ='6销管'!E7 -> 435.369 | F9: ='6销管'!F7 -> 596.77387 | G9: ='6销管'!G7 -> 707.06919 | H9: ='6销管'!H7 -> 794.809 | I9: ='6销管'!I7 -> 843.15614 | J9: ='6销管'!J7 -> 861.22256
B10: 财务费用中的利息支出 | C10: ='11财务费用'!C18 -> 144.02572 | D10: ='11财务费用'!D18 -> 132.21571 | E10: ='11财务费用'!E18 -> 92.333057 | F10: ='11财务费用'!F18 -> 54.1 | G10: ='11财务费用'!G18 -> 71.178944 | H10: ='11财务费用'!H18 -> 54.1 | I10: ='11财务费用'!I18 -> 54.1 | J10: ='11财务费用'!J18 -> 54.1
B11: 减：销售费用中折旧与摊销
B12: 减：管理费用中折旧与摊销 | C12: ='6销管'!C52+'6销管'!C53 -> 115.90069 | D12: ='6销管'!D52+'6销管'!D53 -> 89.179264 | E12: ='6销管'!E52+'6销管'!E53 -> 89.146854 | F12: ='6销管'!F52+'6销管'!F53 -> 145.30685 | G12: ='6销管'!G52+'6销管'!G53 -> 149.87885 | H12: ='6销管'!H52+'6销管'!H53 -> 92.012276 | I12: ='6销管'!I52+'6销管'!I53 -> 57.749604 | J12: ='6销管'!J52+'6销管'!J53 -> 79.069604
B13: 减：研发费用中折旧与摊销
B14: 估计的付现成本合计 | C14: =SUM(C5:C10)-SUM(C11:C13) -> 1952.6358 | D14: =SUM(D5:D10)-SUM(D11:D13) -> 2208.9156 | E14: =SUM(E5:E10)-SUM(E11:E13) -> 2872.3366 | F14: =SUM(F5:F10)-SUM(F11:F13) -> 3317.6075 | G14: =SUM(G5:G10)-SUM(G11:G13) -> 3842.4126 | H14: =SUM(H5:H10)-SUM(H11:H13) -> 4216.6247 | I14: =SUM(I5:I10)-SUM(I11:I13) -> 4456.3787 | J14: =SUM(J5:J10)-SUM(J11:J13) -> 4578.0328
B15: 月数 | C15: 12 | D15: 12 | E15: 12 | F15: 12 | G15: 12 | H15: 12 | I15: 12 | J15: 12
B16: 月均付现成本 | C16: =C14/C15 -> 162.71965 | D16: =D14/D15 -> 184.0763 | E16: =E14/E15 -> 239.36138 | F16: =F14/F15 -> 276.46729 | G16: =G14/G15 -> 320.20105 | H16: =H14/H15 -> 351.38539 | I16: =I14/I15 -> 371.36489 | J16: =J14/J15 -> 381.50273
B17: 保有现金系数(月） | C17: =D17 -> 1 | D17: =E17 -> 1 | E17: 1 | F17: =E17 -> 1 | G17: =F17 -> 1 | H17: =G17 -> 1 | I17: =H17 -> 1 | J17: =I17 -> 1 | K17: 一般取1，取其他数据应结合行业特点说明
B18: 限制用途现金
B19: 经营最低保有现金测算 | C19: =MIN(C16*C17,C23)+C18 -> 162.71965 | D19: =MIN(D16*D17,D23)+D18 -> 184.0763 | E19: =MIN(E16*E17,E23)+E18 -> 239.36138 | F19: =F16*F17+F18 -> 276.46729 | G19: =G16*G17+G18 -> 320.20105 | H19: =H16*H17+H18 -> 351.38539 | I19: =I16*I17+I18 -> 371.36489 | J19: =J16*J17+J18 -> 381.50273
B20: 经营必备现金/收入（检查） | C20: =C19/'3收入'!C5 -> 0.028812376 | D20: =D19/'3收入'!D5 -> 0.02519945 | E20: =E19/'3收入'!E5 -> 0.024893087 | F20: =F19/'3收入'!F5 -> 0.023163488 | G20: =G19/'3收入'!G5 -> 0.022642837 | H20: =H19/'3收入'!H5 -> 0.022105021 | I20: =I19/'3收入'!I5 -> 0.022022309 | J20: =J19/'3收入'!J5 -> 0.022148905
B21: 评估基准日溢余现金分析表
B22: 项目 | E22: =E4 -> 2017年
B23: 资产负债表中的货币资金 | E23: ='2报表调整'!D8 -> 276.81451
B24: 其中：经营最低保有现金 | E24: =E19 -> 239.36138
B25: 溢余现金 | E25: =MAX(E23-E24,0) -> 37.453128

Sheet 10营运
B1: 营运资金预测表
B2: ='1报表'!B11 -> 评估基准日：2017/12/31
B3: ='1报表'!B12 -> 被评估单位：JSBD公司 | J3: 单位：万元
B4: 项目 | C4: ='3收入'!C4 -> 2015年 | D4: ='3收入'!D4 -> 2016年 | E4: ='3收入'!E4 -> 2017年 | F4: ='3收入'!F4 -> 2018年 | G4: ='3收入'!G4 -> 2019年 | H4: ='3收入'!H4 -> 2020年 | I4: ='3收入'!I4 -> 2021年 | J4: ='3收入'!J4 -> 2022年 | K4: 全部为经营性资产负债；不含非经营！
B5: 经营最低保有现金 | C5: ='9溢余现金'!C19 -> 162.71965 | D5: ='9溢余现金'!D19 -> 184.0763 | E5: ='9溢余现金'!E19 -> 239.36138 | F5: ='9溢余现金'!F19 -> 276.46729 | G5: ='9溢余现金'!G19 -> 320.20105 | H5: ='9溢余现金'!H19 -> 351.38539 | I5: ='9溢余现金'!I19 -> 371.36489 | J5: ='9溢余现金'!J19 -> 381.50273 | K5: 当企业不稳定时，不能用周转天数预测！采用绝对额进行预测！
B6: 应收票据及应收账款计算行 | C6: ='1报表'!C18-'2报表调整'!K11 -> 2177.8959 | D6: ='1报表'!D18-'2报表调整'!L11 -> 2618.1402 | E6: ='2报表调整'!G11 -> 3436.3947
B7: 周转天数 | C7: =IF(C41,360*C6/C41,0) -> 138.82852 | D7: =IF(D41,360*D6/D41,0) -> 129.02937 | E7: =IF(E41,360*E6/E41,0) -> 128.65605 | F7: 130 | G7: =F7 -> 130 | H7: =G7 -> 130 | I7: =H7 -> 130 | J7: =I7 -> 130
B8: 应收票据及应收账款 | C8: =C6 -> 2177.8959 | D8: =D6 -> 2618.1402 | E8: =E6 -> 3436.3947 | F8: =IF(F6,F6,F41*F7/360) -> 4310.0335 | G8: =IF(G6,G6,G41*G7/360) -> 5106.6108 | H8: =IF(H6,H6,H41*H7/360) -> 5740.2872 | I8: =IF(I6,I6,I41*I7/360) -> 6089.461 | J8: =IF(J6,J6,J41*J7/360) -> 6219.9407
B9: 预付款项计算行 | C9: ='1报表'!C19-'2报表调整'!K12 -> 163.1034 | D9: ='1报表'!D19-'2报表调整'!L12 -> 99.846675 | E9: ='2报表调整'!G12 -> 43.550822
B10: 周转天数 | C10: =IF(C42,360*C9/C42,0) -> 17.014572 | D10: =IF(D42,360*D9/D42,0) -> 7.7706963 | E10: =IF(E42,360*E9/E42,0) -> 2.7205161 | F10: 10 | G10: =F10 -> 10 | H10: =G10 -> 10 | I10: =H10 -> 10 | J10: =I10 -> 10
B11: 预付款项 | C11: =C9 -> 163.1034 | D11: =D9 -> 99.846675 | E11: =E9 -> 43.550822 | F11: =IF(F9,F9,F42*F10/360) -> 198.92462 | G11: =IF(G9,G9,G42*G10/360) -> 235.68973 | H11: =IF(H9,H9,H42*H10/360) -> 264.93633 | I11: =IF(I9,I9,I42*I10/360) -> 281.05205 | J11: =IF(J9,J9,J42*J10/360) -> 287.07419
B12: 其他应收款计算行 | C12: ='1报表'!C22-'2报表调整'!K15 -> 113.81446 | D12: ='1报表'!D22-'2报表调整'!L15 -> 191.70885 | E12: ='2报表调整'!G15 -> 22.319492
B13: 周转天数 | C13: =IF(C41,360*C12/C41,0) -> 7.2550267 | D13: =IF(D41,360*D12/D41,0) -> 9.4479558 | E13: =IF(E41,360*E12/E41,0) -> 0.83562512 | F13: 7 | G13: =F13 -> 7 | H13: =G13 -> 7 | I13: =H13 -> 7 | J13: =I13 -> 7
B14: 其他应收款 | C14: =C12 -> 113.81446 | D14: =D12 -> 191.70885 | E14: =E12 -> 22.319492 | F14: =IF(F12,F12,F41*F13/360) -> 232.07873 | G14: =IF(G12,G12,G41*G13/360) -> 274.97135 | H14: =IF(H12,H12,H41*H13/360) -> 309.09239 | I14: =IF(I12,I12,I41*I13/360) -> 327.89405 | J14: =IF(J12,J12,J41*J13/360) -> 334.91988
B15: 存货计算行 | C15: ='1报表'!C23-'2报表调整'!K16 -> 879.74901 | D15: ='1报表'!D23-'2报表调整'!L16 -> 1054.9352 | E15: ='2报表调整'!G16 -> 1331.2815
B16: 周转天数 | C16: =IF(C42,360*C15/C42,0) -> 91.773398 | D16: =IF(D42,360*D15/D42,0) -> 82.101695 | E16: =IF(E42,360*E15/E42,0) -> 83.161985 | F16: 85 | G16: =F16 -> 85 | H16: =G16 -> 85 | I16: =H16 -> 85 | J16: =I16 -> 85
B17: 存货 | C17: =C15 -> 879.74901 | D17: =D15 -> 1054.9352 | E17: =E15 -> 1331.2815 | F17: =IF(F15,F15,F42*F16/360) -> 1690.8593 | G17: =IF(G15,G15,G42*G16/360) -> 2003.3627 | H17: =IF(H15,H15,H42*H16/360) -> 2251.9588 | I17: =IF(I15,I15,I42*I16/360) -> 2388.9424 | J17: =IF(J15,J15,J42*J16/360) -> 2440.1306
B18: 合同资产 | C18: ='1报表'!C24-'2报表调整'!K17 -> 0 | D18: ='1报表'!D24-'2报表调整'!L17 -> 0 | E18: ='2报表调整'!G17 -> 0
B19: 一年内到期的非流动资产 | C19: ='1报表'!C26-'2报表调整'!K19 -> 0 | D19: ='1报表'!D26-'2报表调整'!L19 -> 0 | E19: ='2报表调整'!G19 -> 0
B20: 其他流动资产 | C20: ='1报表'!C27-'2报表调整'!K20 -> 34.793744 | D20: ='1报表'!D27-'2报表调整'!L20 -> 21.197218 | E20: ='2报表调整'!G20 -> 85.05866 | F20: =E20 -> 85.05866 | G20: =F20 -> 85.05866 | H20: =G20 -> 85.05866 | I20: =H20 -> 85.05866 | J20: =I20 -> 85.05866
B21: 流动资产合计 | C21: =C5+C8+C11+C14+C17+C18+C19+C20 -> 3532.0762 | D21: =D5+D8+D11+D14+D17+D18+D19+D20 -> 4169.9044 | E21: =E5+E8+E11+E14+E17+E18+E19+E20 -> 5157.9666 | F21: =F5+F8+F11+F14+F17+F18+F19+F20 -> 6793.4221 | G21: =G5+G8+G11+G14+G17+G18+G19+G20 -> 8025.8943 | H21: =H5+H8+H11+H14+H17+H18+H19+H20 -> 9002.7188 | I21: =I5+I8+I11+I14+I17+I18+I19+I20 -> 9543.773 | J21: =J5+J8+J11+J14+J17+J18+J19+J20 -> 9748.6267
B23: 应付票据及应付款项计算行 | C23: ='1报表'!C55-'2报表调整'!K48 -> 417.61032 | D23: ='1报表'!D55-'2报表调整'!L48 -> 1037.928 | E23: ='2报表调整'!G48 -> 1257.6974
B24: 周转天数 | C24: =IF(C42,360*C23/C42,0) -> 43.56415 | D24: =IF(D42,360*D23/D42,0) -> 80.778087 | E24: =IF(E42,360*E23/E42,0) -> 78.565357 | F24: 70 | G24: =F24 -> 70 | H24: =G24 -> 70 | I24: =H24 -> 70 | J24: =I24 -> 70
B25: 应付票据及应付账款 | C25: =C23 -> 417.61032 | D25: =D23 -> 1037.928 | E25: =E23 -> 1257.6974 | F25: =IF(F23,F23,F42*F24/360) -> 1392.4724 | G25: =IF(G23,G23,G42*G24/360) -> 1649.8281 | H25: =IF(H23,H23,H42*H24/360) -> 1854.5543 | I25: =IF(I23,I23,I42*I24/360) -> 1967.3643 | J25: =IF(J23,J23,J42*J24/360) -> 2009.5193
B26: 预收款项计算行 | C26: ='1报表'!C56-'2报表调整'!K49 -> 131.76532 | D26: ='1报表'!D56-'2报表调整'!L49 -> 195.99939 | E26: ='2报表调整'!G49 -> 351.09636
B27: 周转天数 | C27: =IF(C41,360*C26/C41,0) -> 8.3992923 | D27: =IF(D41,360*D26/D41,0) -> 9.6594056 | E27: =IF(E41,360*E26/E41,0) -> 13.144786 | F27: 9 | G27: =F27 -> 9 | H27: =G27 -> 9 | I27: =H27 -> 9 | J27: =I27 -> 9
B28: 预收款项 | C28: =C26 -> 131.76532 | D28: =D26 -> 195.99939 | E28: =E26 -> 351.09636 | F28: =IF(F26,F26,F41*F27/360) -> 298.38693 | G28: =IF(G26,G26,G41*G27/360) -> 353.53459 | H28: =IF(H26,H26,H41*H27/360) -> 397.4045 | I28: =IF(I26,I26,I41*I27/360) -> 421.57807 | J28: =IF(J26,J26,J41*J27/360) -> 430.61128
B29: 合同负债 | C29: ='1报表'!C57-'2报表调整'!K50 -> 0 | D29: ='1报表'!D57-'2报表调整'!L50 -> 0 | E29: ='2报表调整'!G50 -> 0
B30: 应付职工薪酬 | C30: ='1报表'!C58-'2报表调整'!K51 -> 132.57767 | D30: ='1报表'!D58-'2报表调整'!L51 -> 163.35175 | E30: ='2报表调整'!G51 -> 345.76284 | F30: =E30 -> 345.76284 | G30: =F30 -> 345.76284 | H30: =G30 -> 345.76284 | I30: =H30 -> 345.76284 | J30: =I30 -> 345.76284
B31: 应交税费 | C31: ='1报表'!C59-'2报表调整'!K52 -> 104.3759 | D31: ='1报表'!D59-'2报表调整'!L52 -> 117.08402 | E31: ='2报表调整'!G52 -> 225.302 | F31: =E31 -> 225.302 | G31: =F31 -> 225.302 | H31: =G31 -> 225.302 | I31: =H31 -> 225.302 | J31: =I31 -> 225.302
B32: 其他应付款计算行 | C32: ='1报表'!C62-'2报表调整'!K55 -> 1493.8281 | D32: ='1报表'!D62-'2报表调整'!L55 -> 1824.9313 | E32: ='2报表调整'!G55 -> 161.15448 | K32: 扣除17年应付设备款88.34万元后，占成本为1.3%
B33: 占成本比例 | C33: =IF(C42,C32/C42,0) -> 0.43286866 | D33: =IF(D42,D32/D42,0) -> 0.3945212 | E33: =IF(E42,E32/E42,0) -> 0.027963712 | F33: 0.15 | G33: =F33 -> 0.15 | H33: =G33 -> 0.15 | I33: =H33 -> 0.15 | J33: =I33 -> 0.15 | K33: 需要延伸剔除2015、2016年中的非经营
B34: 其他应付款 | C34: =C32 -> 1493.8281 | D34: =D32 -> 1824.9313 | E34: =E32 -> 161.15448 | F34: =IF(F32,F32,F42*F33) -> 1074.193 | G34: =IF(G32,G32,G42*G33) -> 1272.7245 | H34: =IF(H32,H32,H42*H33) -> 1430.6562 | I34: =IF(I32,I32,I42*I33) -> 1517.681 | J34: =IF(J32,J32,J42*J33) -> 1550.2006
B35: 其他流动负债计算行 | C35: ='1报表'!C65-'2报表调整'!K58 -> 0 | D35: ='1报表'!D65-'2报表调整'!L58 -> 0 | E35: ='2报表调整'!G58 -> 0
B36: 占成本比例 | C36: =IF(C42,C35/C42,0) -> 0 | D36: =IF(D42,D35/D42,0) -> 0 | E36: =IF(E42,E35/E42,0) -> 0
B37: 其他流动负债 | C37: =C35 -> 0 | D37: =D35 -> 0 | E37: =E35 -> 0 | F37: =IF(F35,F35,F42*F36) -> 0 | G37: =IF(G35,G35,G42*G36) -> 0 | H37: =IF(H35,H35,H42*H36) -> 0 | I37: =IF(I35,I35,I42*I36) -> 0 | J37: =IF(J35,J35,J42*J36) -> 0
B38: 流动负债合计 | C38: =C25+C28+C29+C30+C31+C34+C37 -> 2280.1573 | D38: =D25+D28+D29+D30+D31+D34+D37 -> 3339.2944 | E38: =E25+E28+E29+E30+E31+E34+E37 -> 2341.0131 | F38: =F25+F28+F29+F30+F31+F34+F37 -> 3336.1171 | G38: =G25+G28+G29+G30+G31+G34+G37 -> 3847.1521 | H38: =H25+H28+H29+H30+H31+H34+H37 -> 4253.6799 | I38: =I25+I28+I29+I30+I31+I34+I37 -> 4477.6883 | J38: =J25+J28+J29+J30+J31+J34+J37 -> 4561.396
B39: 营运资金 | C39: =C21-C38 -> 1251.9189 | D39: =D21-D38 -> 830.61 | E39: =E21-E38 -> 2816.9536 | F39: =F21-F38 -> 3457.305 | G39: =G21-G38 -> 4178.7422 | H39: =H21-H38 -> 4749.0389 | I39: =I21-I38 -> 5066.0847 | J39: =J21-J38 -> 5187.2307
B40: 营运资金增加额 | F40: =F39-E39 -> 640.3514 | G40: =G39-F39 -> 721.43725 | H40: =H39-G39 -> 570.29671 | I40: =I39-H39 -> 317.04582 | J40: =J39-I39 -> 121.14597
B41: 营业收入 | C41: ='3收入'!C5 -> 5647.5609 | D41: ='3收入'!D5 -> 7304.7745 | E41: ='3收入'!E5 -> 9615.5763 | F41: ='3收入'!F5 -> 11935.477 | G41: ='3收入'!G5 -> 14141.384 | H41: ='3收入'!H5 -> 15896.18 | I41: ='3收入'!I5 -> 16863.123 | J41: ='3收入'!J5 -> 17224.451
...

Sheet 11财务费用
B1: 财务费用预测表
B2: ='1报表'!B11 -> 评估基准日：2017/12/31
B3: ='1报表'!B12 -> 被评估单位：JSBD公司 | J3: 单位：万元
B4: 汇总数据 | C4: 利息率% | D4: 借款起讫日期 | E4: ='3收入'!E4 -> 2017年 | F4: ='3收入'!F4 -> 2018年 | G4: ='3收入'!G4 -> 2019年 | H4: ='3收入'!H4 -> 2020年 | I4: ='3收入'!I4 -> 2021年 | J4: ='3收入'!J4 -> 2022年
B5: 短期借款 | C5: 0.0541 | E5: 1000 | F5: 1000 | G5: 1000 | H5: 1000 | I5: 1000 | J5: 1000
B6: 一年内到期的非流动负债
B7: 长期借款
B8: 新增借款 | C8: 0.0541 | F8: 315.69213 | G8: 0 | H8: 0 | I8: 0 | J8: 0 | K8: 该行迭代计算得出
B9: 应付债券
B10: 付息负债合计 | E10: =SUM(E5:E9) -> 1000 | F10: =SUM(F5:F9) -> 1315.6921 | G10: =SUM(G5:G9) -> 1000 | H10: =SUM(H5:H9) -> 1000 | I10: =SUM(I5:I9) -> 1000 | J10: =SUM(J5:J9) -> 1000
B11: 财务费用测算
B12: 利息支出 | C12: ='3收入'!C4 -> 2015年 | D12: ='3收入'!D4 -> 2016年 | E12: ='3收入'!E4 -> 2017年 | F12: ='3收入'!F4 -> 2018年 | G12: ='3收入'!G4 -> 2019年 | H12: ='3收入'!H4 -> 2020年 | I12: ='3收入'!I4 -> 2021年 | J12: ='3收入'!K4 -> 0
B13: 短期借款 | F13: =$C5*E5 -> 54.1 | G13: =$C5*F5 -> 54.1 | H13: =$C5*G5 -> 54.1 | I13: =$C5*H5 -> 54.1 | J13: =$C5*I5 -> 54.1 | K13: 采用上年数计算，可根据具体发生情况填列
B14: 一年内到期的非流动负债 | F14: =$C6*E6 -> 0 | G14: =$C6*F6 -> 0 | H14: =$C6*G6 -> 0 | I14: =$C6*H6 -> 0 | J14: =$C6*I6 -> 0
B15: 长期借款 | F15: =$C7*E7 -> 0 | G15: =$C7*F7 -> 0 | H15: =$C7*G7 -> 0 | I15: =$C7*H7 -> 0 | J15: =$C7*I7 -> 0
B16: 新增借款 | F16: =$C8*E8 -> 0 | G16: =$C8*F8 -> 17.078944 | H16: =$C8*G8 -> 0 | I16: =$C8*H8 -> 0 | J16: =$C8*I8 -> 0
B17: 应付债券 | F17: =$C9*E9 -> 0 | G17: =$C9*F9 -> 0 | H17: =$C9*G9 -> 0 | I17: =$C9*H9 -> 0 | J17: =$C9*I9 -> 0
B18: 利息支出小计 | C18: ='1报表'!C104 -> 144.02572 | D18: ='1报表'!D104 -> 132.21571 | E18: ='1报表'!E104 -> 92.333057 | F18: =SUM(F13:F17) -> 54.1 | G18: =SUM(G13:G17) -> 71.178944 | H18: =SUM(H13:H17) -> 54.1 | I18: =SUM(I13:I17) -> 54.1 | J18: =SUM(J13:J17) -> 54.1
B19: 利息收入 | C19: ='1报表'!C105 -> 1.41285 | D19: ='1报表'!D105 -> 1.028431 | E19: ='1报表'!E105 -> 1.207926
B20: 汇兑损益及手续费等 | C20: =C21-C18+C19 -> -11.15778 | D20: =D21-D18+D19 -> -19.370293 | E20: =E21-E18+E19 -> 8.923127 | F20: 9 | G20: 9 | H20: 9 | I20: 9 | J20: 9 | K20: 预测期只考虑手续费，不考虑汇兑损益
B21: 财务费用合计 | C21: ='1报表'!C103 -> 131.45509 | D21: ='1报表'!D103 -> 111.81699 | E21: ='1报表'!E103 -> 100.04826 | F21: =SUM(F18:F20) -> 63.1 | G21: =SUM(G18:G20) -> 80.178944 | H21: =SUM(H18:H20) -> 63.1 | I21: =SUM(I18:I20) -> 63.1 | J21: =SUM(J18:J20) -> 63.1
B23: 新增借款(由预测资产负债表计算得出) | D23: 无“预测财报”表删除 | F23: =预测财报!F83 -> 0 | G23: =预测财报!G83 -> 0 | H23: =预测财报!H83 -> 0 | I23: =预测财报!I83 -> 0 | J23: =预测财报!J83 -> 0 | K23: 企业未来是否有资金缺口，需要融多少资金，
B24: 是否相等？ | F24: =F8-F23 -> 315.69213 | G24: =G8-G23 -> 0 | H24: =H8-H23 -> 0 | I24: =I8-I23 -> 0 | J24: =J8-J23 -> 0 | K24: 只有通过预测资产负债表计算才能得出。
B27: 借款明细核实如下

Sheet 12收益表
B1: 收益预测表
B2: ='1报表'!B11 -> 评估基准日：2017/12/31
B3: ='1报表'!B12 -> 被评估单位：JSBD公司 | J3: 单位：万元
B4: 利润表（经营性） | C4: ='3收入'!C4 -> 2015年 | D4: ='3收入'!D4 -> 2016年 | E4: ='3收入'!E4 -> 2017年 | F4: ='3收入'!F4 -> 2018年 | G4: ='3收入'!G4 -> 2019年 | H4: ='3收入'!H4 -> 2020年 | I4: ='3收入'!I4 -> 2021年 | J4: ='3收入'!J4 -> 2022年
B5: 一、营业收入 | C5: ='3收入'!C5 -> 5647.5609 | D5: ='3收入'!D5 -> 7304.7745 | E5: ='3收入'!E5 -> 9615.5763 | F5: ='3收入'!F5 -> 11935.477 | G5: ='3收入'!G5 -> 14141.384 | H5: ='3收入'!H5 -> 15896.18 | I5: ='3收入'!I5 -> 16863.123 | J5: ='3收入'!J5 -> 17224.451
B6: 减:营业成本 | C6: ='4成本'!C5 -> 3450.9962 | D6: ='4成本'!D5 -> 4625.6862 | E6: ='4成本'!E5 -> 5762.986 | F6: ='4成本'!F5 -> 7161.2864 | G6: ='4成本'!G5 -> 8484.8303 | H6: ='4成本'!H5 -> 9537.7079 | I6: ='4成本'!I5 -> 10117.874 | J6: ='4成本'!J5 -> 10334.671
B7: 减:税金及附加 | C7: ='5税金'!C5 -> 53.873421 | D7: ='5税金'!D5 -> 81.416231 | E7: ='5税金'!E5 -> 113.39456 | F7: ='5税金'!F5 -> 107.26836 | G7: ='5税金'!G5 -> 127.21454 | H7: ='5税金'!H5 -> 142.79594 | I7: ='5税金'!I5 -> 152.48181 | J7: ='5税金'!J5 -> 155.38377
B8: 减:销售费用 | C8: ='6销管'!C5 -> 481.4591 | D8: ='6销管'!D5 -> 588.55087 | E8: ='6销管'!E5 -> 750.19684 | F8: ='6销管'!F5 -> 950.06399 | G8: ='6销管'!G5 -> 1125.6541 | H8: ='6销管'!H5 -> 1265.3359 | I8: ='6销管'!I5 -> 1342.3046 | J8: ='6销管'!J5 -> 1371.0663
B9: 减:管理费用 | C9: ='6销管'!C6 -> 694.30698 | D9: ='6销管'!D6 -> 710.43654 | E9: ='6销管'!E6 -> 1052.4467 | F9: ='6销管'!F6 -> 1140.1681 | G9: ='6销管'!G6 -> 1284.8847 | H9: ='6销管'!H6 -> 1341.4961 | I9: ='6销管'!I6 -> 1376.4758 | J9: ='6销管'!J6 -> 1432.4397
B10: 减:研发费用 | C10: ='6销管'!C7 -> 384.83578 | D10: ='6销管'!D7 -> 369.90657 | E10: ='6销管'!E7 -> 435.369 | F10: ='6销管'!F7 -> 596.77387 | G10: ='6销管'!G7 -> 707.06919 | H10: ='6销管'!H7 -> 794.809 | I10: ='6销管'!I7 -> 843.15614 | J10: ='6销管'!J7 -> 861.22256
B11: 减:财务费用 | C11: ='11财务费用'!C21 -> 131.45509 | D11: ='11财务费用'!D21 -> 111.81699 | E11: ='11财务费用'!E21 -> 100.04826 | F11: ='11财务费用'!F21 -> 63.1 | G11: ='11财务费用'!G21 -> 80.178944 | H11: ='11财务费用'!H21 -> 63.1 | I11: ='11财务费用'!I21 -> 63.1 | J11: ='11财务费用'!J21 -> 63.1
B12: 二、营业利润 | C12: =C5-SUM(C6:C11) -> 450.63432 | D12: =D5-SUM(D6:D11) -> 816.9611 | E12: =E5-SUM(E6:E11) -> 1401.135 | F12: =F5-SUM(F6:F11) -> 1916.8166 | G12: =G5-SUM(G6:G11) -> 2331.552 | H12: =H5-SUM(H6:H11) -> 2750.935 | I12: =I5-SUM(I6:I11) -> 2967.7308 | J12: =J5-SUM(J6:J11) -> 3006.5681
B13: 三、利润总额 | C13: =C12 -> 450.63432 | D13: =D12 -> 816.9611 | E13: =E12 -> 1401.135 | F13: =F12 -> 1916.8166 | G13: =G12 -> 2331.552 | H13: =H12 -> 2750.935 | I13: =I12 -> 2967.7308 | J13: =J12 -> 3006.5681
B14: 减：弥补以前年度亏损
B15: 减：研发费用加计扣除 | F15: ='6销管'!F7*0.75 -> 447.5804 | G15: ='6销管'!G7*0.75 -> 530.30189 | H15: ='6销管'!H7*0.5 -> 397.4045 | I15: ='6销管'!I7*0.5 -> 421.57807 | J15: ='6销管'!J7*0.5 -> 430.61128
B16: 减：其他纳税调减额
B17: 加：其他纳税调增额
B18: 应纳税所得额 | F18: =F13-F14-F15-F16+F17 -> 1469.2362 | G18: =G13-G14-G15-G16+G17 -> 1801.2501 | H18: =H13-H14-H15-H16+H17 -> 2353.5305 | I18: =I13-I14-I15-I16+I17 -> 2546.1527 | J18: =J13-J14-J15-J16+J17 -> 2575.9568
B19: 所得税税率 | F19: 0.25 | G19: 0.15 | H19: 0.15 | I19: 0.15 | J19: 0.25
B20: 减:所得税费用 | F20: =IF(F18<0,0,F18*F19) -> 367.30906 | G20: =IF(G18<0,0,G18*G19) -> 270.18752 | H20: =IF(H18<0,0,H18*H19) -> 353.02958 | I20: =IF(I18<0,0,I18*I19) -> 381.92291 | J20: =IF(J18<0,0,J18*J19) -> 643.9892
B21: 四、净利润 | F21: =F13-F20 -> 1549.5076 | G21: =G13-G20 -> 2061.3645 | H21: =H13-H20 -> 2397.9054 | I21: =I13-I20 -> 2585.8079 | J21: =J13-J20 -> 2362.5789
B22: 减:少数股东损益
